{"action":"snapshot","channel":"books","instrumentId":"BTC-USDT","instAsks":[{"price":64324,"quantity":0.6409424,"orderId":10},{"price":64324.1,"quantity":0.00153172,"orderId":1},{"price":64326,"quantity":0.32003745,"orderId":9},{"price":64326.5,"quantity":0.00029774,"orderId":1},{"price":64327.9,"quantity":0.04848002,"orderId":1},{"price":64328,"quantity":0.0808,"orderId":1},{"price":64328.7,"quantity":0.01106532,"orderId":1},{"price":64329,"quantity":0.02342886,"orderId":1},{"price":64329.9,"quantity":0.22,"orderId":1},{"price":64330,"quantity":0.080815,"orderId":2},{"price":64331.1,"quantity":0.13200001,"orderId":1},{"price":64331.4,"quantity":0.05866956,"orderId":1},{"price":64331.9,"quantity":0.15536977,"orderId":1},{"price":64332,"quantity":0.0808,"orderId":1},{"price":64332.5,"quantity":0.26003105,"orderId":2},{"price":64333.2,"quantity":0.05968139,"orderId":1},{"price":64333.3,"quantity":0.11188322,"orderId":1},{"price":64333.4,"quantity":0.05848912,"orderId":1},{"price":64333.9,"quantity":0.00775059,"orderId":1},{"price":64336,"quantity":0.00748533,"orderId":1},{"price":64336.4,"quantity":0.000015,"orderId":1},{"price":64337.8,"quantity":0.00016049,"orderId":1},{"price":64338.1,"quantity":0.31796868,"orderId":2},{"price":64338.9,"quantity":0.0166,"orderId":1},{"price":64339,"quantity":0.543933,"orderId":1},{"price":64340,"quantity":0.0015,"orderId":1},{"price":64340.2,"quantity":0.08549363,"orderId":1},{"price":64340.7,"quantity":0.05866956,"orderId":1},{"price":64341.8,"quantity":0.28174336,"orderId":1},{"price":64341.9,"quantity":0.05513,"orderId":1},{"price":64342.3,"quantity":0.46957212,"orderId":1},{"price":64342.5,"quantity":0.05460931,"orderId":2},{"price":64342.8,"quantity":0.00001501,"orderId":1},{"price":64342.9,"quantity":0.09786543,"orderId":1},{"price":64343,"quantity":0.086321,"orderId":1},{"price":64343.1,"quantity":0.03384766,"orderId":1},{"price":64343.2,"quantity":0.156341,"orderId":1},{"price":64343.6,"quantity":0.26,"orderId":1},{"price":64343.8,"quantity":0.00466248,"orderId":3},{"price":64344,"quantity":0.00151,"orderId":1},{"price":64344.8,"quantity":0.01,"orderId":1},{"price":64347.4,"quantity":0.67578372,"orderId":2},{"price":64347.5,"quantity":0.15533231,"orderId":1},{"price":64347.6,"quantity":1.19429561,"orderId":1},{"price":64348.5,"quantity":0.156341,"orderId":1},{"price":64348.8,"quantity":0.7451252,"orderId":1},{"price":64349.2,"quantity":0.00003001,"orderId":2},{"price":64349.7,"quantity":1.36218065,"orderId":2},{"price":64349.8,"quantity":0.00588,"orderId":1},{"price":64350.2,"quantity":0.03188352,"orderId":1},{"price":64350.8,"quantity":0.02017297,"orderId":2},{"price":64350.9,"quantity":0.11241225,"orderId":2},{"price":64351.7,"quantity":0.00528259,"orderId":1},{"price":64352,"quantity":0.26,"orderId":1},{"price":64353.6,"quantity":0.02345539,"orderId":1},{"price":64353.7,"quantity":0.1553168,"orderId":1},{"price":64354,"quantity":0.05866956,"orderId":1},{"price":64355,"quantity":0.02332,"orderId":1},{"price":64355.6,"quantity":0.000015,"orderId":1},{"price":64357.1,"quantity":0.0938046,"orderId":1},{"price":64357.2,"quantity":0.02033272,"orderId":1},{"price":64358.3,"quantity":0.156341,"orderId":1},{"price":64358.5,"quantity":0.000209,"orderId":1},{"price":64358.7,"quantity":0.02329638,"orderId":1},{"price":64358.8,"quantity":0.28174328,"orderId":1},{"price":64358.9,"quantity":0.46957212,"orderId":1},{"price":64359.8,"quantity":0.15530206,"orderId":1},{"price":64360.2,"quantity":0.02331963,"orderId":1},{"price":64360.3,"quantity":0.37114,"orderId":1},{"price":64362,"quantity":0.000015,"orderId":1},{"price":64362.6,"quantity":0.0296,"orderId":1},{"price":64362.7,"quantity":0.02533722,"orderId":1},{"price":64363.3,"quantity":0.02622749,"orderId":1},{"price":64363.8,"quantity":0.416341,"orderId":2},{"price":64364.1,"quantity":0.02,"orderId":1},{"price":64364.3,"quantity":0.15529161,"orderId":1},{"price":64364.6,"quantity":0.02329425,"orderId":1},{"price":64367.4,"quantity":2.49579193,"orderId":1},{"price":64367.9,"quantity":0.02758264,"orderId":1},{"price":64368,"quantity":0.00045193,"orderId":1},{"price":64368.4,"quantity":0.00001501,"orderId":1},{"price":64369.5,"quantity":0.02953706,"orderId":1},{"price":64369.9,"quantity":0.077737,"orderId":1},{"price":64370.3,"quantity":0.28953706,"orderId":2},{"price":64370.6,"quantity":0.02953706,"orderId":1},{"price":64370.9,"quantity":0.156341,"orderId":1},{"price":64371.5,"quantity":0.03731487,"orderId":1},{"price":64371.6,"quantity":0.05866956,"orderId":1},{"price":64371.7,"quantity":0.06219142,"orderId":1},{"price":64373.7,"quantity":0.00679716,"orderId":1},{"price":64374.5,"quantity":0.03494473,"orderId":1},{"price":64374.8,"quantity":0.00210501,"orderId":2},{"price":64376.6,"quantity":0.70538416,"orderId":4},{"price":64376.7,"quantity":0.156341,"orderId":1},{"price":64377,"quantity":1.21167,"orderId":1},{"price":64377.3,"quantity":0.36719,"orderId":1},{"price":64377.4,"quantity":0.46957212,"orderId":1},{"price":64377.5,"quantity":0.26,"orderId":1},{"price":64378.7,"quantity":0.46599,"orderId":1},{"price":64380.5,"quantity":0.03109764,"orderId":1},{"price":64380.7,"quantity":0.43673,"orderId":1},{"price":64381.2,"quantity":0.00003001,"orderId":2},{"price":64381.6,"quantity":0.09380461,"orderId":1},{"price":64381.7,"quantity":0.02045424,"orderId":1},{"price":64382.2,"quantity":0.156341,"orderId":1},{"price":64384.5,"quantity":0.02953835,"orderId":1},{"price":64385.4,"quantity":1.1161265,"orderId":2},{"price":64385.8,"quantity":0.0310931,"orderId":1},{"price":64386.4,"quantity":0.02091663,"orderId":1},{"price":64386.6,"quantity":1.85115477,"orderId":1},{"price":64387.1,"quantity":0.0310931,"orderId":1},{"price":64387.2,"quantity":0.46616,"orderId":1},{"price":64387.3,"quantity":0.33142599,"orderId":1},{"price":64387.4,"quantity":0.156341,"orderId":1},{"price":64387.5,"quantity":0.26,"orderId":1},{"price":64387.6,"quantity":0.00001501,"orderId":1},{"price":64387.7,"quantity":0.0134817,"orderId":1},{"price":64388.1,"quantity":0.14367844,"orderId":1},{"price":64388.2,"quantity":0.00832637,"orderId":1},{"price":64388.5,"quantity":0.55237653,"orderId":1},{"price":64388.7,"quantity":0.0310945,"orderId":1},{"price":64388.9,"quantity":0.11733913,"orderId":1},{"price":64389,"quantity":0.01,"orderId":1},{"price":64389.9,"quantity":0.03109281,"orderId":1},{"price":64391.1,"quantity":0.01294175,"orderId":1},{"price":64392,"quantity":0.0000253,"orderId":1},{"price":64392.5,"quantity":0.00001003,"orderId":1},{"price":64393.1,"quantity":0.02112285,"orderId":2},{"price":64393.2,"quantity":0.03493459,"orderId":1},{"price":64394,"quantity":0.000015,"orderId":1},{"price":64394.7,"quantity":0.00007527,"orderId":1},{"price":64395.2,"quantity":0.02795,"orderId":1},{"price":64395.8,"quantity":0.00001553,"orderId":1},{"price":64395.9,"quantity":0.72040149,"orderId":1},{"price":64396,"quantity":0.016331,"orderId":1},{"price":64396.2,"quantity":1.19858,"orderId":1},{"price":64396.7,"quantity":0.12,"orderId":1},{"price":64397.1,"quantity":0.00003249,"orderId":1},{"price":64397.5,"quantity":0.156341,"orderId":1},{"price":64397.6,"quantity":0.26,"orderId":1},{"price":64397.7,"quantity":1.21398487,"orderId":1},{"price":64398.1,"quantity":0.46957212,"orderId":1},{"price":64398.3,"quantity":0.36063,"orderId":1},{"price":64398.4,"quantity":0.00122155,"orderId":1},{"price":64399,"quantity":2,"orderId":1},{"price":64399.9,"quantity":0.00083349,"orderId":2},{"price":64400,"quantity":0.01693232,"orderId":12},{"price":64400.4,"quantity":0.00001501,"orderId":1},{"price":64400.7,"quantity":1.11022174,"orderId":1},{"price":64400.8,"quantity":1.55294,"orderId":1},{"price":64401.2,"quantity":0.0136,"orderId":2},{"price":64402.4,"quantity":0.00001233,"orderId":1},{"price":64402.9,"quantity":0.00776362,"orderId":1},{"price":64404.3,"quantity":0.12,"orderId":1},{"price":64404.8,"quantity":0.17465263,"orderId":1},{"price":64404.9,"quantity":0.156341,"orderId":1},{"price":64405.4,"quantity":0.0323472,"orderId":2},{"price":64405.5,"quantity":0.29100067,"orderId":2},{"price":64405.8,"quantity":0.0309998,"orderId":1},{"price":64406.3,"quantity":0.03100149,"orderId":1},{"price":64406.8,"quantity":0.00001501,"orderId":1},{"price":64407,"quantity":0.03100149,"orderId":1},{"price":64407.4,"quantity":0.0309998,"orderId":1},{"price":64407.6,"quantity":0.05824042,"orderId":1},{"price":64407.7,"quantity":0.03100149,"orderId":1},{"price":64408,"quantity":0.10795341,"orderId":2},{"price":64408.5,"quantity":0.03100226,"orderId":1},{"price":64408.7,"quantity":0.03100226,"orderId":1},{"price":64408.9,"quantity":0.0309998,"orderId":1},{"price":64409,"quantity":0.00006689,"orderId":2},{"price":64409.3,"quantity":0.19492355,"orderId":3},{"price":64409.4,"quantity":0.09381141,"orderId":1},{"price":64409.9,"quantity":0.03100226,"orderId":1},{"price":64410.5,"quantity":0.14904106,"orderId":1},{"price":64410.6,"quantity":0.0309998,"orderId":1},{"price":64410.7,"quantity":0.15696248,"orderId":2},{"price":64411.8,"quantity":0.24840173,"orderId":1},{"price":64412.2,"quantity":0.0309998,"orderId":1},{"price":64412.3,"quantity":0.00776249,"orderId":1},{"price":64412.6,"quantity":0.05866956,"orderId":1},{"price":64413.2,"quantity":0.00003002,"orderId":2},{"price":64413.9,"quantity":0.0309998,"orderId":1},{"price":64414,"quantity":0.27930702,"orderId":1},{"price":64414.1,"quantity":0.26,"orderId":1},{"price":64414.3,"quantity":0.46551162,"orderId":1},{"price":64414.4,"quantity":0.00776223,"orderId":1},{"price":64414.9,"quantity":0.05174787,"orderId":1},{"price":64415,"quantity":0.06117283,"orderId":3},{"price":64415.2,"quantity":0.00034264,"orderId":1},{"price":64415.6,"quantity":0.0309998,"orderId":1},{"price":64416.5,"quantity":0.156341,"orderId":1},{"price":64416.7,"quantity":0.70575,"orderId":1},{"price":64417.3,"quantity":0.0309998,"orderId":1},{"price":64417.8,"quantity":1.20734764,"orderId":2},{"price":64417.9,"quantity":0.00646819,"orderId":1},{"price":64418,"quantity":0.33876,"orderId":1},{"price":64418.6,"quantity":0.02399869,"orderId":1},{"price":64418.8,"quantity":0.00001544,"orderId":1},{"price":64419.2,"quantity":0.0489998,"orderId":2},{"price":64419.5,"quantity":0.15387694,"orderId":2},{"price":64419.6,"quantity":0.00001501,"orderId":1},{"price":64420.6,"quantity":0.03109764,"orderId":1},{"price":64420.7,"quantity":0.2909998,"orderId":2},{"price":64420.8,"quantity":0.00002712,"orderId":1},{"price":64420.9,"quantity":0.01616971,"orderId":1},{"price":64421.5,"quantity":0.00002959,"orderId":1},{"price":64422.4,"quantity":0.12021695,"orderId":4},{"price":64422.5,"quantity":0.156341,"orderId":1},{"price":64422.8,"quantity":0.0310931,"orderId":1},{"price":64422.9,"quantity":0.12126,"orderId":1},{"price":64423.2,"quantity":0.0309998,"orderId":1},{"price":64423.5,"quantity":0.05302938,"orderId":2},{"price":64423.7,"quantity":0.06988851,"orderId":1},{"price":64424.2,"quantity":0.0310931,"orderId":1},{"price":64425.7,"quantity":0.11733913,"orderId":1},{"price":64425.9,"quantity":0.00014399,"orderId":2},{"price":64426,"quantity":0.00001501,"orderId":1},{"price":64426.3,"quantity":0.00003551,"orderId":1},{"price":64426.5,"quantity":0.03000242,"orderId":1},{"price":64427.1,"quantity":0.03000186,"orderId":1},{"price":64427.2,"quantity":0.26,"orderId":1},{"price":64428,"quantity":0.91055724,"orderId":2},{"price":64428.1,"quantity":0.156341,"orderId":1},{"price":64428.2,"quantity":0.03000242,"orderId":1},{"price":64428.4,"quantity":0.00056826,"orderId":1},{"price":64428.5,"quantity":0.00027074,"orderId":3},{"price":64428.6,"quantity":1.53495,"orderId":1},{"price":64428.8,"quantity":0.03000242,"orderId":1},{"price":64429.5,"quantity":0.29974321,"orderId":1},{"price":64429.6,"quantity":0.51573945,"orderId":3},{"price":64429.8,"quantity":0.03000242,"orderId":1},{"price":64430,"quantity":0.00002855,"orderId":1},{"price":64430.2,"quantity":0.01665205,"orderId":2},{"price":64430.3,"quantity":0.03000242,"orderId":1},{"price":64430.6,"quantity":0.01028553,"orderId":1},{"price":64431,"quantity":0.01665333,"orderId":1},{"price":64433.2,"quantity":0.00003099,"orderId":1},{"price":64433.3,"quantity":0.00001007,"orderId":1},{"price":64433.6,"quantity":0.15600002,"orderId":1},{"price":64433.7,"quantity":0.26,"orderId":1},{"price":64434.2,"quantity":0.00009215,"orderId":1},{"price":64434.4,"quantity":0.0310885,"orderId":1},{"price":64436.3,"quantity":0.03000331,"orderId":1},{"price":64437.7,"quantity":0.09380461,"orderId":1},{"price":64437.8,"quantity":0.03000331,"orderId":1},{"price":64438.4,"quantity":0.156341,"orderId":1},{"price":64439.2,"quantity":0.00096765,"orderId":1},{"price":64439.3,"quantity":0.03000331,"orderId":1},{"price":64440,"quantity":0.0006649,"orderId":3},{"price":64440.1,"quantity":0.69109806,"orderId":1},{"price":64440.2,"quantity":0.26,"orderId":1},{"price":64440.6,"quantity":0.00001558,"orderId":1},{"price":64440.7,"quantity":0.00021217,"orderId":1},{"price":64441,"quantity":0.03000331,"orderId":1},{"price":64441.1,"quantity":0.00002326,"orderId":1},{"price":64441.4,"quantity":1.15183,"orderId":1},{"price":64442,"quantity":0.00002252,"orderId":1},{"price":64442.2,"quantity":0.04693565,"orderId":1},{"price":64443.2,"quantity":0.00027237,"orderId":1},{"price":64444.1,"quantity":0.00015411,"orderId":1},{"price":64444.3,"quantity":0.00011507,"orderId":1},{"price":64444.4,"quantity":0.01041098,"orderId":4},{"price":64445.2,"quantity":0.000015,"orderId":1},{"price":64445.6,"quantity":0.28174328,"orderId":1},{"price":64445.7,"quantity":0.46957212,"orderId":1},{"price":64445.9,"quantity":0.00030577,"orderId":1},{"price":64446.7,"quantity":0.26,"orderId":1},{"price":64446.8,"quantity":0.05866956,"orderId":1},{"price":64448.3,"quantity":0.00001635,"orderId":1},{"price":64448.7,"quantity":0.01616273,"orderId":1},{"price":64449.6,"quantity":0.00003742,"orderId":2},{"price":64449.7,"quantity":0.00002387,"orderId":1},{"price":64449.9,"quantity":0.00003598,"orderId":1},{"price":64450,"quantity":0.00293778,"orderId":4},{"price":64450.6,"quantity":0.00011418,"orderId":1},{"price":64450.8,"quantity":0.00003944,"orderId":1},{"price":64451.6,"quantity":0.00001409,"orderId":1},{"price":64451.8,"quantity":0.18618543,"orderId":1},{"price":64451.9,"quantity":0.31030893,"orderId":1},{"price":64452.1,"quantity":0.0134817,"orderId":1},{"price":64453.2,"quantity":0.26,"orderId":1},{"price":64454.1,"quantity":0.00007025,"orderId":1},{"price":64454.5,"quantity":0.00009453,"orderId":1},{"price":64455,"quantity":0.0001553,"orderId":1},{"price":64455.1,"quantity":0.00064172,"orderId":1},{"price":64456.2,"quantity":0.01331345,"orderId":2},{"price":64456.3,"quantity":0.00001001,"orderId":1},{"price":64457.3,"quantity":0.00007163,"orderId":1},{"price":64458.3,"quantity":0.00833218,"orderId":1},{"price":64458.4,"quantity":0.13123,"orderId":2},{"price":64458.6,"quantity":0.90000007,"orderId":1},{"price":64458.7,"quantity":0.11733913,"orderId":1},{"price":64458.9,"quantity":0.02093154,"orderId":1},{"price":64459.7,"quantity":0.26,"orderId":1},{"price":64459.8,"quantity":0.00001477,"orderId":1},{"price":64459.9,"quantity":1.5,"orderId":1},{"price":64460,"quantity":0.0125009,"orderId":1},{"price":64461.2,"quantity":0.00002573,"orderId":1},{"price":64461.5,"quantity":0.0000247,"orderId":1},{"price":64462.5,"quantity":0.0204,"orderId":3},{"price":64463,"quantity":0.04693565,"orderId":1},{"price":64463.3,"quantity":0.36993,"orderId":1},{"price":64463.7,"quantity":0.00016959,"orderId":2},{"price":64464.1,"quantity":0.46957212,"orderId":1},{"price":64464.4,"quantity":0.0000292,"orderId":1},{"price":64466,"quantity":0.00001607,"orderId":1},{"price":64466.1,"quantity":0.00004251,"orderId":2},{"price":64466.2,"quantity":0.26,"orderId":1},{"price":64466.6,"quantity":0.00001721,"orderId":1},{"price":64467.1,"quantity":3.72,"orderId":1},{"price":64467.8,"quantity":0.00008861,"orderId":4},{"price":64468.4,"quantity":0.00123505,"orderId":14},{"price":64468.5,"quantity":0.00003591,"orderId":1},{"price":64468.6,"quantity":0.00025683,"orderId":1},{"price":64469.5,"quantity":0.00019638,"orderId":1},{"price":64469.9,"quantity":0.0161736,"orderId":1},{"price":64470.8,"quantity":0.05873127,"orderId":2},{"price":64471.2,"quantity":0.04577327,"orderId":2},{"price":64471.4,"quantity":0.00395411,"orderId":2},{"price":64472.7,"quantity":0.26,"orderId":1},{"price":64472.8,"quantity":1.20146,"orderId":1},{"price":64473.2,"quantity":0.89296804,"orderId":1},{"price":64473.3,"quantity":0.00004381,"orderId":4},{"price":64474.1,"quantity":0.00008179,"orderId":1},{"price":64474.5,"quantity":1.5619,"orderId":1},{"price":64474.7,"quantity":0.00003174,"orderId":1},{"price":64474.8,"quantity":0.00002154,"orderId":1},{"price":64474.9,"quantity":0.00001397,"orderId":1},{"price":64475.2,"quantity":0.00002539,"orderId":1},{"price":64476.5,"quantity":0.00001017,"orderId":1},{"price":64476.9,"quantity":0.00003228,"orderId":1},{"price":64477.5,"quantity":0.01553167,"orderId":1},{"price":64477.9,"quantity":0.00679732,"orderId":1},{"price":64478.2,"quantity":0.00869565,"orderId":1},{"price":64478.8,"quantity":0.51790835,"orderId":2},{"price":64479,"quantity":0.00013837,"orderId":1},{"price":64479.2,"quantity":0.26,"orderId":1},{"price":64479.5,"quantity":0.0002291,"orderId":1},{"price":64479.9,"quantity":0.00042349,"orderId":1},{"price":64480,"quantity":0.01594791,"orderId":8},{"price":64480.1,"quantity":0.00008158,"orderId":2},{"price":64481,"quantity":0.00006063,"orderId":1},{"price":64481.1,"quantity":0.00647862,"orderId":2},{"price":64481.2,"quantity":0.00001295,"orderId":1},{"price":64481.7,"quantity":0.46957212,"orderId":1},{"price":64482,"quantity":0.00015508,"orderId":1},{"price":64482.9,"quantity":0.00001158,"orderId":1},{"price":64483.3,"quantity":0.00001564,"orderId":1},{"price":64483.5,"quantity":0.00001302,"orderId":1},{"price":64483.7,"quantity":0.0155,"orderId":1},{"price":64483.9,"quantity":0.00001756,"orderId":1},{"price":64484.6,"quantity":0.00003789,"orderId":3},{"price":64484.8,"quantity":0.01620298,"orderId":3},{"price":64485,"quantity":0.0123245,"orderId":3},{"price":64485.2,"quantity":0.05866956,"orderId":1},{"price":64485.7,"quantity":0.26004469,"orderId":2},{"price":64486,"quantity":0.00001062,"orderId":1},{"price":64486.3,"quantity":0.00007774,"orderId":1},{"price":64486.7,"quantity":0.00001003,"orderId":1},{"price":64487.1,"quantity":0.0029222,"orderId":2},{"price":64488.2,"quantity":0.00056274,"orderId":1},{"price":64488.4,"quantity":0.00001677,"orderId":1},{"price":64489,"quantity":0.01282516,"orderId":2},{"price":64489.3,"quantity":0.00220669,"orderId":2},{"price":64490,"quantity":0.00001801,"orderId":1},{"price":64490.4,"quantity":0.00049732,"orderId":1},{"price":64490.8,"quantity":0.00002325,"orderId":2},{"price":64490.9,"quantity":0.00002679,"orderId":1},{"price":64491.8,"quantity":0.00001076,"orderId":1},{"price":64491.9,"quantity":0.00660259,"orderId":1},{"price":64492,"quantity":0.00014177,"orderId":1},{"price":64492.7,"quantity":0.00012645,"orderId":1},{"price":64492.8,"quantity":0.00067371,"orderId":1},{"price":64493.9,"quantity":0.0002873,"orderId":1},{"price":64494,"quantity":0.05866956,"orderId":1},{"price":64494.7,"quantity":0.01616737,"orderId":1},{"price":64495.4,"quantity":0.0161672,"orderId":1},{"price":64496.2,"quantity":0.00023791,"orderId":5},{"price":64496.3,"quantity":0.00003278,"orderId":2},{"price":64496.4,"quantity":0.12113,"orderId":1},{"price":64496.5,"quantity":0.00001043,"orderId":1},{"price":64497.2,"quantity":0.00001001,"orderId":1},{"price":64497.9,"quantity":0.00001933,"orderId":1},{"price":64498.1,"quantity":0.00001028,"orderId":1},{"price":64498.7,"quantity":0.26,"orderId":1},{"price":64499,"quantity":0.00450527,"orderId":1},{"price":64499.3,"quantity":0.46957212,"orderId":1},{"price":64499.8,"quantity":0.04664866,"orderId":1},{"price":64499.9,"quantity":0.00236431,"orderId":7},{"price":64500,"quantity":3.46297616,"orderId":97},{"price":64500.9,"quantity":0.00004963,"orderId":2},{"price":64501,"quantity":0.016331,"orderId":1},{"price":64501.2,"quantity":0.41270938,"orderId":2},{"price":64501.8,"quantity":0.00007459,"orderId":1},{"price":64503.1,"quantity":0.0001601,"orderId":1},{"price":64503.7,"quantity":0.00004319,"orderId":1},{"price":64503.9,"quantity":0.01258346,"orderId":1},{"price":64504.2,"quantity":0.00011492,"orderId":4},{"price":64505.2,"quantity":0.26001501,"orderId":2},{"price":64506.2,"quantity":0.00005269,"orderId":1}],"instBids":[{"price":64323.9,"quantity":0.16668667,"orderId":2},{"price":64320,"quantity":0.0808,"orderId":1},{"price":64319.3,"quantity":0.15539999,"orderId":1},{"price":64318,"quantity":0.0808,"orderId":1},{"price":64317.5,"quantity":0.00301836,"orderId":1},{"price":64317.4,"quantity":0.1946847,"orderId":2},{"price":64316,"quantity":0.0808,"orderId":1},{"price":64315.6,"quantity":0.0154,"orderId":1},{"price":64314.8,"quantity":0.2205,"orderId":2},{"price":64314.7,"quantity":0.0005,"orderId":1},{"price":64314.3,"quantity":0.00001501,"orderId":1},{"price":64314,"quantity":0.1208,"orderId":2},{"price":64313.9,"quantity":0.0174,"orderId":1},{"price":64313.7,"quantity":0.00528259,"orderId":1},{"price":64313.5,"quantity":0.00833802,"orderId":1},{"price":64313,"quantity":0.0316517,"orderId":1},{"price":64312.7,"quantity":0.46619,"orderId":1},{"price":64312.5,"quantity":0.141584,"orderId":1},{"price":64312,"quantity":0.09971467,"orderId":3},{"price":64310.9,"quantity":0.26,"orderId":1},{"price":64310.8,"quantity":0.03112422,"orderId":3},{"price":64310.7,"quantity":0.00470242,"orderId":1},{"price":64310,"quantity":0.0808,"orderId":1},{"price":64309.6,"quantity":0.00310996,"orderId":1},{"price":64308,"quantity":0.09008367,"orderId":3},{"price":64307.9,"quantity":0.00001501,"orderId":1},{"price":64307.8,"quantity":0.05966956,"orderId":2},{"price":64306.4,"quantity":0.15549,"orderId":1},{"price":64306.1,"quantity":0.156341,"orderId":1},{"price":64306,"quantity":0.1008,"orderId":2},{"price":64305.5,"quantity":0.08785359,"orderId":1},{"price":64305.2,"quantity":0.00466527,"orderId":3},{"price":64304.4,"quantity":0.26,"orderId":1},{"price":64304.2,"quantity":0.0174,"orderId":1},{"price":64304,"quantity":0.16077909,"orderId":3},{"price":64302.8,"quantity":0.0174,"orderId":1},{"price":64302.7,"quantity":0.0296,"orderId":1},{"price":64301.7,"quantity":0.07606956,"orderId":2},{"price":64301.6,"quantity":0.05932932,"orderId":1},{"price":64301.5,"quantity":0.000015,"orderId":1},{"price":64301.3,"quantity":0.0174,"orderId":1},{"price":64301.2,"quantity":0.0174,"orderId":1},{"price":64300.7,"quantity":0.0174,"orderId":1},{"price":64300.1,"quantity":0.0174,"orderId":1},{"price":64300,"quantity":0.00151967,"orderId":1},{"price":64299.8,"quantity":0.0174,"orderId":1},{"price":64299.2,"quantity":0.156341,"orderId":1},{"price":64298.7,"quantity":0.12171582,"orderId":1},{"price":64297.8,"quantity":0.11188232,"orderId":1},{"price":64297.7,"quantity":1.20139282,"orderId":1},{"price":64297.6,"quantity":0.08549363,"orderId":1},{"price":64296.8,"quantity":0.31099,"orderId":1},{"price":64296.7,"quantity":0.15545467,"orderId":1},{"price":64296.5,"quantity":0.26,"orderId":1},{"price":64296,"quantity":0.543953,"orderId":1},{"price":64295.8,"quantity":0.00384923,"orderId":2},{"price":64295.4,"quantity":0.15545787,"orderId":1},{"price":64295.2,"quantity":0.086315,"orderId":1},{"price":64295.1,"quantity":0.000015,"orderId":1},{"price":64293.8,"quantity":0.156341,"orderId":1},{"price":64293.7,"quantity":0.46957212,"orderId":1},{"price":64293.5,"quantity":0.07772148,"orderId":1},{"price":64292.3,"quantity":0.03147127,"orderId":1},{"price":64292,"quantity":0.02250192,"orderId":2},{"price":64291.6,"quantity":0.00002822,"orderId":1},{"price":64290.7,"quantity":2.01413049,"orderId":1},{"price":64290.6,"quantity":0.01,"orderId":1},{"price":64290.1,"quantity":0.05866956,"orderId":1},{"price":64289.9,"quantity":0.02930234,"orderId":1},{"price":64289.6,"quantity":0.02260055,"orderId":1},{"price":64289.4,"quantity":0.15547185,"orderId":1},{"price":64288.7,"quantity":0.000015,"orderId":1},{"price":64288,"quantity":0.00031108,"orderId":1},{"price":64286.1,"quantity":0.2809786,"orderId":1},{"price":64286,"quantity":0.156341,"orderId":1},{"price":64285.6,"quantity":0.00163709,"orderId":1},{"price":64285.5,"quantity":0.26,"orderId":1},{"price":64285.2,"quantity":0.02332302,"orderId":1},{"price":64283.9,"quantity":0.00001501,"orderId":1},{"price":64283.6,"quantity":0.00933,"orderId":1},{"price":64283.4,"quantity":0.05866956,"orderId":1},{"price":64283.3,"quantity":0.02354344,"orderId":1},{"price":64282.4,"quantity":0.02635971,"orderId":1},{"price":64282.3,"quantity":0.00001501,"orderId":1},{"price":64279.2,"quantity":0.15600003,"orderId":1},{"price":64279.1,"quantity":0.156341,"orderId":1},{"price":64279,"quantity":0.26,"orderId":1},{"price":64278.8,"quantity":0.02332534,"orderId":1},{"price":64278.4,"quantity":0.001,"orderId":1},{"price":64278.1,"quantity":0.02938807,"orderId":1},{"price":64278,"quantity":0.04898,"orderId":1},{"price":64275.9,"quantity":0.00001501,"orderId":1},{"price":64274.8,"quantity":0.00256777,"orderId":1},{"price":64274.7,"quantity":0.10698,"orderId":1},{"price":64274.4,"quantity":0.05866956,"orderId":1},{"price":64274.1,"quantity":0.02,"orderId":1},{"price":64273.4,"quantity":0.7,"orderId":1},{"price":64272.7,"quantity":0.156341,"orderId":1},{"price":64272.6,"quantity":0.46957212,"orderId":1},{"price":64272.5,"quantity":0.26,"orderId":1},{"price":64272,"quantity":0.00021,"orderId":1},{"price":64270.6,"quantity":0.03731139,"orderId":1},{"price":64269.9,"quantity":0.00021845,"orderId":1},{"price":64269.6,"quantity":0.00610015,"orderId":1},{"price":64269.5,"quantity":0.01831548,"orderId":2},{"price":64269.3,"quantity":0.06218562,"orderId":1},{"price":64268,"quantity":0.00017315,"orderId":1},{"price":64267.6,"quantity":0.04693565,"orderId":1},{"price":64267.2,"quantity":0.00001554,"orderId":1},{"price":64266.2,"quantity":0.72129204,"orderId":2},{"price":64266.1,"quantity":0.077742,"orderId":1},{"price":64266,"quantity":1.20022,"orderId":1},{"price":64263.7,"quantity":0.156341,"orderId":1},{"price":64263.4,"quantity":0.26,"orderId":1},{"price":64263.1,"quantity":0.000015,"orderId":1},{"price":64262.8,"quantity":0.00255895,"orderId":1},{"price":64262.7,"quantity":0.03498801,"orderId":1},{"price":64262.3,"quantity":0.42000007,"orderId":1},{"price":64261.9,"quantity":0.56612387,"orderId":1},{"price":64261.7,"quantity":0.001,"orderId":1},{"price":64260,"quantity":0.0778089,"orderId":1},{"price":64259.3,"quantity":0.05866956,"orderId":1},{"price":64256.7,"quantity":0.00001501,"orderId":1},{"price":64256.2,"quantity":0.28179734,"orderId":1},{"price":64256.1,"quantity":0.46966212,"orderId":2},{"price":64256,"quantity":1.01748225,"orderId":2},{"price":64255.9,"quantity":1.85952575,"orderId":3},{"price":64253.3,"quantity":0.37786,"orderId":1},{"price":64253.2,"quantity":0.059,"orderId":1},{"price":64253.1,"quantity":0.00832637,"orderId":1},{"price":64253,"quantity":0.26,"orderId":1},{"price":64252.6,"quantity":0.41999997,"orderId":3},{"price":64252.5,"quantity":1.50892,"orderId":1},{"price":64252.4,"quantity":0.00046618,"orderId":1},{"price":64251.9,"quantity":0.0476295,"orderId":3},{"price":64250.4,"quantity":0.00092275,"orderId":1},{"price":64250.3,"quantity":0.00831145,"orderId":2},{"price":64250,"quantity":0.00079354,"orderId":1},{"price":64249.7,"quantity":0.156341,"orderId":1},{"price":64248.8,"quantity":0.07161117,"orderId":2},{"price":64248.7,"quantity":0.10703,"orderId":1},{"price":64248.4,"quantity":0.07491349,"orderId":1},{"price":64247.9,"quantity":0.00097461,"orderId":1},{"price":64247.1,"quantity":1.19908,"orderId":1},{"price":64246,"quantity":0.0134817,"orderId":1},{"price":64245.6,"quantity":0.00007027,"orderId":1},{"price":64245.5,"quantity":0.35016948,"orderId":1},{"price":64244.4,"quantity":0.01925475,"orderId":2},{"price":64243.9,"quantity":0.000015,"orderId":1},{"price":64243.5,"quantity":0.156341,"orderId":1},{"price":64243.4,"quantity":0.26,"orderId":1},{"price":64243.3,"quantity":0.00026412,"orderId":1},{"price":64242.8,"quantity":0.02953706,"orderId":1},{"price":64242.2,"quantity":0.02953706,"orderId":1},{"price":64241.8,"quantity":0.02093679,"orderId":1},{"price":64241.5,"quantity":0.02953706,"orderId":1},{"price":64240.8,"quantity":0.12422,"orderId":1},{"price":64240.4,"quantity":0.0517473,"orderId":1},{"price":64239.2,"quantity":0.01617327,"orderId":1},{"price":64238.7,"quantity":0.00002258,"orderId":1},{"price":64237.5,"quantity":0.000015,"orderId":1},{"price":64237.4,"quantity":0.00838016,"orderId":1},{"price":64237.3,"quantity":0.02091251,"orderId":1},{"price":64237.1,"quantity":0.25015241,"orderId":2},{"price":64236.2,"quantity":0.46957212,"orderId":1},{"price":64235.7,"quantity":0.03000256,"orderId":1},{"price":64235,"quantity":0.00646819,"orderId":1},{"price":64234.3,"quantity":0.03000256,"orderId":1},{"price":64234.2,"quantity":0.00003272,"orderId":1},{"price":64233.5,"quantity":0.03109812,"orderId":1},{"price":64233.4,"quantity":0.01,"orderId":1},{"price":64233.3,"quantity":0.00202562,"orderId":1},{"price":64233.1,"quantity":0.03000018,"orderId":1},{"price":64232.7,"quantity":0.08867212,"orderId":2},{"price":64231.6,"quantity":0.04726866,"orderId":2},{"price":64231.3,"quantity":0.03000018,"orderId":1},{"price":64231.2,"quantity":0.03000303,"orderId":1},{"price":64231.1,"quantity":0.00001501,"orderId":1},{"price":64230.9,"quantity":0.26,"orderId":1},{"price":64229.8,"quantity":0.00810552,"orderId":1},{"price":64229.6,"quantity":0.03001451,"orderId":2},{"price":64229.3,"quantity":0.01616737,"orderId":1},{"price":64229,"quantity":0.03000018,"orderId":1},{"price":64228.1,"quantity":0.156341,"orderId":1},{"price":64228,"quantity":0.03000303,"orderId":1},{"price":64227.3,"quantity":0.03000018,"orderId":1},{"price":64226.6,"quantity":0.00001175,"orderId":1},{"price":64226.5,"quantity":0.0600027,"orderId":2},{"price":64226.2,"quantity":0.36302,"orderId":1},{"price":64225.9,"quantity":1.1792,"orderId":1},{"price":64225.7,"quantity":0.03033397,"orderId":2},{"price":64225.5,"quantity":0.05831762,"orderId":1},{"price":64225.4,"quantity":0.12,"orderId":1},{"price":64225.3,"quantity":0.00001934,"orderId":1},{"price":64225,"quantity":0.02999967,"orderId":1},{"price":64224.8,"quantity":0.03000303,"orderId":1},{"price":64224,"quantity":0.00056482,"orderId":1},{"price":64223.6,"quantity":0.00006425,"orderId":1},{"price":64223.4,"quantity":0.00194906,"orderId":1},{"price":64223.3,"quantity":0.06000004,"orderId":2},{"price":64223.2,"quantity":0.03000303,"orderId":1},{"price":64222.7,"quantity":0.12,"orderId":1},{"price":64222.5,"quantity":0.156341,"orderId":1},{"price":64222.2,"quantity":0.02999953,"orderId":1},{"price":64221.9,"quantity":0.06000004,"orderId":2},{"price":64221.7,"quantity":0.03000303,"orderId":1},{"price":64221.5,"quantity":0.30565081,"orderId":3},{"price":64221.4,"quantity":0.01616256,"orderId":1},{"price":64221.3,"quantity":0.24913848,"orderId":1},{"price":64221.2,"quantity":0.03000027,"orderId":1},{"price":64220.6,"quantity":0.12,"orderId":1},{"price":64220.3,"quantity":0.03,"orderId":1},{"price":64220.2,"quantity":0.02999967,"orderId":1},{"price":64220.1,"quantity":0.46957212,"orderId":1},{"price":64219.9,"quantity":0.00001501,"orderId":1},{"price":64219.8,"quantity":0.03000303,"orderId":1},{"price":64219.4,"quantity":0.00002596,"orderId":1},{"price":64219.1,"quantity":0.05866956,"orderId":1},{"price":64218.4,"quantity":0.02999995,"orderId":1},{"price":64218.3,"quantity":0.02999967,"orderId":1},{"price":64217.7,"quantity":0.04693565,"orderId":1},{"price":64217.3,"quantity":0.00869565,"orderId":1},{"price":64217.1,"quantity":0.0161672,"orderId":1},{"price":64217,"quantity":0.02802,"orderId":1},{"price":64216.6,"quantity":0.85714928,"orderId":1},{"price":64216.5,"quantity":0.156341,"orderId":1},{"price":64216.4,"quantity":0.0299999,"orderId":1},{"price":64216.1,"quantity":0.0015314,"orderId":1},{"price":64216,"quantity":0.00562118,"orderId":1},{"price":64215.9,"quantity":0.00001637,"orderId":1},{"price":64215.8,"quantity":0.0296,"orderId":1},{"price":64215.4,"quantity":0.00003328,"orderId":1},{"price":64215.3,"quantity":0.00003912,"orderId":1},{"price":64215,"quantity":0.26,"orderId":1},{"price":64214.9,"quantity":0.02999967,"orderId":1},{"price":64214.8,"quantity":0.00004474,"orderId":1},{"price":64214.6,"quantity":0.00826897,"orderId":2},{"price":64214.5,"quantity":0.01028553,"orderId":1},{"price":64214.3,"quantity":0.03110306,"orderId":1},{"price":64214.2,"quantity":0.02999953,"orderId":1},{"price":64214.1,"quantity":0.15574875,"orderId":1},{"price":64214,"quantity":0.03111387,"orderId":2},{"price":64213.6,"quantity":0.0299999,"orderId":1},{"price":64213.3,"quantity":0.00005274,"orderId":1},{"price":64212.6,"quantity":0.06997809,"orderId":1},{"price":64212.5,"quantity":0.00003,"orderId":1},{"price":64212.1,"quantity":0.02999953,"orderId":1},{"price":64210.4,"quantity":0.0299999,"orderId":1},{"price":64210.1,"quantity":0.00016023,"orderId":1},{"price":64209.8,"quantity":0.02999953,"orderId":1},{"price":64209.4,"quantity":0.03000069,"orderId":1},{"price":64208.3,"quantity":0.0299999,"orderId":1},{"price":64208,"quantity":0.00008825,"orderId":2},{"price":64206.9,"quantity":0.10707,"orderId":1},{"price":64206.5,"quantity":0.00057976,"orderId":1},{"price":64206.2,"quantity":0.02999953,"orderId":1},{"price":64206,"quantity":0.0299999,"orderId":1},{"price":64205.4,"quantity":0.18634053,"orderId":2},{"price":64205.3,"quantity":0.46702641,"orderId":1},{"price":64205.1,"quantity":0.02109765,"orderId":1},{"price":64204,"quantity":0.00404959,"orderId":1},{"price":64203.8,"quantity":0.0299999,"orderId":1},{"price":64203.5,"quantity":0.26,"orderId":1},{"price":64203.3,"quantity":1.52336,"orderId":1},{"price":64202.2,"quantity":0.02999953,"orderId":1},{"price":64202,"quantity":0.24921335,"orderId":1},{"price":64201.6,"quantity":0.0299999,"orderId":1},{"price":64201.1,"quantity":0.05872253,"orderId":2},{"price":64200.2,"quantity":0.156341,"orderId":1},{"price":64200.1,"quantity":0.46957212,"orderId":1},{"price":64200,"quantity":0.59713575,"orderId":98},{"price":64199.9,"quantity":0.03284707,"orderId":5},{"price":64199.8,"quantity":0.0299999,"orderId":1},{"price":64199.4,"quantity":0.02999953,"orderId":1},{"price":64199.3,"quantity":0.03664911,"orderId":2},{"price":64199.2,"quantity":0.00007386,"orderId":1},{"price":64199,"quantity":0.01,"orderId":1},{"price":64198.4,"quantity":0.00001005,"orderId":1},{"price":64198.2,"quantity":0.022,"orderId":1},{"price":64198,"quantity":0.00007788,"orderId":1},{"price":64197.8,"quantity":0.00540849,"orderId":2},{"price":64197.7,"quantity":0.0299999,"orderId":1},{"price":64197,"quantity":0.02999953,"orderId":1},{"price":64196.8,"quantity":0.26001069,"orderId":2},{"price":64196.5,"quantity":0.00005617,"orderId":4},{"price":64195.3,"quantity":0.3586,"orderId":1},{"price":64195.2,"quantity":0.31154977,"orderId":1},{"price":64195,"quantity":0.00002169,"orderId":1},{"price":64194.8,"quantity":0.89314667,"orderId":1},{"price":64192.9,"quantity":0.00001046,"orderId":1},{"price":64192.8,"quantity":0.00778904,"orderId":1},{"price":64192.4,"quantity":0.0000487,"orderId":3},{"price":64192.2,"quantity":0.00017852,"orderId":1},{"price":64192.1,"quantity":0.00006176,"orderId":1},{"price":64191.9,"quantity":0.00001554,"orderId":1},{"price":64190,"quantity":0.01269473,"orderId":6},{"price":64189.8,"quantity":0.0000197,"orderId":1},{"price":64189.6,"quantity":0.00063239,"orderId":2},{"price":64189.4,"quantity":0.00001701,"orderId":1},{"price":64189,"quantity":0.00006001,"orderId":1},{"price":64188.9,"quantity":0.00013657,"orderId":2},{"price":64188.8,"quantity":0.02872106,"orderId":2},{"price":64188.4,"quantity":0.00023244,"orderId":1},{"price":64188.3,"quantity":0.00001009,"orderId":1},{"price":64188.1,"quantity":0.26013152,"orderId":2},{"price":64187.9,"quantity":0.00001501,"orderId":1},{"price":64186.8,"quantity":0.00006068,"orderId":1},{"price":64186.6,"quantity":0.00042383,"orderId":1},{"price":64186,"quantity":0.01557,"orderId":1},{"price":64185.7,"quantity":0.00022218,"orderId":1},{"price":64185.6,"quantity":0.00046693,"orderId":1},{"price":64185.4,"quantity":0.00308108,"orderId":1},{"price":64185,"quantity":0.00017632,"orderId":1},{"price":64184.9,"quantity":1.15163,"orderId":1},{"price":64184.8,"quantity":0.0001656,"orderId":2},{"price":64184.6,"quantity":0.00014625,"orderId":1},{"price":64184.5,"quantity":0.01294161,"orderId":1},{"price":64183.9,"quantity":0.00009732,"orderId":3},{"price":64183.4,"quantity":0.00155728,"orderId":1},{"price":64183.3,"quantity":0.00009585,"orderId":3},{"price":64183.2,"quantity":0.46957212,"orderId":1},{"price":64183.1,"quantity":0.00001689,"orderId":1},{"price":64182.5,"quantity":0.11733913,"orderId":1},{"price":64181.9,"quantity":0.00081956,"orderId":1},{"price":64181.8,"quantity":0.0001155,"orderId":2},{"price":64181.7,"quantity":0.01350533,"orderId":2},{"price":64181.4,"quantity":0.00452218,"orderId":1},{"price":64180,"quantity":0.26079497,"orderId":3},{"price":64179.8,"quantity":0.00025975,"orderId":1},{"price":64179.6,"quantity":0.00007781,"orderId":1},{"price":64179.5,"quantity":0.01617309,"orderId":1},{"price":64179.4,"quantity":0.00001179,"orderId":1},{"price":64179,"quantity":0.00218175,"orderId":1},{"price":64178.3,"quantity":0.00002121,"orderId":1},{"price":64177.9,"quantity":0.00018698,"orderId":1},{"price":64177.8,"quantity":0.00008832,"orderId":1},{"price":64177.5,"quantity":1.5339,"orderId":1},{"price":64176.7,"quantity":0.05174787,"orderId":1},{"price":64176.6,"quantity":0.00023605,"orderId":1},{"price":64176.4,"quantity":0.00006614,"orderId":4},{"price":64176.2,"quantity":0.0161736,"orderId":1},{"price":64176.1,"quantity":0.00077054,"orderId":4},{"price":64176,"quantity":0.02821988,"orderId":1},{"price":64175.5,"quantity":0.00006199,"orderId":1},{"price":64175,"quantity":0.00015582,"orderId":1},{"price":64173.9,"quantity":0.00008627,"orderId":1},{"price":64173.7,"quantity":0.00001538,"orderId":1},{"price":64173.5,"quantity":0.26019284,"orderId":6},{"price":64173,"quantity":0.00022343,"orderId":1},{"price":64172.8,"quantity":0.0000101,"orderId":1},{"price":64172.1,"quantity":0.00004361,"orderId":1},{"price":64171.6,"quantity":0.00671791,"orderId":1},{"price":64171.3,"quantity":0.00007031,"orderId":1},{"price":64171.2,"quantity":0.00003594,"orderId":1},{"price":64170.9,"quantity":0.00360464,"orderId":1},{"price":64170.7,"quantity":0.00647896,"orderId":2},{"price":64170.4,"quantity":0.00001966,"orderId":1},{"price":64170,"quantity":0.00193434,"orderId":1},{"price":64169.7,"quantity":0.00001055,"orderId":1},{"price":64169.2,"quantity":0.00011505,"orderId":1},{"price":64168.1,"quantity":0.00018747,"orderId":1},{"price":64168,"quantity":0.00014295,"orderId":1},{"price":64167.3,"quantity":0.13169971,"orderId":2},{"price":64167,"quantity":0.27606177,"orderId":2},{"price":64166.8,"quantity":0.05866956,"orderId":1},{"price":64166.6,"quantity":0.01579772,"orderId":8},{"price":64166.5,"quantity":1.21037,"orderId":1},{"price":64166.2,"quantity":0.0000878,"orderId":1},{"price":64166.1,"quantity":0.00031091,"orderId":2},{"price":64165.8,"quantity":0.00022552,"orderId":1},{"price":64165,"quantity":0.01619669,"orderId":2},{"price":64164.8,"quantity":0.00090069,"orderId":1},{"price":64164.7,"quantity":0.00005293,"orderId":5},{"price":64164.5,"quantity":0.00012879,"orderId":2},{"price":64164.1,"quantity":0.00024844,"orderId":1},{"price":64163.9,"quantity":0.00001408,"orderId":1},{"price":64163.5,"quantity":0.36192,"orderId":1},{"price":64162.9,"quantity":0.00004323,"orderId":1},{"price":64162.7,"quantity":0.00373585,"orderId":1},{"price":64162.5,"quantity":0.00073106,"orderId":4},{"price":64161.6,"quantity":0.00009364,"orderId":1},{"price":64161.4,"quantity":0.46957212,"orderId":1},{"price":64161.2,"quantity":0.00001014,"orderId":1},{"price":64161.1,"quantity":0.0296,"orderId":1},{"price":64160.5,"quantity":0.26,"orderId":1},{"price":64160,"quantity":0.00119308,"orderId":12},{"price":64159.9,"quantity":0.01564601,"orderId":2},{"price":64159.6,"quantity":1.5,"orderId":1},{"price":64159.1,"quantity":0.00001007,"orderId":1},{"price":64158.8,"quantity":0.00031097,"orderId":2},{"price":64158.3,"quantity":0.00014683,"orderId":1},{"price":64157.5,"quantity":0.00013042,"orderId":3},{"price":64157.3,"quantity":0.00001832,"orderId":1},{"price":64157.1,"quantity":0.01637125,"orderId":2},{"price":64156.9,"quantity":0.24938823,"orderId":1},{"price":64156.8,"quantity":0.00122821,"orderId":1},{"price":64155.9,"quantity":0.000015,"orderId":1},{"price":64155.4,"quantity":0.00002122,"orderId":1},{"price":64154.8,"quantity":0.01021209,"orderId":1},{"price":64154.5,"quantity":0.00086876,"orderId":5}],"prevSeqId":-1,"currentSeqId":31327882680,"checksum":2022234635}
{"action":"update","channel":"books","instrumentId":"BTC-USDT","instAsks":[{"price":64331.1,"quantity":0,"orderId":0},{"price":64331.3,"quantity":0.15601866,"orderId":1},{"price":64333.9,"quantity":0,"orderId":0},{"price":64335.9,"quantity":0.00775059,"orderId":1},{"price":64346.7,"quantity":0.412695,"orderId":1},{"price":64372.5,"quantity":0.661365,"orderId":1},{"price":64401.4,"quantity":1.622025,"orderId":1},{"price":64419.5,"quantity":1.16976442,"orderId":3},{"price":64420.5,"quantity":1.981665,"orderId":1},{"price":64452.6,"quantity":2.700945,"orderId":1},{"price":64501.2,"quantity":0.00001438,"orderId":1},{"price":64503.7,"quantity":0,"orderId":0},{"price":64503.9,"quantity":0,"orderId":0},{"price":64504.2,"quantity":0,"orderId":0},{"price":64505.2,"quantity":0,"orderId":0},{"price":64506.2,"quantity":0,"orderId":0}],"instBids":[{"price":64314.9,"quantity":0.0005,"orderId":1},{"price":64314.7,"quantity":0,"orderId":0},{"price":64314.2,"quantity":0.00833802,"orderId":1},{"price":64313.5,"quantity":0,"orderId":0},{"price":64291.1,"quantity":0.40284,"orderId":1},{"price":64290.7,"quantity":0,"orderId":0},{"price":64286.2,"quantity":2.01413049,"orderId":1},{"price":64265.3,"quantity":0.66798,"orderId":1},{"price":64236.4,"quantity":1.659015,"orderId":1},{"price":64223.4,"quantity":0,"orderId":0},{"price":64221.4,"quantity":0.0181116,"orderId":2},{"price":64220.3,"quantity":2.01477,"orderId":2},{"price":64188.1,"quantity":3.03073652,"orderId":3},{"price":64154.8,"quantity":0,"orderId":0},{"price":64154.5,"quantity":0,"orderId":0}],"prevSeqId":31327882680,"currentSeqId":31327882738,"checksum":-928488838}
{"action":"update","channel":"books","instrumentId":"BTC-USDT","instAsks":[{"price":64325.9,"quantity":0.19202253,"orderId":1},{"price":64327.9,"quantity":0,"orderId":0},{"price":64333.3,"quantity":0.11188234,"orderId":1},{"price":64367.3,"quantity":1.49747523,"orderId":1},{"price":64458.6,"quantity":0,"orderId":0}],"instBids":[{"price":64297.8,"quantity":0.11188234,"orderId":1},{"price":64289.7,"quantity":2.01413049,"orderId":1},{"price":64286.2,"quantity":0,"orderId":0},{"price":64273.5,"quantity":0.42000005,"orderId":1},{"price":64155.4,"quantity":0,"orderId":0}],"prevSeqId":31327882738,"currentSeqId":31327882755,"checksum":694842151}
{"action":"update","channel":"books","instrumentId":"BTC-USDT","instAsks":[{"price":64331.4,"quantity":0,"orderId":0},{"price":64333.1,"quantity":0.11188291,"orderId":1},{"price":64333.3,"quantity":0,"orderId":0},{"price":64367.2,"quantity":2.5849472,"orderId":1},{"price":64367.3,"quantity":0,"orderId":0},{"price":64367.4,"quantity":0,"orderId":0},{"price":64398.2,"quantity":0.0296,"orderId":1},{"price":64431.1,"quantity":0.24832734,"orderId":1},{"price":64476.2,"quantity":0.24815394,"orderId":1},{"price":64503.1,"quantity":0,"orderId":0}],"instBids":[{"price":64297.8,"quantity":0,"orderId":0},{"price":64296.9,"quantity":0.11188291,"orderId":1},{"price":64291.2,"quantity":1.98688628,"orderId":1},{"price":64289.7,"quantity":0,"orderId":0},{"price":64270.5,"quantity":0.0296,"orderId":1},{"price":64216.1,"quantity":0,"orderId":0},{"price":64214.3,"quantity":0.03263445,"orderId":2}],"prevSeqId":31327882755,"currentSeqId":31327882790,"checksum":-997147226}
{"action":"update","channel":"books","instrumentId":"BTC-USDT","instAsks":[{"price":64326,"quantity":0.28895745,"orderId":5},{"price":64342.8,"quantity":0.09612835,"orderId":2},{"price":64342.9,"quantity":0,"orderId":0},{"price":64349.6,"quantity":0.11455824,"orderId":1},{"price":64349.7,"quantity":1.24,"orderId":1}],"instBids":[{"price":64315.1,"quantity":0.0005,"orderId":1},{"price":64315,"quantity":0.0005,"orderId":1},{"price":64314.9,"quantity":0,"orderId":0},{"price":64314.8,"quantity":0.22,"orderId":1},{"price":64305.6,"quantity":0.09902173,"orderId":1},{"price":64305.5,"quantity":0,"orderId":0},{"price":64298.8,"quantity":0.10955772,"orderId":1},{"price":64298.7,"quantity":0,"orderId":0},{"price":64297.8,"quantity":0.11188264,"orderId":1},{"price":64296.9,"quantity":0,"orderId":0},{"price":64221.4,"quantity":0.01616256,"orderId":1},{"price":64221.3,"quantity":0.25108752,"orderId":2},{"price":64214.3,"quantity":0.03110306,"orderId":1},{"price":64213.7,"quantity":0.00153138,"orderId":1},{"price":64156.8,"quantity":0,"orderId":0},{"price":64155.9,"quantity":0,"orderId":0}],"prevSeqId":31327882790,"currentSeqId":31327882822,"checksum":-110250786}
{"action":"update","channel":"books","instrumentId":"BTC-USDT","instAsks":[{"price":64324,"quantity":0.6487124,"orderId":11},{"price":64325.9,"quantity":0,"orderId":0},{"price":64327.9,"quantity":0.04848008,"orderId":1},{"price":64329.8,"quantity":0.13200009,"orderId":1},{"price":64331.3,"quantity":0,"orderId":0},{"price":64332.5,"quantity":0.00003105,"orderId":1},{"price":64333,"quantity":0.06712975,"orderId":1},{"price":64337,"quantity":0.26,"orderId":1},{"price":64501.2,"quantity":0,"orderId":0},{"price":64501.8,"quantity":0,"orderId":0}],"instBids":[{"price":64315.1,"quantity":0,"orderId":0},{"price":64314.9,"quantity":0.0005,"orderId":1},{"price":64291.7,"quantity":1.98688628,"orderId":1},{"price":64291.2,"quantity":0,"orderId":0}],"prevSeqId":31327882822,"currentSeqId":31327882838,"checksum":-980263755}
{"action":"update","channel":"books","instrumentId":"BTC-USDT","instAsks":[{"price":64332.8,"quantity":0.06712991,"orderId":1},{"price":64332.9,"quantity":0.11188316,"orderId":1},{"price":64333,"quantity":0,"orderId":0},{"price":64333.1,"quantity":0,"orderId":0}],"instBids":[{"price":64314.7,"quantity":0.00833802,"orderId":1},{"price":64314.2,"quantity":0,"orderId":0},{"price":64297.8,"quantity":0,"orderId":0},{"price":64296.9,"quantity":0.1118831,"orderId":1},{"price":64291.7,"quantity":0,"orderId":0},{"price":64286.2,"quantity":1.98688628,"orderId":1}],"prevSeqId":31327882838,"currentSeqId":31327882858,"checksum":1602906519}
{"action":"update","channel":"books","instrumentId":"BTC-USDT","instAsks":[{"price":64330.5,"quantity":0.26,"orderId":1},{"price":64501,"quantity":0,"orderId":0}],"instBids":[{"price":64291.7,"quantity":1.98688628,"orderId":1},{"price":64286.2,"quantity":0,"orderId":0}],"prevSeqId":31327882858,"currentSeqId":31327882864,"checksum":2105224073}
{"action":"update","channel":"books","instrumentId":"BTC-USDT","instAsks":[{"price":64324,"quantity":0.19576,"orderId":5},{"price":64325.9,"quantity":0.06677815,"orderId":1},{"price":64326,"quantity":0.0912896,"orderId":2},{"price":64327.9,"quantity":0,"orderId":0},{"price":64328.7,"quantity":0,"orderId":0},{"price":64328.8,"quantity":0.01106532,"orderId":1},{"price":64330.5,"quantity":0,"orderId":0},{"price":64332.9,"quantity":0,"orderId":0},{"price":64333.2,"quantity":0,"orderId":0},{"price":64333.9,"quantity":0.00775059,"orderId":1},{"price":64335.9,"quantity":0,"orderId":0},{"price":64336.9,"quantity":0.11187986,"orderId":1},{"price":64481.1,"quantity":0.0000103,"orderId":1},{"price":64482.4,"quantity":0.00646819,"orderId":1},{"price":64484.8,"quantity":0.00003312,"orderId":2},{"price":64485.4,"quantity":0.01616971,"orderId":1}],"instBids":[{"price":64323.9,"quantity":0.29968667,"orderId":5},{"price":64322,"quantity":0.0808,"orderId":1},{"price":64317.4,"quantity":0.4546847,"orderId":3},{"price":64315.1,"quantity":0.0005,"orderId":1},{"price":64314.9,"quantity":0,"orderId":0},{"price":64314.7,"quantity":0,"orderId":0},{"price":64312.8,"quantity":0.156341,"orderId":1},{"price":64299.3,"quantity":0.11188109,"orderId":1},{"price":64298.2,"quantity":0.0015,"orderId":1},{"price":64296.9,"quantity":0,"orderId":0},{"price":64291.7,"quantity":0,"orderId":0},{"price":64288.8,"quantity":1.98688628,"orderId":1},{"price":64157.1,"quantity":0,"orderId":0},{"price":64156.9,"quantity":0,"orderId":0}],"prevSeqId":31327882864,"currentSeqId":31327882912,"checksum":-62608298}
{"action":"update","channel":"books","instrumentId":"BTC-USDT","instAsks":[{"price":64324,"quantity":0.4440639,"orderId":6},{"price":64325.1,"quantity":0.143273,"orderId":1},{"price":64325.9,"quantity":0,"orderId":0},{"price":64326.2,"quantity":0.00468517,"orderId":1},{"price":64327.9,"quantity":0.04848006,"orderId":1},{"price":64328.8,"quantity":0,"orderId":0},{"price":64332.8,"quantity":0.03509351,"orderId":1},{"price":64333.9,"quantity":0,"orderId":0},{"price":64335.9,"quantity":0.00775059,"orderId":1},{"price":64500.9,"quantity":0,"orderId":0}],"instBids":[{"price":64323.9,"quantity":0.31718667,"orderId":6},{"price":64298.1,"quantity":0.01555253,"orderId":1},{"price":64291.7,"quantity":1.98688628,"orderId":1},{"price":64288.8,"quantity":0,"orderId":0},{"price":64157.3,"quantity":0,"orderId":0}],"prevSeqId":31327882912,"currentSeqId":31327882935,"checksum":2066730219}
{"action":"update","channel":"books","instrumentId":"BTC-USDT","instAsks":[{"price":64324,"quantity":0.26004034,"orderId":5},{"price":64325,"quantity":0.13280318,"orderId":2},{"price":64327.9,"quantity":0,"orderId":0},{"price":64329.8,"quantity":0,"orderId":0},{"price":64329.9,"quantity":0,"orderId":0},{"price":64331.8,"quantity":0.09322187,"orderId":1},{"price":64333.7,"quantity":0.05968139,"orderId":1},{"price":64367.2,"quantity":0,"orderId":0},{"price":64369.4,"quantity":2.5849472,"orderId":1}],"instBids":[{"price":64319.4,"quantity":0.22,"orderId":1},{"price":64314.8,"quantity":0,"orderId":0},{"price":64304.5,"quantity":0.023307,"orderId":1},{"price":64301.8,"quantity":0.11187595,"orderId":1},{"price":64299.3,"quantity":0,"orderId":0},{"price":64214.3,"quantity":0.03263438,"orderId":2},{"price":64213.7,"quantity":0,"orderId":0}],"prevSeqId":31327882935,"currentSeqId":31327882976,"checksum":-1097923895}
{"action":"update","channel":"books","instrumentId":"BTC-USDT","instAsks":[{"price":64391.1,"quantity":0,"orderId":0},{"price":64500.9,"quantity":0.00004963,"orderId":2}],"instBids":[{"price":64319.4,"quantity":0,"orderId":0},{"price":64298.5,"quantity":0.01555245,"orderId":1},{"price":64298.1,"quantity":0,"orderId":0},{"price":64157.3,"quantity":0.00001832,"orderId":1}],"prevSeqId":31327882976,"currentSeqId":31327882984,"checksum":-1512284208}
{"action":"update","channel":"books","instrumentId":"BTC-USDT","instAsks":[{"price":64328.9,"quantity":0.01106532,"orderId":1},{"price":64336.9,"quantity":0,"orderId":0},{"price":64338,"quantity":0.11187435,"orderId":1},{"price":64367.7,"quantity":1.55096835,"orderId":1},{"price":64367.8,"quantity":2.5849472,"orderId":1},{"price":64369.4,"quantity":0,"orderId":0},{"price":64391.8,"quantity":0.01294161,"orderId":1},{"price":64499.9,"quantity":0,"orderId":0},{"price":64500,"quantity":0,"orderId":0},{"price":64500.9,"quantity":0,"orderId":0}],"instBids":[{"price":64317.1,"quantity":0.00833802,"orderId":1},{"price":64315.1,"quantity":0,"orderId":0},{"price":64314.9,"quantity":0.0005,"orderId":1},{"price":64302.9,"quantity":0.11187435,"orderId":1},{"price":64301.8,"quantity":0,"orderId":0},{"price":64263.8,"quantity":0.15600002,"orderId":1},{"price":64252.6,"quantity":0.18736573,"orderId":2},{"price":64157.5,"quantity":0,"orderId":0},{"price":64157.3,"quantity":0,"orderId":0}],"prevSeqId":31327882984,"currentSeqId":31327883006,"checksum":-581499187}
{"action":"update","channel":"books","instrumentId":"BTC-USDT","instAsks":[{"price":64324,"quantity":0.36693678,"orderId":7},{"price":64325,"quantity":0,"orderId":0},{"price":64327.9,"quantity":0.04848005,"orderId":1},{"price":64367.6,"quantity":2.5849472,"orderId":1},{"price":64367.7,"quantity":0,"orderId":0},{"price":64367.8,"quantity":0,"orderId":0},{"price":64499.9,"quantity":0.00236431,"orderId":7}],"instBids":[],"prevSeqId":31327883006,"currentSeqId":31327883016,"checksum":643581636}
{"action":"update","channel":"books","instrumentId":"BTC-USDT","instAsks":[{"price":64324,"quantity":0.32611453,"orderId":7},{"price":64337.9,"quantity":0.11187317,"orderId":1},{"price":64338,"quantity":0,"orderId":0}],"instBids":[{"price":64315.1,"quantity":0.0005,"orderId":1},{"price":64314.9,"quantity":0,"orderId":0}],"prevSeqId":31327883016,"currentSeqId":31327883025,"checksum":1021964080}
{"action":"update","channel":"books","instrumentId":"BTC-USDT","instAsks":[{"price":64324,"quantity":0.27142624,"orderId":6},{"price":64325,"quantity":0.14354873,"orderId":1},{"price":64327.9,"quantity":0,"orderId":0},{"price":64337.9,"quantity":0,"orderId":0},{"price":64338.8,"quantity":0.11187267,"orderId":1}],"instBids":[{"price":64304.1,"quantity":0.11187267,"orderId":1},{"price":64302.9,"quantity":0,"orderId":0},{"price":64216,"quantity":0,"orderId":0},{"price":64157.5,"quantity":0.00013042,"orderId":3}],"prevSeqId":31327883025,"currentSeqId":31327883043,"checksum":1159077742}
{"action":"update","channel":"books","instrumentId":"BTC-USDT","instAsks":[{"price":64324,"quantity":0.20418034,"orderId":4},{"price":64328.9,"quantity":0,"orderId":0},{"price":64367.6,"quantity":0,"orderId":0},{"price":64374.4,"quantity":2.62319019,"orderId":1},{"price":64500,"quantity":3.46297616,"orderId":97}],"instBids":[{"price":64317.1,"quantity":0,"orderId":0},{"price":64316.9,"quantity":0.05866956,"orderId":1},{"price":64315.2,"quantity":0.0005,"orderId":1},{"price":64315,"quantity":0,"orderId":0},{"price":64304.1,"quantity":0,"orderId":0},{"price":64302.9,"quantity":0.11187289,"orderId":1}],"prevSeqId":31327883043,"currentSeqId":31327883056,"checksum":1785344633}
{"action":"update","channel":"books","instrumentId":"BTC-USDT","instAsks":[{"price":64373.7,"quantity":2.62998735,"orderId":2},{"price":64374.4,"quantity":0,"orderId":0},{"price":64500.9,"quantity":0.00004963,"orderId":2}],"instBids":[{"price":64319.4,"quantity":0.22,"orderId":1},{"price":64315.2,"quantity":0,"orderId":0},{"price":64315,"quantity":0.0005,"orderId":1},{"price":64157.5,"quantity":0,"orderId":0}],"prevSeqId":31327883056,"currentSeqId":31327883065,"checksum":1771981280}
{"action":"update","channel":"books","instrumentId":"BTC-USDT","instAsks":[{"price":64367.8,"quantity":2.62319019,"orderId":1},{"price":64373.7,"quantity":0.00679716,"orderId":1},{"price":64500.9,"quantity":0,"orderId":0}],"instBids":[{"price":64216.7,"quantity":0.00562112,"orderId":1},{"price":64158.3,"quantity":0,"orderId":0}],"prevSeqId":31327883065,"currentSeqId":31327883072,"checksum":1771981280}
{"action":"update","channel":"books","instrumentId":"BTC-USDT","instAsks":[{"price":64409.8,"quantity":0.09417757,"orderId":1},{"price":64410.5,"quantity":0,"orderId":0},{"price":64411.8,"quantity":0,"orderId":0},{"price":64431.1,"quantity":0,"orderId":0},{"price":64476.2,"quantity":0,"orderId":0},{"price":64500.9,"quantity":0.00004963,"orderId":2},{"price":64501,"quantity":0.016331,"orderId":1},{"price":64501.2,"quantity":0.00001438,"orderId":1}],"instBids":[{"price":64315.1,"quantity":0,"orderId":0},{"price":64314.9,"quantity":0.0005,"orderId":1},{"price":64248.8,"quantity":0.05866956,"orderId":1},{"price":64240.4,"quantity":0,"orderId":0},{"price":64239.8,"quantity":0.05174682,"orderId":1},{"price":64221.3,"quantity":0.00194904,"orderId":1},{"price":64202,"quantity":0,"orderId":0},{"price":64184.5,"quantity":0,"orderId":0},{"price":64158.3,"quantity":0.00014683,"orderId":1},{"price":64157.5,"quantity":0.00013042,"orderId":3}],"prevSeqId":31327883072,"currentSeqId":31327883093,"checksum":-1179306728}
{"action":"update","channel":"books","instrumentId":"BTC-USDT","instAsks":[{"price":64338,"quantity":0.11187312,"orderId":1},{"price":64338.8,"quantity":0,"orderId":0}],"instBids":[{"price":64250.1,"quantity":0.01294187,"orderId":1},{"price":64221.4,"quantity":0,"orderId":0},{"price":64221.3,"quantity":0.25108752,"orderId":2},{"price":64202,"quantity":0.24921335,"orderId":1},{"price":64185.8,"quantity":0.01294187,"orderId":1},{"price":64158.3,"quantity":0,"orderId":0},{"price":64157.5,"quantity":0,"orderId":0}],"prevSeqId":31327883093,"currentSeqId":31327883101,"checksum":837335546}
{"action":"update","channel":"books","instrumentId":"BTC-USDT","instAsks":[{"price":64338,"quantity":0.1118739,"orderId":1},{"price":64367.6,"quantity":2.62319019,"orderId":1},{"price":64367.8,"quantity":0,"orderId":0}],"instBids":[{"price":64315.1,"quantity":0.0005,"orderId":1},{"price":64314.9,"quantity":0,"orderId":0},{"price":64232.3,"quantity":0.01616986,"orderId":1},{"price":64231.6,"quantity":0.03109895,"orderId":1},{"price":64229.3,"quantity":0,"orderId":0},{"price":64222.1,"quantity":0.01616273,"orderId":1},{"price":64168,"quantity":0.01631281,"orderId":2},{"price":64167.3,"quantity":0.11553,"orderId":1},{"price":64158.8,"quantity":0,"orderId":0}],"prevSeqId":31327883101,"currentSeqId":31327883125,"checksum":-1463695816}
{"action":"update","channel":"books","instrumentId":"BTC-USDT","instAsks":[{"price":64338,"quantity":0.11187361,"orderId":1}],"instBids":[{"price":64319.4,"quantity":0,"orderId":0},{"price":64306.5,"quantity":0.15549,"orderId":1},{"price":64306.4,"quantity":0,"orderId":0},{"price":64302.9,"quantity":0.11187361,"orderId":1},{"price":64296.9,"quantity":0.31099,"orderId":1},{"price":64296.8,"quantity":0,"orderId":0},{"price":64229.3,"quantity":0.01616737,"orderId":1},{"price":64221.4,"quantity":0.00194902,"orderId":1},{"price":64221.3,"quantity":0.24913848,"orderId":1},{"price":64159.1,"quantity":0,"orderId":0}],"prevSeqId":31327883125,"currentSeqId":31327883180,"checksum":2072317971}
{"action":"update","channel":"books","instrumentId":"BTC-USDT","instAsks":[{"price":64325,"quantity":0,"orderId":0},{"price":64327.9,"quantity":0.04848001,"orderId":1}],"instBids":[{"price":64306.6,"quantity":0.15549,"orderId":1},{"price":64306.5,"quantity":0,"orderId":0},{"price":64297,"quantity":0.31099,"orderId":1},{"price":64296.9,"quantity":0,"orderId":0},{"price":64217.1,"quantity":0,"orderId":0},{"price":64180.8,"quantity":0.01617342,"orderId":1},{"price":64179.5,"quantity":0,"orderId":0},{"price":64159.1,"quantity":0.00001007,"orderId":1}],"prevSeqId":31327883180,"currentSeqId":31327883310,"checksum":-664125219}
{"action":"update","channel":"books","instrumentId":"BTC-USDT","instAsks":[{"price":64325,"quantity":0.1254841,"orderId":1},{"price":64327.9,"quantity":0,"orderId":0},{"price":64338,"quantity":0.11187412,"orderId":1}],"instBids":[{"price":64217.8,"quantity":0.01616735,"orderId":1},{"price":64159.1,"quantity":0,"orderId":0}],"prevSeqId":31327883310,"currentSeqId":31327883319,"checksum":385876404}
{"action":"update","channel":"books","instrumentId":"BTC-USDT","instAsks":[],"instBids":[{"price":64221.3,"quantity":0,"orderId":0},{"price":64202,"quantity":0,"orderId":0},{"price":64166.8,"quantity":0.05878526,"orderId":2},{"price":64159.1,"quantity":0.00001007,"orderId":1},{"price":64158.8,"quantity":0.00031097,"orderId":2}],"prevSeqId":31327883319,"currentSeqId":31327883326,"checksum":385876404}
{"action":"update","channel":"books","instrumentId":"BTC-USDT","instAsks":[{"price":64325,"quantity":0,"orderId":0},{"price":64325.9,"quantity":0.05758489,"orderId":1},{"price":64338,"quantity":0,"orderId":0},{"price":64340.6,"quantity":0.11187024,"orderId":1},{"price":64340.7,"quantity":0,"orderId":0},{"price":64342.3,"quantity":0,"orderId":0},{"price":64343.2,"quantity":0,"orderId":0},{"price":64351.7,"quantity":0,"orderId":0},{"price":64402.9,"quantity":0,"orderId":0},{"price":64404.9,"quantity":0.16410438,"orderId":2},{"price":64410.3,"quantity":0.00776274,"orderId":1},{"price":64411.8,"quantity":0.24840173,"orderId":1},{"price":64412.3,"quantity":0,"orderId":0},{"price":64431.1,"quantity":0.24832734,"orderId":1},{"price":64476.2,"quantity":0.24815394,"orderId":1},{"price":64501.8,"quantity":0.00007459,"orderId":1},{"price":64503.1,"quantity":0.0001601,"orderId":1}],"instBids":[{"price":64323.9,"quantity":0.32636667,"orderId":7},{"price":64305.7,"quantity":0.11187024,"orderId":1},{"price":64302.9,"quantity":0,"orderId":0},{"price":64286.7,"quantity":0.02613967,"orderId":1},{"price":64285.3,"quantity":1.20851,"orderId":1},{"price":64283.3,"quantity":0,"orderId":0},{"price":64282.4,"quantity":0,"orderId":0},{"price":64221.3,"quantity":0.24913848,"orderId":1},{"price":64215.4,"quantity":0.00781958,"orderId":2},{"price":64214,"quantity":0.0233274,"orderId":1},{"price":64202,"quantity":0.24921335,"orderId":1},{"price":64192.8,"quantity":0,"orderId":0},{"price":64191.7,"quantity":0.00778917,"orderId":1},{"price":64166.5,"quantity":0,"orderId":0},{"price":64158.8,"quantity":0,"orderId":0}],"prevSeqId":31327883326,"currentSeqId":31327883363,"checksum":-1727897907}
{"action":"update","channel":"books","instrumentId":"BTC-USDT","instAsks":[{"price":64324,"quantity":0.18918034,"orderId":3},{"price":64325.9,"quantity":0,"orderId":0},{"price":64327.9,"quantity":0.0625374,"orderId":1},{"price":64337,"quantity":0,"orderId":0},{"price":64340.1,"quantity":0.11187092,"orderId":1},{"price":64340.6,"quantity":0,"orderId":0},{"price":64341.8,"quantity":0.03307805,"orderId":1},{"price":64342.4,"quantity":0.15600006,"orderId":1},{"price":64363.3,"quantity":0,"orderId":0},{"price":64366.9,"quantity":0.02515672,"orderId":1},{"price":64367.6,"quantity":0,"orderId":0},{"price":64368,"quantity":2.66175933,"orderId":2},{"price":64451.8,"quantity":1.59729389,"orderId":2},{"price":64476.2,"quantity":0,"orderId":0},{"price":64503.7,"quantity":0.00004319,"orderId":1},{"price":64503.9,"quantity":0.01258346,"orderId":1}],"instBids":[{"price":64315.2,"quantity":0.0005,"orderId":1},{"price":64315,"quantity":0,"orderId":0},{"price":64305.7,"quantity":0,"orderId":0},{"price":64304.6,"quantity":0.11187092,"orderId":1},{"price":64303.8,"quantity":0.00933,"orderId":1},{"price":64301.2,"quantity":0.03295179,"orderId":2},{"price":64298.5,"quantity":0,"orderId":0},{"price":64295.8,"quantity":1.98719811,"orderId":3},{"price":64291.7,"quantity":0,"orderId":0},{"price":64287,"quantity":0.02602595,"orderId":1},{"price":64283.6,"quantity":0,"orderId":0},{"price":64274.5,"quantity":0.42000009,"orderId":1},{"price":64274.2,"quantity":0.7,"orderId":1},{"price":64273.5,"quantity":0,"orderId":0},{"price":64273.4,"quantity":0,"orderId":0},{"price":64158.8,"quantity":0.00031097,"orderId":2}],"prevSeqId":31327883363,"currentSeqId":31327883407,"checksum":-1621154029}
{"action":"update","channel":"books","instrumentId":"BTC-USDT","instAsks":[{"price":64325.9,"quantity":0.04703042,"orderId":1},{"price":64327.9,"quantity":0,"orderId":0},{"price":64337,"quantity":0.26,"orderId":1},{"price":64338,"quantity":0.11187269,"orderId":1},{"price":64340.1,"quantity":0,"orderId":0},{"price":64368,"quantity":0.00045193,"orderId":1},{"price":64369.5,"quantity":2.69084446,"orderId":2},{"price":64431.1,"quantity":0,"orderId":0}],"instBids":[{"price":64323.9,"quantity":0.32792128,"orderId":8},{"price":64320.1,"quantity":0.22,"orderId":1},{"price":64317.4,"quantity":0.1946847,"orderId":2},{"price":64315.2,"quantity":0,"orderId":0},{"price":64315,"quantity":0.0005,"orderId":1},{"price":64304.6,"quantity":0,"orderId":0},{"price":64302.9,"quantity":0.11187269,"orderId":1},{"price":64158.8,"quantity":0,"orderId":0}],"prevSeqId":31327883407,"currentSeqId":31327883427,"checksum":-338225973}
{"action":"update","channel":"books","instrumentId":"BTC-USDT","instAsks":[{"price":64324,"quantity":0.27043606,"orderId":4},{"price":64338,"quantity":0,"orderId":0},{"price":64338.8,"quantity":0.11187276,"orderId":1},{"price":64367.8,"quantity":2.6613074,"orderId":1},{"price":64369.5,"quantity":0.02953706,"orderId":1},{"price":64414.9,"quantity":0,"orderId":0},{"price":64415.6,"quantity":0.0827471,"orderId":2}],"instBids":[{"price":64317.4,"quantity":0.4546847,"orderId":3},{"price":64176.7,"quantity":0,"orderId":0},{"price":64176.1,"quantity":0.05251784,"orderId":5},{"price":64158.8,"quantity":0.00031097,"orderId":2}],"prevSeqId":31327883427,"currentSeqId":31327883437,"checksum":749775694}
{"action":"update","channel":"books","instrumentId":"BTC-USDT","instAsks":[{"price":64324,"quantity":0.34119606,"orderId":6},{"price":64325,"quantity":0.14354867,"orderId":1},{"price":64325.9,"quantity":0,"orderId":0},{"price":64336.9,"quantity":0.1118756,"orderId":1},{"price":64338.8,"quantity":0,"orderId":0},{"price":64339.7,"quantity":0.05866956,"orderId":1},{"price":64503.9,"quantity":0,"orderId":0}],"instBids":[{"price":64323.9,"quantity":0.30134128,"orderId":6},{"price":64320.1,"quantity":0,"orderId":0},{"price":64316.9,"quantity":0,"orderId":0},{"price":64302.9,"quantity":0,"orderId":0},{"price":64301.8,"quantity":0.1118756,"orderId":1},{"price":64295.8,"quantity":0.00384923,"orderId":2},{"price":64291.2,"quantity":1.98334888,"orderId":1},{"price":64158.3,"quantity":0.00014683,"orderId":1}],"prevSeqId":31327883437,"currentSeqId":31327883460,"checksum":-281526049}
{"action":"update","channel":"books","instrumentId":"BTC-USDT","instAsks":[{"price":64324,"quantity":0.35258196,"orderId":7},{"price":64329.1,"quantity":0.01106532,"orderId":1},{"price":64366.8,"quantity":1.59678446,"orderId":1},{"price":64409.8,"quantity":0,"orderId":0},{"price":64410.5,"quantity":0.14904107,"orderId":1},{"price":64434.4,"quantity":0,"orderId":0},{"price":64451.8,"quantity":0.18618543,"orderId":1},{"price":64503.7,"quantity":0,"orderId":0}],"instBids":[{"price":64323.9,"quantity":0.19254128,"orderId":5},{"price":64317.4,"quantity":0.1946847,"orderId":2},{"price":64316.7,"quantity":0.00833802,"orderId":1},{"price":64315.3,"quantity":0.0005,"orderId":1},{"price":64315.2,"quantity":0.0005,"orderId":1},{"price":64315.1,"quantity":0,"orderId":0},{"price":64315,"quantity":0,"orderId":0},{"price":64303.8,"quantity":0,"orderId":0},{"price":64289.9,"quantity":0.03863234,"orderId":2},{"price":64279.3,"quantity":0.00072713,"orderId":1},{"price":64158.3,"quantity":0,"orderId":0}],"prevSeqId":31327883460,"currentSeqId":31327883477,"checksum":-715355552}
{"action":"update","channel":"books","instrumentId":"BTC-USDT","instAsks":[],"instBids":[{"price":64315.3,"quantity":0,"orderId":0},{"price":64315.1,"quantity":0.0005,"orderId":1},{"price":64216.7,"quantity":0,"orderId":0},{"price":64199.1,"quantity":0.00778827,"orderId":1},{"price":64188.8,"quantity":0.02093154,"orderId":1}],"prevSeqId":31327883477,"currentSeqId":31327883489,"checksum":1705235502}
{"action":"update","channel":"books","instrumentId":"BTC-USDT","instAsks":[{"price":64366.8,"quantity":2.6613074,"orderId":1},{"price":64367.8,"quantity":0,"orderId":0},{"price":64404.9,"quantity":0.156341,"orderId":1},{"price":64406.9,"quantity":0.00776314,"orderId":1},{"price":64431.1,"quantity":0.24832734,"orderId":1},{"price":64476.2,"quantity":0.24815394,"orderId":1},{"price":64501.8,"quantity":0,"orderId":0},{"price":64503.1,"quantity":0,"orderId":0}],"instBids":[{"price":64323.9,"quantity":0.16824128,"orderId":3},{"price":64316.7,"quantity":0,"orderId":0},{"price":64315.8,"quantity":0.00833802,"orderId":1},{"price":64301.8,"quantity":0,"orderId":0},{"price":64300.8,"quantity":0.11187763,"orderId":1},{"price":64291.2,"quantity":0,"orderId":0},{"price":64290.2,"quantity":1.99322354,"orderId":1}],"prevSeqId":31327883489,"currentSeqId":31327883510,"checksum":360543701}
{"action":"update","channel":"books","instrumentId":"BTC-USDT","instAsks":[{"price":64405.7,"quantity":0.00776329,"orderId":1},{"price":64410.3,"quantity":0,"orderId":0}],"instBids":[{"price":64323.7,"quantity":0.0155468,"orderId":1},{"price":64322,"quantity":0,"orderId":0},{"price":64315.8,"quantity":0,"orderId":0},{"price":64314.9,"quantity":0.00833802,"orderId":1},{"price":64312.8,"quantity":0,"orderId":0},{"price":64301.4,"quantity":0.0015,"orderId":1},{"price":64301.2,"quantity":0.57686879,"orderId":3},{"price":64300.8,"quantity":0,"orderId":0},{"price":64300.2,"quantity":0.11187823,"orderId":1},{"price":64296,"quantity":0,"orderId":0},{"price":64290.2,"quantity":0,"orderId":0},{"price":64290.1,"quantity":2.0518931,"orderId":2},{"price":64158.3,"quantity":0.00014683,"orderId":1},{"price":64157.5,"quantity":0.00013042,"orderId":3}],"prevSeqId":31327883510,"currentSeqId":31327883532,"checksum":-2016078406}
{"action":"update","channel":"books","instrumentId":"BTC-USDT","instAsks":[{"price":64387.7,"quantity":0,"orderId":0},{"price":64389,"quantity":0.02348143,"orderId":2},{"price":64452.1,"quantity":0,"orderId":0},{"price":64453.4,"quantity":0.01348143,"orderId":1},{"price":64501.8,"quantity":0.00007459,"orderId":1}],"instBids":[{"price":64290.1,"quantity":0.05866956,"orderId":1},{"price":64288.1,"quantity":1.99322354,"orderId":1},{"price":64246,"quantity":0,"orderId":0},{"price":64244.7,"quantity":0.01348143,"orderId":1},{"price":64220.2,"quantity":0.03562048,"orderId":2},{"price":64181.7,"quantity":0.00002363,"orderId":1},{"price":64180.4,"quantity":0.01348143,"orderId":1},{"price":64158.3,"quantity":0,"orderId":0},{"price":64157.5,"quantity":0,"orderId":0}],"prevSeqId":31327883532,"currentSeqId":31327883548,"checksum":-2016078406}
{"action":"update","channel":"books","instrumentId":"BTC-USDT","instAsks":[],"instBids":[{"price":64322,"quantity":0.0808,"orderId":1},{"price":64289.9,"quantity":2.03185588,"orderId":3},{"price":64288.1,"quantity":0,"orderId":0},{"price":64199.1,"quantity":0,"orderId":0},{"price":64188.8,"quantity":0.02872106,"orderId":2},{"price":64158.3,"quantity":0.00014683,"orderId":1}],"prevSeqId":31327883548,"currentSeqId":31327883555,"checksum":-765055589}
{"action":"update","channel":"books","instrumentId":"BTC-USDT","instAsks":[],"instBids":[{"price":64315.6,"quantity":0.02373802,"orderId":2},{"price":64314.9,"quantity":0,"orderId":0},{"price":64301.8,"quantity":0.11187641,"orderId":1},{"price":64300.2,"quantity":0,"orderId":0},{"price":64289.9,"quantity":0.03863234,"orderId":2},{"price":64289.7,"quantity":1.99322354,"orderId":1}],"prevSeqId":31327883555,"currentSeqId":31327883569,"checksum":-1268515944}
{"action":"update","channel":"books","instrumentId":"BTC-USDT","instAsks":[],"instBids":[{"price":64318.1,"quantity":0.22,"orderId":1},{"price":64289.7,"quantity":0,"orderId":0},{"price":64288.1,"quantity":1.99322354,"orderId":1},{"price":64158.3,"quantity":0,"orderId":0}],"prevSeqId":31327883569,"currentSeqId":31327883578,"checksum":-1478674304}
{"action":"update","channel":"books","instrumentId":"BTC-USDT","instAsks":[],"instBids":[{"price":64289.7,"quantity":1.99322354,"orderId":1},{"price":64288.1,"quantity":0,"orderId":0}],"prevSeqId":31327883578,"currentSeqId":31327883580,"checksum":-1478674304}
{"action":"update","channel":"books","instrumentId":"BTC-USDT","instAsks":[{"price":64366.8,"quantity":0,"orderId":0},{"price":64367.8,"quantity":2.6825506,"orderId":1},{"price":64448.7,"quantity":0,"orderId":0},{"price":64449.4,"quantity":0.01616256,"orderId":1}],"instBids":[{"price":64301.8,"quantity":0,"orderId":0},{"price":64301.3,"quantity":0.12927721,"orderId":2},{"price":64292,"quantity":2.01572546,"orderId":3},{"price":64289.7,"quantity":0,"orderId":0},{"price":64158.3,"quantity":0.00014683,"orderId":1},{"price":64157.5,"quantity":0.00013042,"orderId":3}],"prevSeqId":31327883580,"currentSeqId":31327883590,"checksum":-1478674304}
{"action":"update","channel":"books","instrumentId":"BTC-USDT","instAsks":[{"price":64336.9,"quantity":0.11187956,"orderId":1},{"price":64366.8,"quantity":1.62462443,"orderId":1},{"price":64409.8,"quantity":0.09417754,"orderId":1},{"price":64410.5,"quantity":0,"orderId":0},{"price":64411.8,"quantity":0,"orderId":0},{"price":64431.1,"quantity":0,"orderId":0},{"price":64476.2,"quantity":0,"orderId":0},{"price":64503.1,"quantity":0.0001601,"orderId":1},{"price":64503.7,"quantity":0.00004319,"orderId":1}],"instBids":[{"price":64322,"quantity":0,"orderId":0},{"price":64318.1,"quantity":0,"orderId":0},{"price":64315.6,"quantity":0.0154,"orderId":1},{"price":64315.4,"quantity":0.00833802,"orderId":1},{"price":64301.3,"quantity":0.0174,"orderId":1},{"price":64299.3,"quantity":0.11187951,"orderId":1},{"price":64292,"quantity":0.02250192,"orderId":2},{"price":64288.1,"quantity":1.99322354,"orderId":1},{"price":64221.3,"quantity":0,"orderId":0},{"price":64202,"quantity":0,"orderId":0},{"price":64157.3,"quantity":0.00001832,"orderId":1}],"prevSeqId":31327883590,"currentSeqId":31327883627,"checksum":1726192025}
{"action":"update","channel":"books","instrumentId":"BTC-USDT","instAsks":[{"price":64366.8,"quantity":2.69898613,"orderId":1},{"price":64367.8,"quantity":0,"orderId":0},{"price":64451.8,"quantity":1.59729388,"orderId":2},{"price":64503.9,"quantity":0.01258346,"orderId":1}],"instBids":[{"price":64300.2,"quantity":0.11187825,"orderId":1},{"price":64299.3,"quantity":0,"orderId":0}],"prevSeqId":31327883627,"currentSeqId":31327883635,"checksum":1726192025}
{"action":"update","channel":"books","instrumentId":"BTC-USDT","instAsks":[{"price":64404.9,"quantity":0.16410438,"orderId":2},{"price":64405.4,"quantity":0.0161736,"orderId":1},{"price":64406.9,"quantity":0,"orderId":0},{"price":64407.4,"quantity":0.04717289,"orderId":2},{"price":64429.6,"quantity":0.49957193,"orderId":2},{"price":64504.2,"quantity":0.00011492,"orderId":4}],"instBids":[{"price":64221.4,"quantity":0,"orderId":0},{"price":64221.3,"quantity":0.00194903,"orderId":1}],"prevSeqId":31327883635,"currentSeqId":31327883647,"checksum":1726192025}
{"action":"update","channel":"books","instrumentId":"BTC-USDT","instAsks":[{"price":64405.4,"quantity":0,"orderId":0},{"price":64407.3,"quantity":0.01617312,"orderId":1},{"price":64425.4,"quantity":0.03100077,"orderId":1},{"price":64431.6,"quantity":0.01616702,"orderId":1},{"price":64469.9,"quantity":0,"orderId":0},{"price":64471.8,"quantity":0.01617312,"orderId":1},{"price":64478.8,"quantity":0.46616,"orderId":1},{"price":64480.7,"quantity":0.05174682,"orderId":1},{"price":64503.7,"quantity":0,"orderId":0},{"price":64503.9,"quantity":0,"orderId":0},{"price":64504.2,"quantity":0,"orderId":0}],"instBids":[{"price":64322,"quantity":0.0808,"orderId":1},{"price":64301.8,"quantity":0.11187676,"orderId":1},{"price":64300.2,"quantity":0,"orderId":0},{"price":64292,"quantity":2.05309978,"orderId":3},{"price":64288.1,"quantity":0,"orderId":0},{"price":64176.2,"quantity":0,"orderId":0},{"price":64174.3,"quantity":0.01617312,"orderId":1}],"prevSeqId":31327883647,"currentSeqId":31327883667,"checksum":-288749571}
{"action":"update","channel":"books","instrumentId":"BTC-USDT","instAsks":[{"price":64366.8,"quantity":0,"orderId":0},{"price":64366.9,"quantity":2.72414285,"orderId":2},{"price":64503.7,"quantity":0.00004319,"orderId":1}],"instBids":[{"price":64312.5,"quantity":0,"orderId":0},{"price":64157.1,"quantity":0.01637125,"orderId":2}],"prevSeqId":31327883667,"currentSeqId":31327883674,"checksum":748296047}
{"action":"update","channel":"books","instrumentId":"BTC-USDT","instAsks":[{"price":64324,"quantity":0.4333592,"orderId":6},{"price":64325,"quantity":0,"orderId":0},{"price":64326.2,"quantity":0,"orderId":0},{"price":64327.9,"quantity":0.04848008,"orderId":1},{"price":64329.1,"quantity":0,"orderId":0},{"price":64333.7,"quantity":0,"orderId":0},{"price":64335.9,"quantity":0,"orderId":0},{"price":64336,"quantity":0,"orderId":0},{"price":64338.9,"quantity":0.02435059,"orderId":2},{"price":64339.7,"quantity":0,"orderId":0},{"price":64340,"quantity":0,"orderId":0},{"price":64343,"quantity":0,"orderId":0},{"price":64344,"quantity":0.00973533,"orderId":1},{"price":64347.5,"quantity":0,"orderId":0},{"price":64348,"quantity":0.0015,"orderId":1},{"price":64351.9,"quantity":0.086309,"orderId":1},{"price":64352,"quantity":0.2615,"orderId":2},{"price":64353.1,"quantity":0.15531861,"orderId":1},{"price":64366.9,"quantity":0.02515672,"orderId":1},{"price":64367.8,"quantity":2.69898613,"orderId":1},{"price":64387.3,"quantity":0,"orderId":0},{"price":64388,"quantity":0.07040357,"orderId":1},{"price":64388.5,"quantity":0,"orderId":0},{"price":64405.7,"quantity":0,"orderId":0},{"price":64406.5,"quantity":0.00776319,"orderId":1},{"price":64411.8,"quantity":0.24840173,"orderId":1},{"price":64420.3,"quantity":0.01616986,"orderId":1},{"price":64420.9,"quantity":0,"orderId":0},{"price":64430.2,"quantity":0.00048468,"orderId":1},{"price":64431.1,"quantity":0.24832734,"orderId":1},{"price":64476.2,"quantity":0.24815394,"orderId":1},{"price":64494.7,"quantity":0,"orderId":0},{"price":64503.9,"quantity":0.01258346,"orderId":1},{"price":64504.2,"quantity":0.00011492,"orderId":4},{"price":64505.2,"quantity":0.26001501,"orderId":2},{"price":64506.2,"quantity":0.00005269,"orderId":1}],"instBids":[{"price":64323.9,"quantity":0.49590128,"orderId":7},{"price":64322.9,"quantity":0.15539127,"orderId":1},{"price":64319.8,"quantity":0.46594,"orderId":1},{"price":64319.3,"quantity":0,"orderId":0},{"price":64317.4,"quantity":0.4546847,"orderId":3},{"price":64317.2,"quantity":0.46665,"orderId":2},{"price":64317.1,"quantity":0.0005,"orderId":1},{"price":64316.6,"quantity":0.05866956,"orderId":1},{"price":64316.5,"quantity":0.143271,"orderId":1},{"price":64316,"quantity":0.08156467,"orderId":2},{"price":64315.6,"quantity":0,"orderId":0},{"price":64315.4,"quantity":0,"orderId":0},{"price":64315.2,"quantity":0,"orderId":0},{"price":64315.1,"quantity":0.0153,"orderId":1},{"price":64313.1,"quantity":0.007774,"orderId":1},{"price":64312.7,"quantity":0,"orderId":0},{"price":64311,"quantity":0.46957212,"orderId":1},{"price":64309.7,"quantity":0.023305,"orderId":1},{"price":64308,"quantity":0.08230967,"orderId":2},{"price":64304.5,"quantity":0,"orderId":0},{"price":64302.5,"quantity":0.15544063,"orderId":1},{"price":64301.8,"quantity":0,"orderId":0},{"price":64301.4,"quantity":0,"orderId":0},{"price":64300.8,"quantity":0.11187576,"orderId":1},{"price":64300.2,"quantity":0.086309,"orderId":1},{"price":64300,"quantity":0,"orderId":0},{"price":64295.4,"quantity":0,"orderId":0},{"price":64295.2,"quantity":0,"orderId":0},{"price":64292,"quantity":0.02250192,"orderId":2},{"price":64290.1,"quantity":2.08926742,"orderId":2},{"price":64221.3,"quantity":0.25108751,"orderId":2},{"price":64202,"quantity":0.24921335,"orderId":1},{"price":64165,"quantity":0.00002932,"orderId":1},{"price":64157.3,"quantity":0,"orderId":0},{"price":64157.1,"quantity":0,"orderId":0}],"prevSeqId":31327883674,"currentSeqId":31327883769,"checksum":-227102579}
{"action":"update","channel":"books","instrumentId":"BTC-USDT","instAsks":[{"price":64367.8,"quantity":0,"orderId":0},{"price":64369.4,"quantity":2.69898613,"orderId":1},{"price":64430.9,"quantity":0.0161672,"orderId":1},{"price":64431.1,"quantity":0,"orderId":0},{"price":64476.2,"quantity":0,"orderId":0},{"price":64495.4,"quantity":0.0323344,"orderId":2},{"price":64506.4,"quantity":0.00004945,"orderId":2}],"instBids":[{"price":64318.2,"quantity":0.0005,"orderId":1},{"price":64318.1,"quantity":0.0005,"orderId":1},{"price":64317.2,"quantity":0.46615,"orderId":1},{"price":64317.1,"quantity":0,"orderId":0},{"price":64315.1,"quantity":0.0154,"orderId":1},{"price":64313.2,"quantity":0.007774,"orderId":1},{"price":64313.1,"quantity":0,"orderId":0},{"price":64164.4,"quantity":0.0161672,"orderId":1},{"price":64158.3,"quantity":0,"orderId":0},{"price":64157.5,"quantity":0,"orderId":0}],"prevSeqId":31327883769,"currentSeqId":31327883786,"checksum":1289668920}
{"action":"update","channel":"books","instrumentId":"BTC-USDT","instAsks":[{"price":64334.7,"quantity":0.05968139,"orderId":1},{"price":64366.9,"quantity":2.72414285,"orderId":2},{"price":64369.4,"quantity":0,"orderId":0},{"price":64393.6,"quantity":0.54372021,"orderId":1},{"price":64506.4,"quantity":0,"orderId":0}],"instBids":[{"price":64320.1,"quantity":0.22,"orderId":1},{"price":64311.2,"quantity":0.02,"orderId":1},{"price":64306,"quantity":0.0808,"orderId":1},{"price":64290.1,"quantity":0.05866956,"orderId":1},{"price":64288.8,"quantity":2.03059786,"orderId":1},{"price":64159.6,"quantity":0,"orderId":0},{"price":64159.1,"quantity":0,"orderId":0},{"price":64158.8,"quantity":0,"orderId":0}],"prevSeqId":31327883786,"currentSeqId":31327883801,"checksum":-804210686}
{"action":"update","channel":"books","instrumentId":"BTC-USDT","instAsks":[{"price":64329.1,"quantity":0.01106532,"orderId":1},{"price":64366.9,"quantity":0.02515672,"orderId":1},{"price":64367.8,"quantity":2.69898613,"orderId":1},{"price":64456.2,"quantity":0.00037184,"orderId":1},{"price":64505.2,"quantity":0,"orderId":0},{"price":64506.2,"quantity":0,"orderId":0}],"instBids":[{"price":64323.9,"quantity":0.47850128,"orderId":6},{"price":64320.1,"quantity":0,"orderId":0},{"price":64318.3,"quantity":0.0005,"orderId":1},{"price":64318.1,"quantity":0,"orderId":0},{"price":64316.9,"quantity":0.00833802,"orderId":1},{"price":64300.8,"quantity":0,"orderId":0},{"price":64299.9,"quantity":0.11187704,"orderId":1},{"price":64298.2,"quantity":0,"orderId":0},{"price":64289.7,"quantity":2.03059786,"orderId":1},{"price":64288.8,"quantity":0,"orderId":0},{"price":64220.2,"quantity":0.02999967,"orderId":1},{"price":64159.6,"quantity":1.5,"orderId":1}],"prevSeqId":31327883801,"currentSeqId":31327883826,"checksum":1201528771}
{"action":"update","channel":"books","instrumentId":"BTC-USDT","instAsks":[{"price":64324,"quantity":0.49966774,"orderId":7},{"price":64329.1,"quantity":0,"orderId":0},{"price":64406.5,"quantity":0,"orderId":0},{"price":64412.7,"quantity":0.00776245,"orderId":1},{"price":64455.5,"quantity":0.01294175,"orderId":1}],"instBids":[{"price":64316.9,"quantity":0,"orderId":0},{"price":64301.2,"quantity":0.561317,"orderId":2},{"price":64290.1,"quantity":2.08926742,"orderId":2},{"price":64289.7,"quantity":0,"orderId":0},{"price":64159.1,"quantity":0.00001007,"orderId":1},{"price":64158.8,"quantity":0.00031097,"orderId":2}],"prevSeqId":31327883826,"currentSeqId":31327883845,"checksum":-1890914844}
{"action":"update","channel":"books","instrumentId":"BTC-USDT","instAsks":[{"price":64324,"quantity":0.51105364,"orderId":8},{"price":64328.2,"quantity":0.00466233,"orderId":1},{"price":64329.2,"quantity":0.01106532,"orderId":1},{"price":64366.8,"quantity":1.61939169,"orderId":1},{"price":64431.1,"quantity":0.24832734,"orderId":1},{"price":64451.8,"quantity":0.18618543,"orderId":1},{"price":64476.2,"quantity":0.24815394,"orderId":1},{"price":64501.8,"quantity":0,"orderId":0},{"price":64503.1,"quantity":0,"orderId":0},{"price":64503.7,"quantity":0,"orderId":0},{"price":64503.9,"quantity":0,"orderId":0},{"price":64504.2,"quantity":0,"orderId":0}],"instBids":[{"price":64317.4,"quantity":0.1946847,"orderId":2},{"price":64316.8,"quantity":0.00833802,"orderId":1},{"price":64315.1,"quantity":0.0149,"orderId":1},{"price":64158.8,"quantity":0,"orderId":0}],"prevSeqId":31327883845,"currentSeqId":31327883860,"checksum":618197329}
{"action":"update","channel":"books","instrumentId":"BTC-USDT","instAsks":[{"price":64324,"quantity":0.56691364,"orderId":9},{"price":64332.8,"quantity":0,"orderId":0},{"price":64334.4,"quantity":0.11187876,"orderId":1},{"price":64334.5,"quantity":0.03580886,"orderId":1},{"price":64336.9,"quantity":0,"orderId":0},{"price":64339.9,"quantity":0.05866956,"orderId":1},{"price":64501.2,"quantity":0,"orderId":0}],"instBids":[{"price":64323.9,"quantity":0.16824128,"orderId":3},{"price":64322,"quantity":0,"orderId":0},{"price":64318.3,"quantity":0,"orderId":0},{"price":64318.1,"quantity":0.0005,"orderId":1},{"price":64316.8,"quantity":0,"orderId":0},{"price":64316.6,"quantity":0,"orderId":0},{"price":64315.1,"quantity":0.0147,"orderId":1},{"price":64314.2,"quantity":0.00833802,"orderId":1},{"price":64311,"quantity":0,"orderId":0},{"price":64306.6,"quantity":0,"orderId":0},{"price":64306.4,"quantity":0.15549,"orderId":1},{"price":64300.8,"quantity":0.01555188,"orderId":1},{"price":64299.9,"quantity":0,"orderId":0},{"price":64299.3,"quantity":0.11187876,"orderId":1},{"price":64297,"quantity":0,"orderId":0},{"price":64296.8,"quantity":0.31099,"orderId":1},{"price":64291.2,"quantity":2.03059786,"orderId":1},{"price":64290.1,"quantity":0.05866956,"orderId":1},{"price":64158.8,"quantity":0.00031097,"orderId":2}],"prevSeqId":31327883860,"currentSeqId":31327883907,"checksum":-626040742}
{"action":"update","channel":"books","instrumentId":"BTC-USDT","instAsks":[{"price":64334.3,"quantity":0.0671273,"orderId":1},{"price":64334.5,"quantity":0,"orderId":0},{"price":64363.7,"quantity":2.71005784,"orderId":1},{"price":64366.8,"quantity":0,"orderId":0},{"price":64367.8,"quantity":0,"orderId":0},{"price":64501.2,"quantity":0.00001438,"orderId":1}],"instBids":[{"price":64318.2,"quantity":0,"orderId":0},{"price":64318,"quantity":0.0813,"orderId":2},{"price":64297.7,"quantity":0,"orderId":0},{"price":64291.2,"quantity":0,"orderId":0},{"price":64289.7,"quantity":2.07651364,"orderId":1},{"price":64256,"quantity":0.156341,"orderId":1},{"price":64255.9,"quantity":0.01683288,"orderId":2},{"price":64252.6,"quantity":0.71596315,"orderId":3},{"price":64158.3,"quantity":0.00014683,"orderId":1},{"price":64157.5,"quantity":0.00013042,"orderId":3}],"prevSeqId":31327883907,"currentSeqId":31327884025,"checksum":1901882588}
{"action":"update","channel":"books","instrumentId":"BTC-USDT","instAsks":[{"price":64324,"quantity":0.5006051,"orderId":8},{"price":64334.3,"quantity":0.03580889,"orderId":1},{"price":64334.4,"quantity":0,"orderId":0},{"price":64336.9,"quantity":0.1118775,"orderId":1},{"price":64363.7,"quantity":0,"orderId":0},{"price":64367.8,"quantity":2.71005784,"orderId":1}],"instBids":[{"price":64318.1,"quantity":0,"orderId":0},{"price":64318,"quantity":0.0808,"orderId":1},{"price":64317.8,"quantity":0.0005,"orderId":1},{"price":64317.7,"quantity":0.0005,"orderId":1},{"price":64315.1,"quantity":0.0146,"orderId":1},{"price":64313.2,"quantity":0,"orderId":0},{"price":64313.1,"quantity":0.007774,"orderId":1},{"price":64300.3,"quantity":0.1118775,"orderId":1},{"price":64299.3,"quantity":0,"orderId":0},{"price":64291.7,"quantity":2.07651364,"orderId":1},{"price":64289.7,"quantity":0,"orderId":0},{"price":64217.9,"quantity":0.00562101,"orderId":1},{"price":64158.3,"quantity":0,"orderId":0},{"price":64157.5,"quantity":0,"orderId":0}],"prevSeqId":31327884025,"currentSeqId":31327884049,"checksum":1290775554}
{"action":"update","channel":"books","instrumentId":"BTC-USDT","instAsks":[{"price":64328.2,"quantity":0,"orderId":0},{"price":64334.1,"quantity":0.06712715,"orderId":1},{"price":64334.3,"quantity":0,"orderId":0},{"price":64334.6,"quantity":0.11187843,"orderId":1},{"price":64336.9,"quantity":0,"orderId":0},{"price":64362.7,"quantity":0,"orderId":0},{"price":64411.8,"quantity":0,"orderId":0},{"price":64431.1,"quantity":0,"orderId":0},{"price":64476.2,"quantity":0,"orderId":0},{"price":64501.8,"quantity":0.00007459,"orderId":1},{"price":64503.1,"quantity":0.0001601,"orderId":1},{"price":64503.7,"quantity":0.00004319,"orderId":1},{"price":64503.9,"quantity":0.01258346,"orderId":1},{"price":64504.2,"quantity":0.00011492,"orderId":4}],"instBids":[{"price":64313.2,"quantity":0.007774,"orderId":1},{"price":64313.1,"quantity":0,"orderId":0},{"price":64300.3,"quantity":0,"orderId":0},{"price":64299.3,"quantity":0.11187843,"orderId":1},{"price":64291.7,"quantity":0,"orderId":0},{"price":64288.8,"quantity":2.07651364,"orderId":1},{"price":64221.3,"quantity":0.00194903,"orderId":1},{"price":64202,"quantity":0,"orderId":0},{"price":64158.3,"quantity":0.00014683,"orderId":1}],"prevSeqId":31327884049,"currentSeqId":31327884073,"checksum":1797632730}
{"action":"update","channel":"books","instrumentId":"BTC-USDT","instAsks":[{"price":64334.1,"quantity":0.03580891,"orderId":1},{"price":64334.6,"quantity":0,"orderId":0},{"price":64336.9,"quantity":0.11187743,"orderId":1},{"price":64366.1,"quantity":0.02722651,"orderId":1},{"price":64411.8,"quantity":0.24840173,"orderId":1},{"price":64431.1,"quantity":0.24832734,"orderId":1},{"price":64476.2,"quantity":0.24815394,"orderId":1},{"price":64503.1,"quantity":0,"orderId":0},{"price":64503.7,"quantity":0,"orderId":0},{"price":64503.9,"quantity":0,"orderId":0},{"price":64504.2,"quantity":0,"orderId":0}],"instBids":[{"price":64322,"quantity":0.0808,"orderId":1},{"price":64318.1,"quantity":0.0005,"orderId":1},{"price":64318,"quantity":0.0813,"orderId":2},{"price":64317.8,"quantity":0,"orderId":0},{"price":64317.7,"quantity":0,"orderId":0},{"price":64314.9,"quantity":0.00833802,"orderId":1},{"price":64314.2,"quantity":0,"orderId":0},{"price":64300.3,"quantity":0.11187743,"orderId":1},{"price":64299.3,"quantity":0,"orderId":0},{"price":64221.3,"quantity":0.25108751,"orderId":2},{"price":64202,"quantity":0.24921335,"orderId":1},{"price":64158.3,"quantity":0,"orderId":0}],"prevSeqId":31327884073,"currentSeqId":31327884109,"checksum":426005269}
{"action":"update","channel":"books","instrumentId":"BTC-USDT","instAsks":[{"price":64324,"quantity":0.47182613,"orderId":9},{"price":64334.6,"quantity":0.11187778,"orderId":1},{"price":64336.9,"quantity":0,"orderId":0},{"price":64431.1,"quantity":0,"orderId":0},{"price":64476.2,"quantity":0,"orderId":0},{"price":64503.1,"quantity":0.0001601,"orderId":1},{"price":64503.7,"quantity":0.00004319,"orderId":1}],"instBids":[{"price":64301.4,"quantity":0.0015,"orderId":1},{"price":64301.2,"quantity":0.57686879,"orderId":3},{"price":64300.8,"quantity":0,"orderId":0},{"price":64300.3,"quantity":0,"orderId":0},{"price":64300.2,"quantity":0.19818678,"orderId":2},{"price":64298.2,"quantity":1.24090281,"orderId":1},{"price":64290.2,"quantity":2.07651364,"orderId":1},{"price":64288.8,"quantity":0,"orderId":0},{"price":64274.5,"quantity":0,"orderId":0},{"price":64274.2,"quantity":0,"orderId":0},{"price":64272.8,"quantity":0.70174328,"orderId":1},{"price":64272.6,"quantity":1.16957212,"orderId":2},{"price":64256.4,"quantity":1.8911276,"orderId":1},{"price":64256.2,"quantity":0,"orderId":0},{"price":64231.7,"quantity":0.15600009,"orderId":1},{"price":64214.4,"quantity":0.09344925,"orderId":1},{"price":64158.8,"quantity":0,"orderId":0}],"prevSeqId":31327884109,"currentSeqId":31327884151,"checksum":-954257975}
{"action":"update","channel":"books","instrumentId":"BTC-USDT","instAsks":[{"price":64334.6,"quantity":0,"orderId":0},{"price":64336.9,"quantity":0.11187731,"orderId":1},{"price":64364.3,"quantity":2.86534945,"orderId":2},{"price":64367.8,"quantity":0,"orderId":0},{"price":64404.9,"quantity":0.156341,"orderId":1},{"price":64405,"quantity":0.00776337,"orderId":1},{"price":64471.2,"quantity":0.0296,"orderId":1},{"price":64471.9,"quantity":0.01617309,"orderId":1},{"price":64503.7,"quantity":0,"orderId":0}],"instBids":[{"price":64318.2,"quantity":0.0005,"orderId":1},{"price":64318,"quantity":0.0808,"orderId":1},{"price":64300.3,"quantity":0.11187731,"orderId":1},{"price":64300.2,"quantity":0.086309,"orderId":1},{"price":64291.2,"quantity":2.07651364,"orderId":1},{"price":64290.2,"quantity":0,"orderId":0},{"price":64215.4,"quantity":0.00003328,"orderId":1},{"price":64214,"quantity":0.03111387,"orderId":2},{"price":64159.6,"quantity":0,"orderId":0},{"price":64159.1,"quantity":0,"orderId":0}],"prevSeqId":31327884151,"currentSeqId":31327884213,"checksum":-691571170}
{"action":"update","channel":"books","instrumentId":"BTC-USDT","instAsks":[{"price":64324,"quantity":0.58099882,"orderId":10}],"instBids":[{"price":64323.9,"quantity":0.30384128,"orderId":4}],"prevSeqId":31327884213,"currentSeqId":31327884217,"checksum":1081764347}
{"action":"update","channel":"books","instrumentId":"BTC-USDT","instAsks":[],"instBids":[{"price":64318.2,"quantity":0,"orderId":0},{"price":64318,"quantity":0.0813,"orderId":2},{"price":64315.6,"quantity":0.00833802,"orderId":1},{"price":64314.9,"quantity":0,"orderId":0},{"price":64159.6,"quantity":1.5,"orderId":1}],"prevSeqId":31327884217,"currentSeqId":31327884224,"checksum":-1859298539}
{"action":"update","channel":"books","instrumentId":"BTC-USDT","instAsks":[{"price":64364.3,"quantity":0.15529161,"orderId":1},{"price":64367.8,"quantity":2.71005784,"orderId":1},{"price":64393.1,"quantity":0.3237741,"orderId":3},{"price":64406.5,"quantity":0.00776319,"orderId":1},{"price":64409.8,"quantity":0,"orderId":0},{"price":64410.5,"quantity":0.14904106,"orderId":1},{"price":64412.7,"quantity":0,"orderId":0},{"price":64431.1,"quantity":0.24832734,"orderId":1},{"price":64451.8,"quantity":1.57417373,"orderId":2},{"price":64476.2,"quantity":0.24815394,"orderId":1},{"price":64501.2,"quantity":0,"orderId":0},{"price":64501.8,"quantity":0,"orderId":0},{"price":64503.1,"quantity":0,"orderId":0}],"instBids":[],"prevSeqId":31327884224,"currentSeqId":31327884241,"checksum":-1859298539}
{"action":"update","channel":"books","instrumentId":"BTC-USDT","instAsks":[{"price":64334.6,"quantity":0.111878,"orderId":1},{"price":64336.9,"quantity":0,"orderId":0},{"price":64364.3,"quantity":2.89346828,"orderId":2},{"price":64367.8,"quantity":0,"orderId":0},{"price":64476.2,"quantity":0,"orderId":0},{"price":64501.2,"quantity":0.00001438,"orderId":1},{"price":64501.8,"quantity":0.00007459,"orderId":1}],"instBids":[{"price":64300.3,"quantity":0,"orderId":0},{"price":64299.9,"quantity":0.111878,"orderId":1},{"price":64291.2,"quantity":2.11442699,"orderId":1}],"prevSeqId":31327884241,"currentSeqId":31327884274,"checksum":-141413383}
{"action":"update","channel":"books","instrumentId":"BTC-USDT","instAsks":[{"price":64334.6,"quantity":0,"orderId":0},{"price":64336.9,"quantity":0.11187705,"orderId":1},{"price":64364.3,"quantity":0.15529161,"orderId":1},{"price":64366,"quantity":2.73817667,"orderId":1},{"price":64501.8,"quantity":0,"orderId":0}],"instBids":[{"price":64300.3,"quantity":0.11187705,"orderId":1},{"price":64299.9,"quantity":0,"orderId":0}],"prevSeqId":31327884274,"currentSeqId":31327884287,"checksum":1866051282}
{"action":"update","channel":"books","instrumentId":"BTC-USDT","instAsks":[{"price":64391.8,"quantity":0,"orderId":0},{"price":64501.8,"quantity":0.00007459,"orderId":1}],"instBids":[{"price":64319.9,"quantity":0.14,"orderId":1},{"price":64159.6,"quantity":0,"orderId":0}],"prevSeqId":31327884287,"currentSeqId":31327884291,"checksum":1195259144}
{"action":"update","channel":"books","instrumentId":"BTC-USDT","instAsks":[{"price":64390.5,"quantity":0.01294187,"orderId":1},{"price":64501.8,"quantity":0,"orderId":0}],"instBids":[],"prevSeqId":31327884291,"currentSeqId":31327884294,"checksum":1195259144}
{"action":"update","channel":"books","instrumentId":"BTC-USDT","instAsks":[{"price":64324,"quantity":0.47182613,"orderId":9},{"price":64334.1,"quantity":0.06265067,"orderId":2},{"price":64334.6,"quantity":0.11187789,"orderId":1},{"price":64336.9,"quantity":0,"orderId":0},{"price":64364.3,"quantity":2.89346828,"orderId":2},{"price":64366,"quantity":0,"orderId":0},{"price":64476.2,"quantity":0.24815394,"orderId":1}],"instBids":[{"price":64323.9,"quantity":0.16824128,"orderId":3},{"price":64319.9,"quantity":0,"orderId":0},{"price":64318.1,"quantity":0,"orderId":0},{"price":64317.9,"quantity":0.0005,"orderId":1},{"price":64300.3,"quantity":0,"orderId":0},{"price":64299.9,"quantity":0.11187789,"orderId":1},{"price":64159.6,"quantity":1.5,"orderId":1}],"prevSeqId":31327884294,"currentSeqId":31327884307,"checksum":-229558949}
{"action":"update","channel":"books","instrumentId":"BTC-USDT","instAsks":[{"price":64363.7,"quantity":2.73817667,"orderId":1},{"price":64364.3,"quantity":0.15529161,"orderId":1},{"price":64501.2,"quantity":0,"orderId":0}],"instBids":[{"price":64318.1,"quantity":0.0005,"orderId":1},{"price":64317.9,"quantity":0,"orderId":0},{"price":64299.9,"quantity":0,"orderId":0},{"price":64299.3,"quantity":0.11187827,"orderId":1}],"prevSeqId":31327884307,"currentSeqId":31327884313,"checksum":1810658833}
{"action":"update","channel":"books","instrumentId":"BTC-USDT","instAsks":[{"price":64334.1,"quantity":0.06265085,"orderId":2},{"price":64334.6,"quantity":0.11187817,"orderId":1},{"price":64441,"quantity":0,"orderId":0},{"price":64501.2,"quantity":0.00001438,"orderId":1}],"instBids":[{"price":64299.3,"quantity":0.11187815,"orderId":1}],"prevSeqId":31327884313,"currentSeqId":31327884326,"checksum":-577305004}
{"action":"update","channel":"books","instrumentId":"BTC-USDT","instAsks":[{"price":64334.1,"quantity":0.03580891,"orderId":1},{"price":64334.6,"quantity":0,"orderId":0},{"price":64336.9,"quantity":0.11187757,"orderId":1}],"instBids":[{"price":64318.1,"quantity":0,"orderId":0},{"price":64317.9,"quantity":0.0005,"orderId":1},{"price":64300.3,"quantity":0.11187757,"orderId":1},{"price":64299.3,"quantity":0,"orderId":0},{"price":64217.9,"quantity":0,"orderId":0},{"price":64159.1,"quantity":0.00001007,"orderId":1}],"prevSeqId":31327884326,"currentSeqId":31327884339,"checksum":-1459663013}
{"action":"update","channel":"books","instrumentId":"BTC-USDT","instAsks":[{"price":64324,"quantity":0.35258196,"orderId":7},{"price":64325.1,"quantity":0,"orderId":0},{"price":64325.9,"quantity":0.05477384,"orderId":1},{"price":64327.9,"quantity":0,"orderId":0},{"price":64334.1,"quantity":0.06265092,"orderId":2},{"price":64334.7,"quantity":0,"orderId":0},{"price":64336.9,"quantity":0.11187672,"orderId":1},{"price":64347.6,"quantity":0,"orderId":0},{"price":64363.7,"quantity":0,"orderId":0},{"price":64366.9,"quantity":0,"orderId":0},{"price":64370.2,"quantity":0.0235715,"orderId":1},{"price":64501.8,"quantity":0.00007459,"orderId":1},{"price":64503.1,"quantity":0.0001601,"orderId":1},{"price":64503.7,"quantity":0.00004319,"orderId":1},{"price":64503.9,"quantity":0.01258346,"orderId":1}],"instBids":[{"price":64323.9,"quantity":0.45034128,"orderId":6},{"price":64318,"quantity":0.0808,"orderId":1},{"price":64317.8,"quantity":0.0005,"orderId":1},{"price":64316.4,"quantity":0.00833802,"orderId":1},{"price":64315.6,"quantity":0,"orderId":0},{"price":64300.3,"quantity":0.11187672,"orderId":1},{"price":64159.1,"quantity":0,"orderId":0}],"prevSeqId":31327884339,"currentSeqId":31327884368,"checksum":-393894266}
{"action":"update","channel":"books","instrumentId":"BTC-USDT","instAsks":[{"price":64324,"quantity":0.0579177,"orderId":1},{"price":64325.9,"quantity":0.03021064,"orderId":1},{"price":64326.7,"quantity":0.08596268,"orderId":1},{"price":64326.8,"quantity":0.143271,"orderId":1},{"price":64329.2,"quantity":0,"orderId":0},{"price":64331.5,"quantity":0.01106532,"orderId":1},{"price":64333.3,"quantity":0.03509356,"orderId":1},{"price":64334.1,"quantity":0,"orderId":0},{"price":64336.9,"quantity":0,"orderId":0},{"price":64337,"quantity":0,"orderId":0},{"price":64338.8,"quantity":0.11187092,"orderId":1},{"price":64339.9,"quantity":0,"orderId":0},{"price":64341.4,"quantity":0.06712116,"orderId":1},{"price":64341.8,"quantity":0,"orderId":0},{"price":64342.8,"quantity":0.00001501,"orderId":1},{"price":64346.6,"quantity":0.24761701,"orderId":1},{"price":64347.4,"quantity":0,"orderId":0},{"price":64349.6,"quantity":0,"orderId":0},{"price":64350.9,"quantity":0.07772148,"orderId":1},{"price":64367.6,"quantity":2.74643307,"orderId":1},{"price":64367.7,"quantity":1.64290602,"orderId":1},{"price":64367.9,"quantity":1.26368931,"orderId":2},{"price":64378.7,"quantity":0,"orderId":0},{"price":64381.6,"quantity":0,"orderId":0},{"price":64389,"quantity":0.01,"orderId":1},{"price":64392.1,"quantity":0.01348078,"orderId":1},{"price":64451.8,"quantity":0.18618543,"orderId":1},{"price":64453.4,"quantity":0,"orderId":0},{"price":64456.5,"quantity":0.01348078,"orderId":1}],"instBids":[{"price":64323.9,"quantity":1.0735393,"orderId":11},{"price":64322,"quantity":0.13946956,"orderId":2},{"price":64320.1,"quantity":0.00528259,"orderId":1},{"price":64318.1,"quantity":0.0005,"orderId":1},{"price":64318,"quantity":0.08963802,"orderId":3},{"price":64317.9,"quantity":0,"orderId":0},{"price":64317.8,"quantity":0,"orderId":0},{"price":64317.4,"quantity":0.4546847,"orderId":3},{"price":64316.8,"quantity":0.05866956,"orderId":1},{"price":64316.4,"quantity":0,"orderId":0},{"price":64315.1,"quantity":0.0147,"orderId":1},{"price":64313.7,"quantity":0,"orderId":0},{"price":64309.6,"quantity":0,"orderId":0},{"price":64308.4,"quantity":0.15549,"orderId":1},{"price":64306.4,"quantity":0,"orderId":0},{"price":64306.3,"quantity":0.03147127,"orderId":1},{"price":64305.6,"quantity":0,"orderId":0},{"price":64302.9,"quantity":0.11187092,"orderId":1},{"price":64300.3,"quantity":0,"orderId":0},{"price":64298.8,"quantity":0.31099,"orderId":1},{"price":64296.8,"quantity":0,"orderId":0},{"price":64292.3,"quantity":0,"orderId":0},{"price":64291.2,"quantity":2.14868027,"orderId":1},{"price":64256.5,"quantity":0.71601725,"orderId":1},{"price":64252.6,"quantity":0.18736573,"orderId":2},{"price":64246.5,"quantity":0.01348078,"orderId":1},{"price":64244.7,"quantity":0,"orderId":0},{"price":64243.9,"quantity":0.02101955,"orderId":2},{"price":64241.8,"quantity":0,"orderId":0},{"price":64182.2,"quantity":0.01348078,"orderId":1},{"price":64180.4,"quantity":0,"orderId":0},{"price":64159.1,"quantity":0.00001007,"orderId":1},{"price":64158.8,"quantity":0.00031097,"orderId":2},{"price":64158.3,"quantity":0.00014683,"orderId":1},{"price":64157.5,"quantity":0.00013042,"orderId":3}],"prevSeqId":31327884368,"currentSeqId":31327884518,"checksum":535834915}
{"action":"update","channel":"books","instrumentId":"BTC-USDT","instAsks":[{"price":64324,"quantity":0,"orderId":0},{"price":64325.9,"quantity":0,"orderId":0},{"price":64331.5,"quantity":0,"orderId":0},{"price":64332.2,"quantity":0.01106532,"orderId":1},{"price":64335.4,"quantity":0.05968139,"orderId":1},{"price":64338.8,"quantity":0,"orderId":0},{"price":64341.3,"quantity":0.11186868,"orderId":1},{"price":64341.4,"quantity":0.033078,"orderId":1},{"price":64344,"quantity":0.10889496,"orderId":2},{"price":64350.8,"quantity":0.12984975,"orderId":3},{"price":64367.6,"quantity":0,"orderId":0},{"price":64367.7,"quantity":0,"orderId":0},{"price":64372.4,"quantity":2.74643307,"orderId":1},{"price":64396.7,"quantity":0,"orderId":0},{"price":64504.2,"quantity":0.00011492,"orderId":4},{"price":64505.2,"quantity":0.26001501,"orderId":2},{"price":64506.2,"quantity":0.00005269,"orderId":1}],"instBids":[{"price":64324,"quantity":1.43267056,"orderId":16},{"price":64323.9,"quantity":0.558636,"orderId":5},{"price":64318.3,"quantity":0.0005,"orderId":1},{"price":64318.2,"quantity":0.0005,"orderId":1},{"price":64318.1,"quantity":0,"orderId":0},{"price":64318,"quantity":0.08913802,"orderId":2},{"price":64317.5,"quantity":0.17173808,"orderId":2},{"price":64317.4,"quantity":0.2774,"orderId":2},{"price":64315.6,"quantity":0.0146,"orderId":1},{"price":64315.1,"quantity":0,"orderId":0},{"price":64311.4,"quantity":0.00310987,"orderId":1},{"price":64306.8,"quantity":0.09450691,"orderId":1},{"price":64304.5,"quantity":0.11186868,"orderId":1},{"price":64302.9,"quantity":0,"orderId":0},{"price":64301.4,"quantity":0,"orderId":0},{"price":64301.3,"quantity":0.04670234,"orderId":2},{"price":64300,"quantity":0.12361557,"orderId":1},{"price":64295.8,"quantity":2.1525295,"orderId":3},{"price":64291.2,"quantity":0,"orderId":0},{"price":64289.9,"quantity":0.00933,"orderId":1},{"price":64286.1,"quantity":0,"orderId":0},{"price":64285.6,"quantity":0.89673691,"orderId":2},{"price":64256.5,"quantity":0,"orderId":0},{"price":64218.5,"quantity":0.00562096,"orderId":1},{"price":64199.1,"quantity":0.00778827,"orderId":1},{"price":64188.8,"quantity":0.02093154,"orderId":1},{"price":64158.8,"quantity":0,"orderId":0},{"price":64158.3,"quantity":0,"orderId":0},{"price":64157.5,"quantity":0,"orderId":0}],"prevSeqId":31327884518,"currentSeqId":31327884689,"checksum":-1289194274}
{"action":"update","channel":"books","instrumentId":"BTC-USDT","instAsks":[{"price":64324.1,"quantity":0.00111182,"orderId":1},{"price":64330.8,"quantity":0.01106532,"orderId":1},{"price":64332.2,"quantity":0,"orderId":0},{"price":64367.8,"quantity":2.74643307,"orderId":1},{"price":64372.4,"quantity":0,"orderId":0}],"instBids":[{"price":64323.9,"quantity":0.338636,"orderId":4},{"price":64318.8,"quantity":0.00833802,"orderId":1},{"price":64318,"quantity":0.0808,"orderId":1},{"price":64312.5,"quantity":0.001,"orderId":1},{"price":64296,"quantity":0.00001105,"orderId":1},{"price":64159.9,"quantity":0,"orderId":0},{"price":64159.6,"quantity":0,"orderId":0},{"price":64159.1,"quantity":0,"orderId":0}],"prevSeqId":31327884689,"currentSeqId":31327884827,"checksum":-133012962}
{"action":"update","channel":"books","instrumentId":"BTC-USDT","instAsks":[{"price":64326.7,"quantity":0.04779796,"orderId":1}],"instBids":[{"price":64324,"quantity":1.17267056,"orderId":15},{"price":64323.9,"quantity":0.078636,"orderId":3},{"price":64315.6,"quantity":0.0147,"orderId":1},{"price":64306.3,"quantity":0,"orderId":0},{"price":64272.9,"quantity":0.7,"orderId":1},{"price":64272.8,"quantity":0,"orderId":0},{"price":64272.6,"quantity":0.46957212,"orderId":1},{"price":64251.2,"quantity":0.01294123,"orderId":1},{"price":64250.1,"quantity":0,"orderId":0},{"price":64241.6,"quantity":0.05174473,"orderId":1},{"price":64239.8,"quantity":0,"orderId":0},{"price":64236.5,"quantity":0.61627361,"orderId":1},{"price":64186.9,"quantity":0.01294123,"orderId":1},{"price":64185.8,"quantity":0,"orderId":0}],"prevSeqId":31327884827,"currentSeqId":31327884850,"checksum":-816986230}
{"action":"update","channel":"books","instrumentId":"BTC-USDT","instAsks":[{"price":64325.9,"quantity":0.05477381,"orderId":1},{"price":64326.7,"quantity":0.07998792,"orderId":2},{"price":64337.1,"quantity":0.26,"orderId":1},{"price":64340.1,"quantity":0.11186949,"orderId":1},{"price":64341.3,"quantity":0,"orderId":0},{"price":64344,"quantity":0.00973533,"orderId":1},{"price":64350.8,"quantity":0.02017297,"orderId":2},{"price":64406.5,"quantity":0,"orderId":0},{"price":64412.6,"quantity":0.06643201,"orderId":2},{"price":64505.2,"quantity":0.00001501,"orderId":1},{"price":64506.2,"quantity":0,"orderId":0}],"instBids":[{"price":64324,"quantity":0.95267056,"orderId":14},{"price":64318.4,"quantity":0.0005,"orderId":1},{"price":64318.2,"quantity":0,"orderId":0},{"price":64306.8,"quantity":0,"orderId":0},{"price":64304.5,"quantity":0.11186949,"orderId":1},{"price":64300,"quantity":0,"orderId":0},{"price":64295.8,"quantity":0.00384923,"orderId":2},{"price":64290.2,"quantity":2.14868027,"orderId":1},{"price":64223.2,"quantity":0.04616498,"orderId":2},{"price":64222.1,"quantity":0,"orderId":0},{"price":64217.5,"quantity":0.00778604,"orderId":1},{"price":64214,"quantity":0.0233274,"orderId":1},{"price":64159.9,"quantity":0.01564601,"orderId":2}],"prevSeqId":31327884850,"currentSeqId":31327884886,"checksum":1721663553}
{"action":"update","channel":"books","instrumentId":"BTC-USDT","instAsks":[{"price":64330,"quantity":0.09188032,"orderId":3},{"price":64330.8,"quantity":0,"orderId":0},{"price":64338.8,"quantity":0.11187142,"orderId":1},{"price":64340.1,"quantity":0,"orderId":0},{"price":64343.8,"quantity":0.10003716,"orderId":4},{"price":64350.6,"quantity":0.11418064,"orderId":1},{"price":64505.2,"quantity":0.26001501,"orderId":2}],"instBids":[{"price":64306.7,"quantity":0.09694604,"orderId":1},{"price":64304.5,"quantity":0,"orderId":0},{"price":64302.9,"quantity":0.11187142,"orderId":1},{"price":64299.9,"quantity":0.1131612,"orderId":1},{"price":64292,"quantity":2.17118219,"orderId":3},{"price":64290.2,"quantity":0,"orderId":0},{"price":64236.8,"quantity":0.00646795,"orderId":1},{"price":64235,"quantity":0,"orderId":0},{"price":64233.4,"quantity":0.02616908,"orderId":2},{"price":64232.3,"quantity":0,"orderId":0},{"price":64229.3,"quantity":0,"orderId":0},{"price":64169.1,"quantity":0.01616908,"orderId":1},{"price":64168,"quantity":0.00014295,"orderId":1}],"prevSeqId":31327884886,"currentSeqId":31327884913,"checksum":803504121}
{"action":"update","channel":"books","instrumentId":"BTC-USDT","instAsks":[{"price":64325.9,"quantity":0,"orderId":0},{"price":64326.7,"quantity":0.12444418,"orderId":3},{"price":64343.8,"quantity":0.00466248,"orderId":3},{"price":64350.6,"quantity":0,"orderId":0},{"price":64405,"quantity":0,"orderId":0},{"price":64406.9,"quantity":0.00776314,"orderId":1},{"price":64506.2,"quantity":0.00005269,"orderId":1},{"price":64506.4,"quantity":0.00004945,"orderId":2}],"instBids":[{"price":64307.8,"quantity":0.05866956,"orderId":1},{"price":64306.7,"quantity":0,"orderId":0},{"price":64299.9,"quantity":0,"orderId":0},{"price":64295.8,"quantity":2.1525295,"orderId":3},{"price":64292,"quantity":0.02250192,"orderId":2},{"price":64231.1,"quantity":0.01618175,"orderId":2},{"price":64159.6,"quantity":1.5,"orderId":1},{"price":64159.1,"quantity":0.00001007,"orderId":1}],"prevSeqId":31327884913,"currentSeqId":31327884925,"checksum":-1532631626}
{"action":"update","channel":"books","instrumentId":"BTC-USDT","instAsks":[{"price":64344,"quantity":0.10076308,"orderId":2},{"price":64350.7,"quantity":0.11823608,"orderId":1},{"price":64506.4,"quantity":0,"orderId":0}],"instBids":[{"price":64324,"quantity":0.95242838,"orderId":14},{"price":64318.4,"quantity":0,"orderId":0},{"price":64318.2,"quantity":0.0005,"orderId":1},{"price":64306.8,"quantity":0.08741061,"orderId":1},{"price":64300,"quantity":0.10908818,"orderId":1},{"price":64295.8,"quantity":0.00384923,"orderId":2},{"price":64292,"quantity":2.17118219,"orderId":3},{"price":64217.8,"quantity":0,"orderId":0},{"price":64182.6,"quantity":0.01617282,"orderId":1},{"price":64180.8,"quantity":0,"orderId":0},{"price":64159.1,"quantity":0,"orderId":0}],"prevSeqId":31327884925,"currentSeqId":31327884942,"checksum":-2024649437}
{"action":"update","channel":"books","instrumentId":"BTC-USDT","instAsks":[],"instBids":[{"price":64218.9,"quantity":0.01616659,"orderId":1},{"price":64159.6,"quantity":0,"orderId":0}],"prevSeqId":31327884942,"currentSeqId":31327884943,"checksum":-2024649437}
{"action":"update","channel":"books","instrumentId":"BTC-USDT","instAsks":[{"price":64338,"quantity":0.11187204,"orderId":1},{"price":64338.8,"quantity":0,"orderId":0},{"price":64385.4,"quantity":0,"orderId":0},{"price":64386.3,"quantity":0.27969608,"orderId":1},{"price":64386.6,"quantity":0,"orderId":0},{"price":64506.4,"quantity":0.00004945,"orderId":2}],"instBids":[],"prevSeqId":31327884943,"currentSeqId":31327884952,"checksum":989240299}
{"action":"update","channel":"books","instrumentId":"BTC-USDT","instAsks":[{"price":64343.9,"quantity":0.08739527,"orderId":1},{"price":64344,"quantity":0.00973533,"orderId":1},{"price":64350.6,"quantity":0.11081577,"orderId":1},{"price":64350.7,"quantity":0,"orderId":0},{"price":64367.7,"quantity":1.64785985,"orderId":1},{"price":64451.8,"quantity":1.43426079,"orderId":2},{"price":64506.2,"quantity":0,"orderId":0},{"price":64506.4,"quantity":0,"orderId":0}],"instBids":[{"price":64318.4,"quantity":0.0005,"orderId":1},{"price":64318.2,"quantity":0,"orderId":0},{"price":64306.9,"quantity":0.09418078,"orderId":1},{"price":64306.8,"quantity":0,"orderId":0},{"price":64300.1,"quantity":0.12625175,"orderId":2},{"price":64300,"quantity":0,"orderId":0},{"price":64273,"quantity":0.42000009,"orderId":1},{"price":64253.4,"quantity":0.226716,"orderId":1},{"price":64236.5,"quantity":0,"orderId":0},{"price":64214.4,"quantity":0.09498045,"orderId":2},{"price":64214.3,"quantity":0.03110306,"orderId":1}],"prevSeqId":31327884952,"currentSeqId":31327884975,"checksum":-576947701}
{"action":"update","channel":"books","instrumentId":"BTC-USDT","instAsks":[{"price":64350.8,"quantity":1.22329007,"orderId":3},{"price":64367.6,"quantity":2.74643307,"orderId":1},{"price":64367.7,"quantity":0,"orderId":0},{"price":64367.8,"quantity":0,"orderId":0},{"price":64506.2,"quantity":0.00005269,"orderId":1}],"instBids":[{"price":64221.6,"quantity":0.00194897,"orderId":1},{"price":64221.3,"quantity":0.24913848,"orderId":1},{"price":64217.5,"quantity":0,"orderId":0},{"price":64215.4,"quantity":0.00781958,"orderId":2}],"prevSeqId":31327884975,"currentSeqId":31327884994,"checksum":-576947701}
{"action":"update","channel":"books","instrumentId":"BTC-USDT","instAsks":[{"price":64338,"quantity":0,"orderId":0},{"price":64338.8,"quantity":0.11187141,"orderId":1},{"price":64404.9,"quantity":0.16410438,"orderId":2},{"price":64406.9,"quantity":0,"orderId":0},{"price":64407.4,"quantity":0.05493598,"orderId":3},{"price":64412.6,"quantity":0.05866956,"orderId":1},{"price":64506.4,"quantity":0.00004945,"orderId":2}],"instBids":[{"price":64302.9,"quantity":0.11187141,"orderId":1}],"prevSeqId":31327884994,"currentSeqId":31327885102,"checksum":-456226898}
{"action":"update","channel":"books","instrumentId":"BTC-USDT","instAsks":[{"price":64338,"quantity":0.11187164,"orderId":1},{"price":64338.8,"quantity":0,"orderId":0},{"price":64415.6,"quantity":0.0309998,"orderId":1}],"instBids":[{"price":64323.8,"quantity":0.0155468,"orderId":1},{"price":64323.7,"quantity":0,"orderId":0},{"price":64301.5,"quantity":0.01556672,"orderId":2},{"price":64301.2,"quantity":0.561317,"orderId":2},{"price":64176.1,"quantity":0.00077054,"orderId":4}],"prevSeqId":31327885102,"currentSeqId":31327885114,"checksum":-440865827}
{"action":"update","channel":"books","instrumentId":"BTC-USDT","instAsks":[{"price":64326,"quantity":0.0104896,"orderId":1},{"price":64326.7,"quantity":0,"orderId":0},{"price":64327.9,"quantity":0.06253735,"orderId":1},{"price":64337.1,"quantity":0,"orderId":0},{"price":64338,"quantity":0.00020734,"orderId":1},{"price":64340.1,"quantity":0.11186857,"orderId":1},{"price":64343.9,"quantity":0,"orderId":0},{"price":64344.1,"quantity":0.09111989,"orderId":1},{"price":64350.6,"quantity":0,"orderId":0},{"price":64350.9,"quantity":0.19063765,"orderId":2},{"price":64367.6,"quantity":0,"orderId":0},{"price":64376.5,"quantity":2.72018282,"orderId":1},{"price":64376.6,"quantity":0.0136,"orderId":2},{"price":64418,"quantity":0.39050538,"orderId":2},{"price":64507.6,"quantity":0.00003677,"orderId":1}],"instBids":[{"price":64307.1,"quantity":0.09328428,"orderId":1},{"price":64306.9,"quantity":0,"orderId":0},{"price":64304.5,"quantity":0.1118683,"orderId":1},{"price":64302.9,"quantity":0,"orderId":0},{"price":64300.4,"quantity":0.11686037,"orderId":1},{"price":64300.1,"quantity":0.0174,"orderId":1},{"price":64177.9,"quantity":0.05193236,"orderId":2},{"price":64159.9,"quantity":0,"orderId":0}],"prevSeqId":31327885114,"currentSeqId":31327885152,"checksum":-1116706192}
{"action":"update","channel":"books","instrumentId":"BTC-USDT","instAsks":[{"price":64338,"quantity":0,"orderId":0},{"price":64374.4,"quantity":2.72018282,"orderId":1},{"price":64376.5,"quantity":0,"orderId":0},{"price":64507.9,"quantity":0.00679745,"orderId":1}],"instBids":[{"price":64324,"quantity":1.21242838,"orderId":15},{"price":64318.4,"quantity":0,"orderId":0},{"price":64318.2,"quantity":0.0005,"orderId":1},{"price":64295.8,"quantity":2.20641643,"orderId":3},{"price":64292,"quantity":0.02250192,"orderId":2},{"price":64218.5,"quantity":0,"orderId":0},{"price":64199.1,"quantity":0,"orderId":0},{"price":64188.8,"quantity":0.02872106,"orderId":2},{"price":64159.9,"quantity":0.01564601,"orderId":2},{"price":64159.6,"quantity":1.5,"orderId":1}],"prevSeqId":31327885152,"currentSeqId":31327885166,"checksum":-1936830873}
{"action":"update","channel":"books","instrumentId":"BTC-USDT","instAsks":[{"price":64340.1,"quantity":0,"orderId":0},{"price":64341.3,"quantity":0.11186834,"orderId":1},{"price":64367.8,"quantity":2.72018282,"orderId":1},{"price":64367.9,"quantity":0.02758264,"orderId":1},{"price":64374.4,"quantity":0,"orderId":0}],"instBids":[{"price":64318.4,"quantity":0.0005,"orderId":1},{"price":64318.2,"quantity":0,"orderId":0},{"price":64307.3,"quantity":0.00933,"orderId":1},{"price":64301.6,"quantity":0,"orderId":0},{"price":64295.8,"quantity":0.00384923,"orderId":2},{"price":64292.1,"quantity":2.2025672,"orderId":1},{"price":64289.9,"quantity":0,"orderId":0}],"prevSeqId":31327885166,"currentSeqId":31327885182,"checksum":-1853949655}
{"action":"update","channel":"books","instrumentId":"BTC-USDT","instAsks":[{"price":64330,"quantity":0.080815,"orderId":2},{"price":64330.7,"quantity":0.01106532,"orderId":1},{"price":64358.7,"quantity":0,"orderId":0},{"price":64374.2,"quantity":0.02329077,"orderId":1},{"price":64507.9,"quantity":0,"orderId":0}],"instBids":[{"price":64312.5,"quantity":0.06036993,"orderId":2}],"prevSeqId":31327885182,"currentSeqId":31327885193,"checksum":-1005325671}
{"action":"update","channel":"books","instrumentId":"BTC-USDT","instAsks":[{"price":64329.8,"quantity":0.0045663,"orderId":1},{"price":64396.6,"quantity":1.79481134,"orderId":1},{"price":64506.4,"quantity":0,"orderId":0},{"price":64507.6,"quantity":0,"orderId":0}],"instBids":[{"price":64304,"quantity":0.15620664,"orderId":2},{"price":64220.2,"quantity":0.03562048,"orderId":2}],"prevSeqId":31327885193,"currentSeqId":31327885201,"checksum":-1105879801}
{"action":"update","channel":"books","instrumentId":"BTC-USDT","instAsks":[{"price":64331.8,"quantity":0.04848004,"orderId":1},{"price":64331.9,"quantity":0,"orderId":0},{"price":64333.3,"quantity":0,"orderId":0},{"price":64335.3,"quantity":0.08874032,"orderId":2},{"price":64335.7,"quantity":0.15536061,"orderId":1},{"price":64341.3,"quantity":0,"orderId":0},{"price":64341.4,"quantity":0.06298458,"orderId":2},{"price":64342.3,"quantity":0.11186543,"orderId":1},{"price":64366.1,"quantity":0,"orderId":0},{"price":64367.8,"quantity":0,"orderId":0},{"price":64371.6,"quantity":2.77885238,"orderId":2},{"price":64506.4,"quantity":0.00004945,"orderId":2},{"price":64507.6,"quantity":0.00003677,"orderId":1}],"instBids":[{"price":64306.2,"quantity":0.11186545,"orderId":1},{"price":64304.5,"quantity":0,"orderId":0},{"price":64303,"quantity":0.01555135,"orderId":1},{"price":64301.5,"quantity":0.000015,"orderId":1},{"price":64287,"quantity":0,"orderId":0}],"prevSeqId":31327885201,"currentSeqId":31327885229,"checksum":2071839678}
{"action":"update","channel":"books","instrumentId":"BTC-USDT","instAsks":[{"price":64341.3,"quantity":0.11186642,"orderId":1},{"price":64341.4,"quantity":0.033078,"orderId":1},{"price":64342.3,"quantity":0,"orderId":0},{"price":64369.5,"quantity":0.05672,"orderId":2},{"price":64369.8,"quantity":2.65089054,"orderId":1},{"price":64371.6,"quantity":0.05866956,"orderId":1},{"price":64507.6,"quantity":0,"orderId":0}],"instBids":[{"price":64295.8,"quantity":2.20641643,"orderId":3},{"price":64292.1,"quantity":0,"orderId":0},{"price":64290.3,"quantity":0.02553567,"orderId":1}],"prevSeqId":31327885229,"currentSeqId":31327885240,"checksum":-1855596802}
{"action":"update","channel":"books","instrumentId":"BTC-USDT","instAsks":[{"price":64341.3,"quantity":0.11186833,"orderId":1},{"price":64361.1,"quantity":0.02329552,"orderId":1},{"price":64369.7,"quantity":1.59053441,"orderId":1},{"price":64374.2,"quantity":0,"orderId":0},{"price":64506.4,"quantity":0,"orderId":0}],"instBids":[{"price":64306.2,"quantity":0,"orderId":0},{"price":64304.5,"quantity":0.11186873,"orderId":1},{"price":64256.5,"quantity":0.38001632,"orderId":1},{"price":64231.7,"quantity":0,"orderId":0},{"price":64214.4,"quantity":0.0015312,"orderId":1}],"prevSeqId":31327885240,"currentSeqId":31327885252,"checksum":1649497329}
{"action":"update","channel":"books","instrumentId":"BTC-USDT","instAsks":[{"price":64340.1,"quantity":0.11186883,"orderId":1},{"price":64341.3,"quantity":0,"orderId":0},{"price":64367.8,"quantity":2.65089054,"orderId":1},{"price":64369.7,"quantity":0,"orderId":0},{"price":64369.8,"quantity":0,"orderId":0},{"price":64419.2,"quantity":0.0309998,"orderId":1},{"price":64506.4,"quantity":0.00004945,"orderId":2}],"instBids":[{"price":64228.1,"quantity":0.192341,"orderId":3}],"prevSeqId":31327885252,"currentSeqId":31327885264,"checksum":-517094724}
{"action":"update","channel":"books","instrumentId":"BTC-USDT","instAsks":[{"price":64326,"quantity":0.0912896,"orderId":2},{"price":64340.1,"quantity":0,"orderId":0},{"price":64341.3,"quantity":0.11186838,"orderId":1},{"price":64343.9,"quantity":0.09604245,"orderId":1},{"price":64344.1,"quantity":0,"orderId":0},{"price":64350.7,"quantity":0.12411565,"orderId":1},{"price":64350.9,"quantity":0.07772148,"orderId":1},{"price":64506.4,"quantity":0,"orderId":0}],"instBids":[{"price":64307.1,"quantity":0,"orderId":0},{"price":64306.9,"quantity":0.09011893,"orderId":1},{"price":64300.4,"quantity":0,"orderId":0},{"price":64300.2,"quantity":0.20987693,"orderId":2},{"price":64159.1,"quantity":0.00001007,"orderId":1}],"prevSeqId":31327885264,"currentSeqId":31327885280,"checksum":851642405}
{"action":"update","channel":"books","instrumentId":"BTC-USDT","instAsks":[{"price":64449.4,"quantity":0,"orderId":0},{"price":64450.5,"quantity":0.01616228,"orderId":1}],"instBids":[{"price":64324,"quantity":1.20956234,"orderId":15},{"price":64306.2,"quantity":0.1118667,"orderId":1},{"price":64304.5,"quantity":0,"orderId":0}],"prevSeqId":31327885280,"currentSeqId":31327885288,"checksum":1260667186}
{"action":"update","channel":"books","instrumentId":"BTC-USDT","instAsks":[{"price":64404.9,"quantity":0.156341,"orderId":1},{"price":64407.4,"quantity":0.04717289,"orderId":2},{"price":64409.6,"quantity":0.00776282,"orderId":1},{"price":64409.7,"quantity":0.0077628,"orderId":1},{"price":64505.2,"quantity":0,"orderId":0},{"price":64506.2,"quantity":0,"orderId":0}],"instBids":[{"price":64306.2,"quantity":0.11186675,"orderId":1},{"price":64217.5,"quantity":0.00778604,"orderId":1},{"price":64215.4,"quantity":0.00003328,"orderId":1},{"price":64199.1,"quantity":0.00778827,"orderId":1},{"price":64188.8,"quantity":0.02093154,"orderId":1},{"price":64159.6,"quantity":0,"orderId":0},{"price":64159.1,"quantity":0,"orderId":0}],"prevSeqId":31327885288,"currentSeqId":31327885313,"checksum":1260667186}
{"action":"update","channel":"books","instrumentId":"BTC-USDT","instAsks":[{"price":64326.8,"quantity":0,"orderId":0},{"price":64327.9,"quantity":0,"orderId":0},{"price":64330.7,"quantity":0,"orderId":0},{"price":64332.1,"quantity":0.01106532,"orderId":1},{"price":64341.3,"quantity":0,"orderId":0},{"price":64343,"quantity":0.11186413,"orderId":1},{"price":64343.9,"quantity":0,"orderId":0},{"price":64344.2,"quantity":0.09025661,"orderId":1},{"price":64350.7,"quantity":0,"orderId":0},{"price":64350.9,"quantity":0.19322977,"orderId":2},{"price":64361.1,"quantity":0,"orderId":0},{"price":64374.2,"quantity":0.02329077,"orderId":1},{"price":64505.2,"quantity":0.26001501,"orderId":2},{"price":64506.2,"quantity":0.00005269,"orderId":1},{"price":64506.4,"quantity":0.00004945,"orderId":2}],"instBids":[{"price":64324,"quantity":1.42956234,"orderId":16},{"price":64307.1,"quantity":0.09125964,"orderId":1},{"price":64306.9,"quantity":0,"orderId":0},{"price":64306.2,"quantity":0.11186423,"orderId":1},{"price":64300.4,"quantity":0.11200937,"orderId":1},{"price":64300.2,"quantity":0.086309,"orderId":1},{"price":64298.2,"quantity":1.27238481,"orderId":2},{"price":64159.9,"quantity":0,"orderId":0}],"prevSeqId":31327885313,"currentSeqId":31327885342,"checksum":-382063058}
{"action":"update","channel":"books","instrumentId":"BTC-USDT","instAsks":[{"price":64327.2,"quantity":0.143269,"orderId":1},{"price":64327.9,"quantity":0.02318203,"orderId":1},{"price":64343,"quantity":0.11186464,"orderId":1},{"price":64344,"quantity":0.1085537,"orderId":2},{"price":64344.2,"quantity":0,"orderId":0},{"price":64350.7,"quantity":0.12131802,"orderId":1},{"price":64350.9,"quantity":0.07772148,"orderId":1},{"price":64367.8,"quantity":0,"orderId":0},{"price":64372.4,"quantity":2.65089054,"orderId":1},{"price":64407.4,"quantity":0.0309998,"orderId":1},{"price":64409.4,"quantity":0.109984,"orderId":2},{"price":64431.6,"quantity":0,"orderId":0},{"price":64433.6,"quantity":0.17216654,"orderId":2},{"price":64506.4,"quantity":0,"orderId":0}],"instBids":[{"price":64318.4,"quantity":0,"orderId":0},{"price":64318.2,"quantity":0.0005,"orderId":1},{"price":64307.1,"quantity":0.11186464,"orderId":1},{"price":64307,"quantity":0.09474228,"orderId":1},{"price":64306.2,"quantity":0,"orderId":0},{"price":64300.4,"quantity":0,"orderId":0},{"price":64300.2,"quantity":0.20065049,"orderId":2},{"price":64296.1,"quantity":2.2696981,"orderId":1},{"price":64295.8,"quantity":0.00384923,"orderId":2}],"prevSeqId":31327885342,"currentSeqId":31327885379,"checksum":1262027935}
{"action":"update","channel":"books","instrumentId":"BTC-USDT","instAsks":[{"price":64329,"quantity":0,"orderId":0},{"price":64372.3,"quantity":2.65089054,"orderId":1},{"price":64372.4,"quantity":0,"orderId":0},{"price":64407.3,"quantity":0,"orderId":0},{"price":64410,"quantity":0.01617244,"orderId":1},{"price":64471.8,"quantity":0,"orderId":0},{"price":64474.5,"quantity":1.57807244,"orderId":2},{"price":64480.7,"quantity":0,"orderId":0},{"price":64483.4,"quantity":0.05174465,"orderId":1},{"price":64506.4,"quantity":0.00004945,"orderId":2},{"price":64507.6,"quantity":0.00003677,"orderId":1}],"instBids":[{"price":64318.3,"quantity":0,"orderId":0},{"price":64318.1,"quantity":0.0005,"orderId":1},{"price":64316,"quantity":0.10156467,"orderId":3},{"price":64311.2,"quantity":0,"orderId":0},{"price":64296.1,"quantity":0,"orderId":0},{"price":64295.8,"quantity":2.27354733,"orderId":3},{"price":64176.7,"quantity":0.01617244,"orderId":1},{"price":64174.3,"quantity":0,"orderId":0},{"price":64159.9,"quantity":0.01564601,"orderId":2},{"price":64159.6,"quantity":1.5,"orderId":1}],"prevSeqId":31327885379,"currentSeqId":31327885402,"checksum":926776638}
{"action":"update","channel":"books","instrumentId":"BTC-USDT","instAsks":[{"price":64327.1,"quantity":0.13444143,"orderId":1},{"price":64327.9,"quantity":0,"orderId":0},{"price":64330.9,"quantity":0.01106532,"orderId":1},{"price":64332.1,"quantity":0,"orderId":0},{"price":64341.4,"quantity":0.08966989,"orderId":2},{"price":64341.8,"quantity":0.11186606,"orderId":1},{"price":64342.3,"quantity":0.156341,"orderId":1},{"price":64343,"quantity":0,"orderId":0},{"price":64344,"quantity":0.00973533,"orderId":1},{"price":64350.7,"quantity":0,"orderId":0},{"price":64361.1,"quantity":0.02329552,"orderId":1},{"price":64367.8,"quantity":2.65089054,"orderId":1},{"price":64372.3,"quantity":0,"orderId":0},{"price":64374.2,"quantity":0,"orderId":0},{"price":64427.2,"quantity":0.29100159,"orderId":2},{"price":64436.3,"quantity":0,"orderId":0},{"price":64437.8,"quantity":0,"orderId":0},{"price":64507.9,"quantity":0.00679745,"orderId":1},{"price":64508.1,"quantity":0.00001147,"orderId":1}],"instBids":[{"price":64324,"quantity":0.94956234,"orderId":14},{"price":64307.1,"quantity":0,"orderId":0},{"price":64307,"quantity":0,"orderId":0},{"price":64306.2,"quantity":0.11186606,"orderId":1},{"price":64300.2,"quantity":0.086309,"orderId":1},{"price":64159.6,"quantity":1.5161619,"orderId":2},{"price":64159.1,"quantity":0.00001007,"orderId":1}],"prevSeqId":31327885402,"currentSeqId":31327885450,"checksum":664696826}
{"action":"update","channel":"books","instrumentId":"BTC-USDT","instAsks":[{"price":64329.8,"quantity":0,"orderId":0},{"price":64335.2,"quantity":0.02307401,"orderId":1},{"price":64338,"quantity":0.00030721,"orderId":1},{"price":64341.8,"quantity":0.11186651,"orderId":1},{"price":64344,"quantity":0.10212009,"orderId":2},{"price":64350.7,"quantity":0.10940727,"orderId":1},{"price":64398.2,"quantity":0,"orderId":0},{"price":64417.9,"quantity":0,"orderId":0},{"price":64419.7,"quantity":0.00646801,"orderId":1},{"price":64420.3,"quantity":0,"orderId":0},{"price":64422.7,"quantity":0.01616925,"orderId":1},{"price":64430.9,"quantity":0,"orderId":0},{"price":64495.4,"quantity":0.0161672,"orderId":1}],"instBids":[{"price":64324,"quantity":1.20956234,"orderId":15},{"price":64318.2,"quantity":0,"orderId":0},{"price":64318.1,"quantity":0,"orderId":0},{"price":64318,"quantity":0.0813,"orderId":2},{"price":64317.9,"quantity":0.0005,"orderId":1},{"price":64306.9,"quantity":0.08835758,"orderId":1},{"price":64300.2,"quantity":0.19788633,"orderId":2},{"price":64173.1,"quantity":0.00646801,"orderId":1},{"price":64170.7,"quantity":0.00001077,"orderId":1},{"price":64164.4,"quantity":0,"orderId":0}],"prevSeqId":31327885450,"currentSeqId":31327885479,"checksum":-795197287}
{"action":"update","channel":"books","instrumentId":"BTC-USDT","instAsks":[{"price":64327.1,"quantity":0,"orderId":0},{"price":64327.9,"quantity":0.04848005,"orderId":1},{"price":64367.6,"quantity":2.65089054,"orderId":1},{"price":64367.7,"quantity":1.59053438,"orderId":1},{"price":64367.8,"quantity":0,"orderId":0},{"price":64407.5,"quantity":0.00776307,"orderId":1},{"price":64409.7,"quantity":0,"orderId":0},{"price":64432.7,"quantity":0.01616674,"orderId":1},{"price":64497.2,"quantity":0.01617675,"orderId":2},{"price":64507.9,"quantity":0,"orderId":0},{"price":64508.1,"quantity":0,"orderId":0}],"instBids":[{"price":64307,"quantity":0.09824412,"orderId":1},{"price":64306.9,"quantity":0,"orderId":0},{"price":64218.9,"quantity":0.02395246,"orderId":2},{"price":64217.5,"quantity":0,"orderId":0},{"price":64203.3,"quantity":1.53114776,"orderId":2},{"price":64199.1,"quantity":0,"orderId":0},{"price":64166.8,"quantity":0.074952,"orderId":3},{"price":64158.8,"quantity":0.00031097,"orderId":2},{"price":64158.3,"quantity":0.00014683,"orderId":1}],"prevSeqId":31327885479,"currentSeqId":31327885499,"checksum":-47585308}
{"action":"update","channel":"books","instrumentId":"BTC-USDT","instAsks":[{"price":64361.1,"quantity":0,"orderId":0},{"price":64367.7,"quantity":0,"orderId":0},{"price":64374.2,"quantity":0.02329077,"orderId":1},{"price":64476.2,"quantity":0,"orderId":0},{"price":64507.9,"quantity":0.00679745,"orderId":1},{"price":64508.1,"quantity":0.00001147,"orderId":1}],"instBids":[{"price":64247.5,"quantity":0.01617297,"orderId":1},{"price":64244.4,"quantity":0.00308148,"orderId":1},{"price":64158.3,"quantity":0,"orderId":0}],"prevSeqId":31327885499,"currentSeqId":31327885507,"checksum":-47585308}
{"action":"update","channel":"books","instrumentId":"BTC-USDT","instAsks":[{"price":64338,"quantity":0,"orderId":0},{"price":64341.3,"quantity":0.11186735,"orderId":1},{"price":64341.8,"quantity":0,"orderId":0},{"price":64455.5,"quantity":0,"orderId":0},{"price":64509,"quantity":0.00043689,"orderId":3},{"price":64509.2,"quantity":0.00006054,"orderId":3}],"instBids":[{"price":64315.6,"quantity":0.0146,"orderId":1},{"price":64306.2,"quantity":0,"orderId":0},{"price":64304.5,"quantity":0.11186735,"orderId":1},{"price":64241.7,"quantity":0.01617282,"orderId":1},{"price":64239.2,"quantity":0,"orderId":0},{"price":64220.2,"quantity":0.02999967,"orderId":1}],"prevSeqId":31327885507,"currentSeqId":31327885528,"checksum":1830727293}
{"action":"update","channel":"books","instrumentId":"BTC-USDT","instAsks":[{"price":64341.3,"quantity":0,"orderId":0},{"price":64342.2,"quantity":0.11186542,"orderId":1},{"price":64361.1,"quantity":0.02329552,"orderId":1},{"price":64374.2,"quantity":0,"orderId":0},{"price":64458,"quantity":0.01294125,"orderId":1},{"price":64479.3,"quantity":0.24814198,"orderId":1},{"price":64509,"quantity":0,"orderId":0},{"price":64509.2,"quantity":0,"orderId":0}],"instBids":[{"price":64306.2,"quantity":0.1118655,"orderId":1},{"price":64304.5,"quantity":0,"orderId":0}],"prevSeqId":31327885528,"currentSeqId":31327885543,"checksum":-1867335047}
{"action":"update","channel":"books","instrumentId":"BTC-USDT","instAsks":[{"price":64341.3,"quantity":0.11186646,"orderId":1},{"price":64342.2,"quantity":0,"orderId":0}],"instBids":[{"price":64221.6,"quantity":0,"orderId":0},{"price":64221.4,"quantity":0.00194901,"orderId":1}],"prevSeqId":31327885543,"currentSeqId":31327885550,"checksum":164307762}
{"action":"update","channel":"books","instrumentId":"BTC-USDT","instAsks":[{"price":64341.3,"quantity":0,"orderId":0},{"price":64341.8,"quantity":0.11186595,"orderId":1}],"instBids":[{"price":64324,"quantity":1.42956234,"orderId":16},{"price":64318.1,"quantity":0.0005,"orderId":1},{"price":64317.9,"quantity":0,"orderId":0},{"price":64306.2,"quantity":0.11186666,"orderId":1},{"price":64225.6,"quantity":0.00562034,"orderId":1},{"price":64158.8,"quantity":0,"orderId":0}],"prevSeqId":31327885550,"currentSeqId":31327885567,"checksum":-1425770175}
{"action":"update","channel":"books","instrumentId":"BTC-USDT","instAsks":[{"price":64330.9,"quantity":0,"orderId":0},{"price":64331.6,"quantity":0.01106532,"orderId":1},{"price":64439.3,"quantity":0,"orderId":0},{"price":64509,"quantity":0.00043689,"orderId":3}],"instBids":[],"prevSeqId":31327885567,"currentSeqId":31327885570,"checksum":-1310129826}
{"action":"update","channel":"books","instrumentId":"BTC-USDT","instAsks":[{"price":64341.8,"quantity":0,"orderId":0},{"price":64343.5,"quantity":0.11186358,"orderId":1}],"instBids":[{"price":64307.1,"quantity":0.11186394,"orderId":1},{"price":64306.2,"quantity":0,"orderId":0}],"prevSeqId":31327885570,"currentSeqId":31327885577,"checksum":2143238735}
{"action":"update","channel":"books","instrumentId":"BTC-USDT","instAsks":[{"price":64326,"quantity":0.0104896,"orderId":1},{"price":64343,"quantity":0.11186428,"orderId":1},{"price":64343.5,"quantity":0,"orderId":0},{"price":64344,"quantity":0.00973533,"orderId":1},{"price":64344.3,"quantity":0.08865766,"orderId":1},{"price":64350.7,"quantity":0,"orderId":0},{"price":64351.1,"quantity":0.1220989,"orderId":1},{"price":64458.3,"quantity":0.08707025,"orderId":2},{"price":64509,"quantity":0,"orderId":0}],"instBids":[{"price":64307.3,"quantity":0.10299115,"orderId":2},{"price":64307.1,"quantity":0,"orderId":0},{"price":64307,"quantity":0,"orderId":0},{"price":64306.2,"quantity":0.11186417,"orderId":1},{"price":64300.6,"quantity":0.10898312,"orderId":1},{"price":64300.2,"quantity":0.086309,"orderId":1}],"prevSeqId":31327885577,"currentSeqId":31327885598,"checksum":846609513}
{"action":"update","channel":"books","instrumentId":"BTC-USDT","instAsks":[{"price":64326,"quantity":0.0912896,"orderId":2},{"price":64338,"quantity":0.0001908,"orderId":1},{"price":64341.3,"quantity":0.11186642,"orderId":1},{"price":64343,"quantity":0,"orderId":0},{"price":64344,"quantity":0.10360798,"orderId":2},{"price":64344.3,"quantity":0,"orderId":0},{"price":64350.7,"quantity":0.11116269,"orderId":1},{"price":64351.1,"quantity":0,"orderId":0}],"instBids":[{"price":64324,"quantity":1.20956234,"orderId":15},{"price":64318.1,"quantity":0,"orderId":0},{"price":64317.9,"quantity":0.0005,"orderId":1},{"price":64307.3,"quantity":0.00933,"orderId":1},{"price":64307,"quantity":0.0871608,"orderId":1},{"price":64306.2,"quantity":0.11186714,"orderId":1},{"price":64300.6,"quantity":0,"orderId":0},{"price":64300.2,"quantity":0.19516506,"orderId":2}],"prevSeqId":31327885598,"currentSeqId":31327885623,"checksum":-1974544762}
{"action":"update","channel":"books","instrumentId":"BTC-USDT","instAsks":[{"price":64367.5,"quantity":1.5905344,"orderId":1},{"price":64508.1,"quantity":0,"orderId":0}],"instBids":[{"price":64318.1,"quantity":0.0005,"orderId":1},{"price":64317.9,"quantity":0,"orderId":0},{"price":64306.2,"quantity":0,"orderId":0},{"price":64306.1,"quantity":0.26820791,"orderId":2},{"price":64158.8,"quantity":0.00031097,"orderId":2}],"prevSeqId":31327885623,"currentSeqId":31327885632,"checksum":-1749637367}
{"action":"update","channel":"books","instrumentId":"BTC-USDT","instAsks":[{"price":64329.9,"quantity":0.00468238,"orderId":1},{"price":64471.9,"quantity":0,"orderId":0},{"price":64473.7,"quantity":0.01617264,"orderId":1},{"price":64495.4,"quantity":0,"orderId":0},{"price":64497.9,"quantity":0.0161859,"orderId":2}],"instBids":[{"price":64318.3,"quantity":0.00468331,"orderId":1},{"price":64158.8,"quantity":0,"orderId":0}],"prevSeqId":31327885632,"currentSeqId":31327885642,"checksum":101069932}
{"action":"update","channel":"books","instrumentId":"BTC-USDT","instAsks":[{"price":64407.5,"quantity":0,"orderId":0},{"price":64409.6,"quantity":0,"orderId":0},{"price":64410.3,"quantity":0.00776274,"orderId":1},{"price":64412.7,"quantity":0.00776245,"orderId":1},{"price":64414.4,"quantity":0,"orderId":0},{"price":64418,"quantity":0.39826719,"orderId":3},{"price":64508.1,"quantity":0.00001147,"orderId":1}],"instBids":[{"price":64207.5,"quantity":0.00778725,"orderId":1},{"price":64203.3,"quantity":1.52336,"orderId":1},{"price":64159.1,"quantity":0,"orderId":0}],"prevSeqId":31327885642,"currentSeqId":31327885749,"checksum":101069932}
{"action":"update","channel":"books","instrumentId":"BTC-USDT","instAsks":[{"price":64338,"quantity":0,"orderId":0},{"price":64341.3,"quantity":0,"orderId":0},{"price":64341.8,"quantity":0.11186629,"orderId":1},{"price":64409.8,"quantity":0.09417758,"orderId":1},{"price":64410.5,"quantity":0,"orderId":0},{"price":64411.8,"quantity":0,"orderId":0},{"price":64431.1,"quantity":0,"orderId":0},{"price":64479.3,"quantity":0,"orderId":0},{"price":64509,"quantity":0.00043689,"orderId":3},{"price":64509.2,"quantity":0.00006054,"orderId":3},{"price":64509.4,"quantity":0.00528449,"orderId":1},{"price":64509.6,"quantity":0.0000314,"orderId":2}],"instBids":[{"price":64318.1,"quantity":0,"orderId":0},{"price":64317.9,"quantity":0.0005,"orderId":1},{"price":64315.6,"quantity":0.0148,"orderId":1},{"price":64306.2,"quantity":0.11186629,"orderId":1},{"price":64306.1,"quantity":0.156341,"orderId":1},{"price":64221.3,"quantity":0,"orderId":0},{"price":64202,"quantity":0,"orderId":0},{"price":64159.1,"quantity":0.00001007,"orderId":1}],"prevSeqId":31327885749,"currentSeqId":31327885770,"checksum":-1366009949}
{"action":"update","channel":"books","instrumentId":"BTC-USDT","instAsks":[{"price":64341.3,"quantity":0.11186719,"orderId":1},{"price":64341.8,"quantity":0,"orderId":0},{"price":64482.4,"quantity":0,"orderId":0},{"price":64484.2,"quantity":0.00646801,"orderId":1},{"price":64485.4,"quantity":0,"orderId":0},{"price":64486.6,"quantity":0.0161694,"orderId":1}],"instBids":[{"price":64306.2,"quantity":0,"orderId":0},{"price":64304.5,"quantity":0.11186714,"orderId":1}],"prevSeqId":31327885770,"currentSeqId":31327885782,"checksum":-919027367}
{"action":"update","channel":"books","instrumentId":"BTC-USDT","instAsks":[{"price":64361.1,"quantity":0,"orderId":0},{"price":64374.2,"quantity":0.02329077,"orderId":1},{"price":64439.2,"quantity":0,"orderId":0},{"price":64509.7,"quantity":0.0000139,"orderId":1}],"instBids":[{"price":64324,"quantity":1.36956234,"orderId":16},{"price":64306.2,"quantity":0.11186671,"orderId":1},{"price":64304.5,"quantity":0,"orderId":0},{"price":64251.9,"quantity":0.04666185,"orderId":2}],"prevSeqId":31327885782,"currentSeqId":31327885790,"checksum":1074187545}
{"action":"update","channel":"books","instrumentId":"BTC-USDT","instAsks":[{"price":64341.3,"quantity":0,"orderId":0},{"price":64342.2,"quantity":0.11186532,"orderId":1},{"price":64343.1,"quantity":0,"orderId":0},{"price":64412.5,"quantity":0.00776247,"orderId":1},{"price":64412.7,"quantity":0,"orderId":0},{"price":64439.2,"quantity":0.00096765,"orderId":1}],"instBids":[{"price":64256.1,"quantity":0.47062977,"orderId":3}],"prevSeqId":31327885790,"currentSeqId":31327885799,"checksum":-829769095}
{"action":"update","channel":"books","instrumentId":"BTC-USDT","instAsks":[{"price":64341.3,"quantity":0.11186705,"orderId":1},{"price":64342.2,"quantity":0,"orderId":0},{"price":64390.5,"quantity":0,"orderId":0},{"price":64509.8,"quantity":0.00034037,"orderId":1}],"instBids":[{"price":64306.2,"quantity":0,"orderId":0},{"price":64304.5,"quantity":0.11186705,"orderId":1},{"price":64207.5,"quantity":0,"orderId":0},{"price":64204.6,"quantity":0.0077876,"orderId":1}],"prevSeqId":31327885799,"currentSeqId":31327885814,"checksum":399253552}
{"action":"update","channel":"books","instrumentId":"BTC-USDT","instAsks":[{"price":64394.9,"quantity":0.01294099,"orderId":1},{"price":64509.8,"quantity":0,"orderId":0}],"instBids":[{"price":64307.3,"quantity":0,"orderId":0},{"price":64306.2,"quantity":0.11186631,"orderId":1},{"price":64304.5,"quantity":0,"orderId":0},{"price":64295.8,"quantity":2.28287733,"orderId":4},{"price":64158.8,"quantity":0.00031097,"orderId":2}],"prevSeqId":31327885814,"currentSeqId":31327885820,"checksum":399253552}
{"action":"update","channel":"books","instrumentId":"BTC-USDT","instAsks":[{"price":64338.1,"quantity":0,"orderId":0},{"price":64339,"quantity":0,"orderId":0},{"price":64341.3,"quantity":0.11186653,"orderId":1},{"price":64341.4,"quantity":0.31513006,"orderId":3},{"price":64341.6,"quantity":0.543898,"orderId":1},{"price":64509.8,"quantity":0.00034037,"orderId":1}],"instBids":[{"price":64324,"quantity":1.34956961,"orderId":15},{"price":64306.2,"quantity":0.11186653,"orderId":1}],"prevSeqId":31327885820,"currentSeqId":31327885845,"checksum":298506190}
{"action":"update","channel":"books","instrumentId":"BTC-USDT","instAsks":[{"price":64341.3,"quantity":0,"orderId":0},{"price":64342.2,"quantity":0.11186506,"orderId":1},{"price":64371.5,"quantity":0.39215465,"orderId":2},{"price":64414.9,"quantity":0.24838976,"orderId":1},{"price":64434.2,"quantity":0.24840752,"orderId":2},{"price":64458.3,"quantity":0.00833218,"orderId":1},{"price":64458.6,"quantity":0.55210913,"orderId":1},{"price":64479.3,"quantity":0.24814198,"orderId":1},{"price":64509.6,"quantity":0,"orderId":0},{"price":64509.7,"quantity":0,"orderId":0},{"price":64509.8,"quantity":0,"orderId":0}],"instBids":[{"price":64307.1,"quantity":0.11186459,"orderId":1},{"price":64306.2,"quantity":0,"orderId":0},{"price":64225.6,"quantity":0,"orderId":0},{"price":64224.4,"quantity":0.24912647,"orderId":1},{"price":64221.4,"quantity":0,"orderId":0},{"price":64221.3,"quantity":0.00194904,"orderId":1},{"price":64205.1,"quantity":0.27029899,"orderId":2},{"price":64160,"quantity":0.25056929,"orderId":13}],"prevSeqId":31327885845,"currentSeqId":31327885875,"checksum":421869238}
{"action":"update","channel":"books","instrumentId":"BTC-USDT","instAsks":[{"price":64341.3,"quantity":0.11186591,"orderId":1},{"price":64342.2,"quantity":0,"orderId":0},{"price":64361.1,"quantity":0.02329552,"orderId":1},{"price":64374.2,"quantity":0,"orderId":0},{"price":64479.3,"quantity":0,"orderId":0},{"price":64509.6,"quantity":0.0000314,"orderId":2}],"instBids":[{"price":64307.1,"quantity":0,"orderId":0},{"price":64306.2,"quantity":0.11186591,"orderId":1}],"prevSeqId":31327885875,"currentSeqId":31327885886,"checksum":-1759602996}
{"action":"update","channel":"books","instrumentId":"BTC-USDT","instAsks":[{"price":64389.5,"quantity":0.01348133,"orderId":1},{"price":64392.1,"quantity":0,"orderId":0},{"price":64414.9,"quantity":0,"orderId":0},{"price":64434.2,"quantity":0.00009215,"orderId":1},{"price":64453.9,"quantity":0.01348133,"orderId":1},{"price":64456.5,"quantity":0,"orderId":0},{"price":64509.7,"quantity":0.0000139,"orderId":1}],"instBids":[{"price":64248.4,"quantity":0.08839482,"orderId":2},{"price":64246.5,"quantity":0,"orderId":0},{"price":64224.4,"quantity":0,"orderId":0},{"price":64205.1,"quantity":0.02109765,"orderId":1},{"price":64184.1,"quantity":0.01348133,"orderId":1},{"price":64182.2,"quantity":0,"orderId":0},{"price":64160,"quantity":0.00119308,"orderId":12},{"price":64158.3,"quantity":0.00014683,"orderId":1},{"price":64157.5,"quantity":0.00013042,"orderId":3}],"prevSeqId":31327885886,"currentSeqId":31327885904,"checksum":-1759602996}
{"action":"update","channel":"books","instrumentId":"BTC-USDT","instAsks":[{"price":64341.3,"quantity":0.11186525,"orderId":1}],"instBids":[{"price":64306.2,"quantity":0.11186525,"orderId":1},{"price":64220.4,"quantity":0.00562079,"orderId":1},{"price":64157.5,"quantity":0,"orderId":0}],"prevSeqId":31327885904,"currentSeqId":31327885913,"checksum":-105066671}
{"action":"update","channel":"books","instrumentId":"BTC-USDT","instAsks":[{"price":64327.9,"quantity":0.02216945,"orderId":1},{"price":64361.1,"quantity":0,"orderId":0},{"price":64374.2,"quantity":0.02329077,"orderId":1}],"instBids":[{"price":64324,"quantity":1.40956961,"orderId":16},{"price":64322,"quantity":0.60550956,"orderId":3},{"price":64319.8,"quantity":0,"orderId":0},{"price":64315.6,"quantity":0.0147,"orderId":1},{"price":64296.6,"quantity":2.37999563,"orderId":1},{"price":64295.8,"quantity":0.01317923,"orderId":3}],"prevSeqId":31327885913,"currentSeqId":31327885924,"checksum":-600330714}
{"action":"update","channel":"books","instrumentId":"BTC-USDT","instAsks":[{"price":64329.9,"quantity":0,"orderId":0},{"price":64340.1,"quantity":0.00025973,"orderId":1},{"price":64341.3,"quantity":0,"orderId":0},{"price":64342.2,"quantity":0.11186492,"orderId":1},{"price":64361.1,"quantity":0.02329552,"orderId":1},{"price":64374.2,"quantity":0,"orderId":0},{"price":64414.9,"quantity":0.24838976,"orderId":1},{"price":64434.2,"quantity":0.24840752,"orderId":2},{"price":64479.3,"quantity":0.24814198,"orderId":1},{"price":64509.6,"quantity":0,"orderId":0},{"price":64509.7,"quantity":0,"orderId":0}],"instBids":[{"price":64318,"quantity":0.0808,"orderId":1},{"price":64317.8,"quantity":0.0005,"orderId":1},{"price":64315.6,"quantity":0.0148,"orderId":1},{"price":64307.1,"quantity":0.11186492,"orderId":1},{"price":64306.2,"quantity":0,"orderId":0},{"price":64224.4,"quantity":0.24912647,"orderId":1},{"price":64205.1,"quantity":0.27029899,"orderId":2},{"price":64160,"quantity":0.25056929,"orderId":13},{"price":64158.8,"quantity":0,"orderId":0},{"price":64158.3,"quantity":0,"orderId":0}],"prevSeqId":31327885924,"currentSeqId":31327885943,"checksum":-204502453}
{"action":"update","channel":"books","instrumentId":"BTC-USDT","instAsks":[{"price":64338.9,"quantity":0.0166,"orderId":1},{"price":64340,"quantity":0.00775059,"orderId":1},{"price":64340.1,"quantity":0,"orderId":0},{"price":64341.3,"quantity":0.1118652,"orderId":1},{"price":64342.2,"quantity":0,"orderId":0}],"instBids":[{"price":64307.1,"quantity":0,"orderId":0},{"price":64306.2,"quantity":0.1118652,"orderId":1},{"price":64251.2,"quantity":0,"orderId":0},{"price":64242.8,"quantity":0.08128284,"orderId":2},{"price":64241.6,"quantity":0,"orderId":0},{"price":64186.9,"quantity":0,"orderId":0},{"price":64158.8,"quantity":0.00031097,"orderId":2},{"price":64158.3,"quantity":0.00014683,"orderId":1},{"price":64157.5,"quantity":0.00013042,"orderId":3}],"prevSeqId":31327885943,"currentSeqId":31327885957,"checksum":-1098468871}
{"action":"update","channel":"books","instrumentId":"BTC-USDT","instAsks":[{"price":64338.9,"quantity":0.02435059,"orderId":2},{"price":64340,"quantity":0,"orderId":0},{"price":64341.3,"quantity":0.11186649,"orderId":1},{"price":64509.6,"quantity":0.0000314,"orderId":2}],"instBids":[{"price":64318,"quantity":0.0813,"orderId":2},{"price":64317.8,"quantity":0,"orderId":0},{"price":64306.2,"quantity":0.11186649,"orderId":1},{"price":64251.9,"quantity":0.05960322,"orderId":3},{"price":64223.2,"quantity":0.04616496,"orderId":2},{"price":64187.6,"quantity":0.01294137,"orderId":1}],"prevSeqId":31327885957,"currentSeqId":31327885981,"checksum":-255677384}
{"action":"update","channel":"books","instrumentId":"BTC-USDT","instAsks":[{"price":64338.9,"quantity":0.0166,"orderId":1},{"price":64340.1,"quantity":0.00775059,"orderId":1},{"price":64341.3,"quantity":0.11186664,"orderId":1},{"price":64509.6,"quantity":0,"orderId":0}],"instBids":[{"price":64306.2,"quantity":0.11186664,"orderId":1},{"price":64236.8,"quantity":0.00646794,"orderId":1},{"price":64233.4,"quantity":0.02616905,"orderId":2},{"price":64231.1,"quantity":0.00001501,"orderId":1},{"price":64169.1,"quantity":0.01616905,"orderId":1}],"prevSeqId":31327885981,"currentSeqId":31327886003,"checksum":-1655504837}
{"action":"update","channel":"books","instrumentId":"BTC-USDT","instAsks":[{"price":64326,"quantity":0.0104896,"orderId":1},{"price":64327.9,"quantity":0,"orderId":0},{"price":64331.6,"quantity":0,"orderId":0},{"price":64332.4,"quantity":0.01106532,"orderId":1},{"price":64338.9,"quantity":0.02435059,"orderId":2},{"price":64340.1,"quantity":0,"orderId":0},{"price":64341.3,"quantity":0.00045751,"orderId":1},{"price":64343.5,"quantity":0.11186412,"orderId":1},{"price":64344,"quantity":0.00973533,"orderId":1},{"price":64344.3,"quantity":0.09577049,"orderId":1},{"price":64350.7,"quantity":0,"orderId":0},{"price":64351.1,"quantity":0.12065633,"orderId":1},{"price":64376.6,"quantity":0.74060204,"orderId":3},{"price":64458.6,"quantity":0,"orderId":0},{"price":64509.6,"quantity":0.0000314,"orderId":2}],"instBids":[{"price":64307.3,"quantity":0.0927033,"orderId":1},{"price":64307.1,"quantity":0.11186412,"orderId":1},{"price":64307,"quantity":0,"orderId":0},{"price":64306.2,"quantity":0,"orderId":0},{"price":64300.6,"quantity":0.123617,"orderId":1},{"price":64300.2,"quantity":0.086309,"orderId":1},{"price":64231.1,"quantity":0.01618173,"orderId":2},{"price":64157.5,"quantity":0,"orderId":0}],"prevSeqId":31327886003,"currentSeqId":31327886032,"checksum":1726378616}
{"action":"update","channel":"books","instrumentId":"BTC-USDT","instAsks":[{"price":64338.9,"quantity":0.0166,"orderId":1},{"price":64340.1,"quantity":0.00775059,"orderId":1},{"price":64341.3,"quantity":0,"orderId":0},{"price":64343.5,"quantity":0.11186437,"orderId":1},{"price":64367.6,"quantity":0,"orderId":0},{"price":64372.4,"quantity":2.47655164,"orderId":1}],"instBids":[{"price":64323.9,"quantity":0.07708139,"orderId":2},{"price":64307.4,"quantity":0.11186437,"orderId":1},{"price":64307.1,"quantity":0,"orderId":0},{"price":64218.9,"quantity":0.00778587,"orderId":1},{"price":64182.6,"quantity":0.01617264,"orderId":1}],"prevSeqId":31327886032,"currentSeqId":31327886053,"checksum":-1971577566}
{"action":"update","channel":"books","instrumentId":"BTC-USDT","instAsks":[{"price":64331.7,"quantity":0.00475603,"orderId":1},{"price":64367.5,"quantity":0,"orderId":0},{"price":64369.4,"quantity":2.44070205,"orderId":1},{"price":64372.4,"quantity":0,"orderId":0},{"price":64380.7,"quantity":0,"orderId":0},{"price":64386.3,"quantity":0,"orderId":0},{"price":64387.2,"quantity":0,"orderId":0},{"price":64388,"quantity":0.43699,"orderId":1},{"price":64458.3,"quantity":0.08707023,"orderId":2},{"price":64509.7,"quantity":0.0000139,"orderId":1},{"price":64509.8,"quantity":0.00034037,"orderId":1},{"price":64510,"quantity":0.00101459,"orderId":2}],"instBids":[{"price":64315.6,"quantity":0.0149,"orderId":1},{"price":64219.6,"quantity":0.01616652,"orderId":1},{"price":64158.3,"quantity":0,"orderId":0}],"prevSeqId":31327886053,"currentSeqId":31327886068,"checksum":300710891}
{"action":"update","channel":"books","instrumentId":"BTC-USDT","instAsks":[{"price":64338.9,"quantity":0.02435059,"orderId":2},{"price":64340.1,"quantity":0.00042564,"orderId":1},{"price":64341.3,"quantity":0.11186633,"orderId":1},{"price":64343.5,"quantity":0,"orderId":0},{"price":64367.8,"quantity":2.44070205,"orderId":1},{"price":64369.4,"quantity":0,"orderId":0}],"instBids":[{"price":64324,"quantity":1.18956961,"orderId":14},{"price":64318.8,"quantity":0,"orderId":0},{"price":64318.1,"quantity":0.00833802,"orderId":1},{"price":64315.1,"quantity":0.00933,"orderId":1},{"price":64307.4,"quantity":0,"orderId":0},{"price":64306.2,"quantity":0.11186633,"orderId":1},{"price":64295.8,"quantity":0.00384923,"orderId":2},{"price":64158.8,"quantity":0,"orderId":0}],"prevSeqId":31327886068,"currentSeqId":31327886084,"checksum":-1621252188}
{"action":"update","channel":"books","instrumentId":"BTC-USDT","instAsks":[{"price":64341.3,"quantity":0,"orderId":0},{"price":64343.5,"quantity":0.11186428,"orderId":1},{"price":64414.9,"quantity":0,"orderId":0},{"price":64418,"quantity":0.34652181,"orderId":2},{"price":64418.9,"quantity":0.05174465,"orderId":1},{"price":64479.3,"quantity":0,"orderId":0},{"price":64510.1,"quantity":0.00008038,"orderId":2}],"instBids":[{"price":64315.1,"quantity":0,"orderId":0},{"price":64307.4,"quantity":0.11186428,"orderId":1},{"price":64306.2,"quantity":0,"orderId":0},{"price":64301.1,"quantity":0.00933,"orderId":1},{"price":64224.4,"quantity":0,"orderId":0},{"price":64205.1,"quantity":0.02109765,"orderId":1},{"price":64177.9,"quantity":0.05193163,"orderId":2},{"price":64160,"quantity":0.00119308,"orderId":12},{"price":64158.8,"quantity":0.00031097,"orderId":2}],"prevSeqId":31327886084,"currentSeqId":31327886111,"checksum":-1347695986}
{"action":"update","channel":"books","instrumentId":"BTC-USDT","instAsks":[{"price":64326,"quantity":0.0912896,"orderId":2},{"price":64338.9,"quantity":0.0166,"orderId":1},{"price":64340,"quantity":0.00775059,"orderId":1},{"price":64340.1,"quantity":0,"orderId":0},{"price":64341.3,"quantity":0.11186616,"orderId":1},{"price":64343.5,"quantity":0,"orderId":0},{"price":64344,"quantity":0.10899367,"orderId":2},{"price":64344.3,"quantity":0,"orderId":0},{"price":64350.7,"quantity":0.10891009,"orderId":1},{"price":64351.1,"quantity":0,"orderId":0},{"price":64434.2,"quantity":0.00009215,"orderId":1},{"price":64510.2,"quantity":0.00018585,"orderId":4}],"instBids":[{"price":64307.4,"quantity":0,"orderId":0},{"price":64307.3,"quantity":0,"orderId":0},{"price":64307.1,"quantity":0.11186534,"orderId":1},{"price":64307,"quantity":0.09191171,"orderId":1},{"price":64300.6,"quantity":0,"orderId":0},{"price":64300.2,"quantity":0.20707533,"orderId":2},{"price":64224.4,"quantity":0.24912647,"orderId":1},{"price":64220.4,"quantity":0,"orderId":0},{"price":64205.1,"quantity":0.27029899,"orderId":2},{"price":64160,"quantity":0.25056929,"orderId":13},{"price":64158.3,"quantity":0.00014683,"orderId":1}],"prevSeqId":31327886111,"currentSeqId":31327886146,"checksum":-1010728705}
{"action":"update","channel":"books","instrumentId":"BTC-USDT","instAsks":[{"price":64338.9,"quantity":0.02435059,"orderId":2},{"price":64340,"quantity":0,"orderId":0},{"price":64350.8,"quantity":0.02017297,"orderId":2},{"price":64387.9,"quantity":0.46615,"orderId":1},{"price":64396.6,"quantity":0,"orderId":0},{"price":64510.4,"quantity":0.00010027,"orderId":4}],"instBids":[{"price":64307.1,"quantity":0,"orderId":0},{"price":64306.2,"quantity":0.11186549,"orderId":1},{"price":64298.2,"quantity":0.031482,"orderId":1},{"price":64256.5,"quantity":0.28237792,"orderId":1},{"price":64256.4,"quantity":0,"orderId":0},{"price":64157.5,"quantity":0.00013042,"orderId":3}],"prevSeqId":31327886146,"currentSeqId":31327886159,"checksum":-1578735574}
{"action":"update","channel":"books","instrumentId":"BTC-USDT","instAsks":[{"price":64338.9,"quantity":0.0166,"orderId":1},{"price":64340.1,"quantity":0.00775059,"orderId":1},{"price":64353.4,"quantity":1.20828302,"orderId":1},{"price":64367.7,"quantity":1.4644213,"orderId":1},{"price":64387.3,"quantity":0.27969008,"orderId":1},{"price":64510,"quantity":0,"orderId":0},{"price":64510.1,"quantity":0,"orderId":0},{"price":64510.2,"quantity":0,"orderId":0},{"price":64510.4,"quantity":0,"orderId":0}],"instBids":[{"price":64307.1,"quantity":0.11186535,"orderId":1},{"price":64306.2,"quantity":0,"orderId":0},{"price":64300.7,"quantity":1.22585397,"orderId":2}],"prevSeqId":31327886159,"currentSeqId":31327886171,"checksum":1282543896}
{"action":"update","channel":"books","instrumentId":"BTC-USDT","instAsks":[{"price":64338.9,"quantity":0.02435059,"orderId":2},{"price":64340.1,"quantity":0,"orderId":0},{"price":64367.6,"quantity":2.44070205,"orderId":1},{"price":64367.7,"quantity":0,"orderId":0},{"price":64367.8,"quantity":0,"orderId":0},{"price":64395.3,"quantity":1.82277613,"orderId":1},{"price":64395.9,"quantity":0,"orderId":0},{"price":64510,"quantity":0.00101459,"orderId":2},{"price":64510.1,"quantity":0.00008038,"orderId":2}],"instBids":[{"price":64307.1,"quantity":0,"orderId":0},{"price":64306.3,"quantity":0.11186573,"orderId":1},{"price":64259,"quantity":1.78228062,"orderId":1},{"price":64256.5,"quantity":0,"orderId":0},{"price":64226,"quantity":0.0056203,"orderId":1},{"price":64224.4,"quantity":0,"orderId":0},{"price":64205.1,"quantity":0.02109765,"orderId":1},{"price":64160,"quantity":0.00119308,"orderId":12}],"prevSeqId":31327886171,"currentSeqId":31327886197,"checksum":-1578735574}
{"action":"update","channel":"books","instrumentId":"BTC-USDT","instAsks":[{"price":64338.9,"quantity":0.0166,"orderId":1},{"price":64340.1,"quantity":0.00775059,"orderId":1},{"price":64341.3,"quantity":0,"orderId":0},{"price":64342.2,"quantity":0.11186506,"orderId":1},{"price":64510.1,"quantity":0,"orderId":0}],"instBids":[{"price":64324,"quantity":1.19112422,"orderId":15},{"price":64307.1,"quantity":0.11186506,"orderId":1},{"price":64306.3,"quantity":0,"orderId":0},{"price":64214.6,"quantity":0.00015773,"orderId":1}],"prevSeqId":31327886197,"currentSeqId":31327886318,"checksum":-2059934742}
{"action":"update","channel":"books","instrumentId":"BTC-USDT","instAsks":[{"price":64338.9,"quantity":0.02435059,"orderId":2},{"price":64340.1,"quantity":0,"orderId":0},{"price":64341.3,"quantity":0.11186562,"orderId":1},{"price":64342.2,"quantity":0,"orderId":0},{"price":64471.4,"quantity":0.00022195,"orderId":1},{"price":64475.3,"quantity":0.00393914,"orderId":1}],"instBids":[{"price":64307.1,"quantity":0,"orderId":0},{"price":64306.2,"quantity":0.11186562,"orderId":1},{"price":64221.4,"quantity":0.00811064,"orderId":1},{"price":64162.7,"quantity":0,"orderId":0}],"prevSeqId":31327886318,"currentSeqId":31327886334,"checksum":-1832156257}
{"action":"update","channel":"books","instrumentId":"BTC-USDT","instAsks":[{"price":64326,"quantity":0.0104896,"orderId":1},{"price":64335.4,"quantity":0,"orderId":0},{"price":64338.3,"quantity":0.05968139,"orderId":1},{"price":64338.9,"quantity":0.0166,"orderId":1},{"price":64340.1,"quantity":0.00775059,"orderId":1},{"price":64344,"quantity":0.00973533,"orderId":1},{"price":64344.3,"quantity":0.08700136,"orderId":1},{"price":64350.7,"quantity":0,"orderId":0},{"price":64351.1,"quantity":0.11521255,"orderId":1},{"price":64509.8,"quantity":0,"orderId":0},{"price":64510,"quantity":0,"orderId":0}],"instBids":[{"price":64307.3,"quantity":0.08953476,"orderId":1},{"price":64307,"quantity":0,"orderId":0},{"price":64300.6,"quantity":0.1139811,"orderId":1},{"price":64300.2,"quantity":0.086309,"orderId":1},{"price":64170.5,"quantity":0.00394407,"orderId":1},{"price":64158.3,"quantity":0,"orderId":0},{"price":64157.5,"quantity":0,"orderId":0}],"prevSeqId":31327886334,"currentSeqId":31327886348,"checksum":1766925659}
{"action":"update","channel":"books","instrumentId":"BTC-USDT","instAsks":[{"price":64338.9,"quantity":0.02435059,"orderId":2},{"price":64340.1,"quantity":0,"orderId":0},{"price":64509.8,"quantity":0.00034037,"orderId":1}],"instBids":[{"price":64315.6,"quantity":0.015,"orderId":1},{"price":64296.6,"quantity":0,"orderId":0},{"price":64293.9,"quantity":2.47604916,"orderId":1},{"price":64221.5,"quantity":0.3075999,"orderId":4},{"price":64221.3,"quantity":0,"orderId":0},{"price":64158.3,"quantity":0.00014683,"orderId":1}],"prevSeqId":31327886348,"currentSeqId":31327886359,"checksum":600633703}
{"action":"update","channel":"books","instrumentId":"BTC-USDT","instAsks":[{"price":64328,"quantity":0,"orderId":0},{"price":64338.9,"quantity":0.0166,"orderId":1},{"price":64340.1,"quantity":0.00775059,"orderId":1},{"price":64341.3,"quantity":0,"orderId":0},{"price":64343.5,"quantity":0.11186406,"orderId":1},{"price":64387.9,"quantity":0,"orderId":0},{"price":64510,"quantity":0.00101459,"orderId":2}],"instBids":[{"price":64307.4,"quantity":0.11186406,"orderId":1},{"price":64306.2,"quantity":0,"orderId":0},{"price":64296.1,"quantity":2.47604916,"orderId":1},{"price":64293.9,"quantity":0,"orderId":0}],"prevSeqId":31327886359,"currentSeqId":31327886379,"checksum":2032092441}
{"action":"update","channel":"books","instrumentId":"BTC-USDT","instAsks":[{"price":64342.2,"quantity":0.11186478,"orderId":1},{"price":64343.5,"quantity":0,"orderId":0},{"price":64450.5,"quantity":0,"orderId":0},{"price":64454.6,"quantity":0.01616125,"orderId":1}],"instBids":[{"price":64222.8,"quantity":0.0077854,"orderId":1},{"price":64218.9,"quantity":0,"orderId":0}],"prevSeqId":31327886379,"currentSeqId":31327886400,"checksum":1053959660}
{"action":"update","channel":"books","instrumentId":"BTC-USDT","instAsks":[{"price":64342.2,"quantity":0,"orderId":0},{"price":64343.5,"quantity":0.11186375,"orderId":1},{"price":64361.1,"quantity":0,"orderId":0},{"price":64362.5,"quantity":0.02329501,"orderId":1},{"price":64374.5,"quantity":0,"orderId":0},{"price":64392.2,"quantity":0.03493513,"orderId":1}],"instBids":[{"price":64307.4,"quantity":0.11186423,"orderId":1}],"prevSeqId":31327886400,"currentSeqId":31327886412,"checksum":2032092441}
{"action":"update","channel":"books","instrumentId":"BTC-USDT","instAsks":[{"price":64362.5,"quantity":0,"orderId":0},{"price":64375.6,"quantity":0.02329027,"orderId":1}],"instBids":[],"prevSeqId":31327886412,"currentSeqId":31327886416,"checksum":2032092441}
{"action":"update","channel":"books","instrumentId":"BTC-USDT","instAsks":[{"price":64353,"quantity":0.72496981,"orderId":1},{"price":64362.5,"quantity":0.02329501,"orderId":1},{"price":64367.6,"quantity":0,"orderId":0},{"price":64369.4,"quantity":2.32492019,"orderId":1},{"price":64375.6,"quantity":0,"orderId":0},{"price":64381.6,"quantity":0.09380461,"orderId":1},{"price":64409.4,"quantity":0.09381141,"orderId":1},{"price":64410.3,"quantity":0,"orderId":0},{"price":64411.6,"quantity":0.00776258,"orderId":1},{"price":64412,"quantity":0.01617194,"orderId":1},{"price":64433.6,"quantity":0.15600002,"orderId":1},{"price":64458.3,"quantity":0.00833218,"orderId":1},{"price":64458.6,"quantity":0.90000002,"orderId":1},{"price":64509.6,"quantity":0,"orderId":0},{"price":64509.7,"quantity":0,"orderId":0},{"price":64509.8,"quantity":0,"orderId":0},{"price":64510,"quantity":0,"orderId":0}],"instBids":[{"price":64259.1,"quantity":0.38001633,"orderId":1},{"price":64158.3,"quantity":0,"orderId":0}],"prevSeqId":31327886416,"currentSeqId":31327886434,"checksum":2032092441}
{"action":"update","channel":"books","instrumentId":"BTC-USDT","instAsks":[{"price":64324.1,"quantity":0,"orderId":0},{"price":64326,"quantity":0,"orderId":0},{"price":64326.5,"quantity":0,"orderId":0},{"price":64327.2,"quantity":0,"orderId":0},{"price":64330,"quantity":0,"orderId":0},{"price":64331.7,"quantity":0,"orderId":0},{"price":64331.8,"quantity":0.04484869,"orderId":1},{"price":64332.4,"quantity":0,"orderId":0},{"price":64334,"quantity":0.0808,"orderId":1},{"price":64338.3,"quantity":0,"orderId":0},{"price":64341.6,"quantity":0.60357939,"orderId":2},{"price":64342.3,"quantity":0,"orderId":0},{"price":64342.4,"quantity":0,"orderId":0},{"price":64343.5,"quantity":0,"orderId":0},{"price":64343.6,"quantity":0,"orderId":0},{"price":64344.1,"quantity":0.06711841,"orderId":1},{"price":64344.2,"quantity":0.11186392,"orderId":1},{"price":64344.3,"quantity":0,"orderId":0},{"price":64344.8,"quantity":0.27,"orderId":2},{"price":64346.5,"quantity":0.0975098,"orderId":1},{"price":64348.8,"quantity":0,"orderId":0},{"price":64349.7,"quantity":0,"orderId":0},{"price":64351.1,"quantity":0,"orderId":0},{"price":64353.1,"quantity":0,"orderId":0},{"price":64353.3,"quantity":0.1217446,"orderId":1},{"price":64354,"quantity":0,"orderId":0},{"price":64369.4,"quantity":0,"orderId":0},{"price":64369.5,"quantity":0.02718294,"orderId":1},{"price":64370.6,"quantity":0,"orderId":0},{"price":64376.6,"quantity":0.0136,"orderId":2},{"price":64378,"quantity":0.02953794,"orderId":1},{"price":64380.5,"quantity":0,"orderId":0},{"price":64393.8,"quantity":0.46612,"orderId":1},{"price":64410,"quantity":0,"orderId":0},{"price":64412.9,"quantity":0.01617171,"orderId":1},{"price":64414.9,"quantity":0.24838976,"orderId":1},{"price":64431.9,"quantity":0.03100226,"orderId":1},{"price":64434.2,"quantity":0.24840752,"orderId":2},{"price":64436.8,"quantity":0.01616572,"orderId":1},{"price":64474.5,"quantity":1.5619,"orderId":1},{"price":64477.4,"quantity":0.01617171,"orderId":1},{"price":64479.3,"quantity":0.24814198,"orderId":1},{"price":64483.4,"quantity":0,"orderId":0},{"price":64486.2,"quantity":0.0517424,"orderId":1},{"price":64492.2,"quantity":0.26,"orderId":1},{"price":64509.6,"quantity":0.0000314,"orderId":2},{"price":64509.7,"quantity":0.0000139,"orderId":1},{"price":64509.8,"quantity":0.00034037,"orderId":1},{"price":64510,"quantity":0.00101459,"orderId":2},{"price":64510.1,"quantity":0.00008038,"orderId":2},{"price":64510.2,"quantity":0.00018585,"orderId":4},{"price":64510.4,"quantity":0.00010027,"orderId":4},{"price":64511,"quantity":0.00026944,"orderId":2}],"instBids":[{"price":64331.7,"quantity":0.08968139,"orderId":3},{"price":64330.1,"quantity":0.5095,"orderId":4},{"price":64330,"quantity":0.9275418,"orderId":8},{"price":64328.6,"quantity":0.05866956,"orderId":1},{"price":64328,"quantity":0.0808,"orderId":1},{"price":64326,"quantity":0.0808,"orderId":1},{"price":64325.9,"quantity":0.07826,"orderId":3},{"price":64325.3,"quantity":0.00528259,"orderId":1},{"price":64324.2,"quantity":0.00138412,"orderId":1},{"price":64324.1,"quantity":0.22,"orderId":1},{"price":64324,"quantity":0.49967076,"orderId":8},{"price":64323.9,"quantity":0.0174,"orderId":1},{"price":64323.8,"quantity":0,"orderId":0},{"price":64323.5,"quantity":0.1497627,"orderId":1},{"price":64322.9,"quantity":0,"orderId":0},{"price":64322,"quantity":0.13971876,"orderId":3},{"price":64320.7,"quantity":0.000015,"orderId":1},{"price":64320.1,"quantity":0,"orderId":0},{"price":64318.1,"quantity":0.156341,"orderId":1},{"price":64318,"quantity":0.0808,"orderId":1},{"price":64317.8,"quantity":0.0005,"orderId":1},{"price":64317.5,"quantity":0,"orderId":0},{"price":64317.2,"quantity":0,"orderId":0},{"price":64311.4,"quantity":0,"orderId":0},{"price":64311.3,"quantity":0.156341,"orderId":1},{"price":64311.2,"quantity":0.46957212,"orderId":1},{"price":64311.1,"quantity":0.31090985,"orderId":2},{"price":64309.5,"quantity":0.09166195,"orderId":1},{"price":64308.4,"quantity":0,"orderId":0},{"price":64308,"quantity":0.00150967,"orderId":1},{"price":64307.9,"quantity":0.11187907,"orderId":2},{"price":64307.4,"quantity":0,"orderId":0},{"price":64307.3,"quantity":0,"orderId":0},{"price":64306,"quantity":0,"orderId":0},{"price":64302.8,"quantity":0.14208088,"orderId":2},{"price":64301.5,"quantity":0.311005,"orderId":2},{"price":64300.6,"quantity":0,"orderId":0},{"price":64299.3,"quantity":2.48954107,"orderId":1},{"price":64298.8,"quantity":0,"orderId":0},{"price":64297.6,"quantity":0,"orderId":0},{"price":64296.1,"quantity":0,"orderId":0},{"price":64289.4,"quantity":0,"orderId":0},{"price":64289.1,"quantity":0.0068,"orderId":1},{"price":64279.2,"quantity":0.90132005,"orderId":2},{"price":64278.7,"quantity":1.5347,"orderId":1},{"price":64278.1,"quantity":0,"orderId":0},{"price":64259.1,"quantity":0,"orderId":0},{"price":64253.4,"quantity":0,"orderId":0},{"price":64252.6,"quantity":0.04720913,"orderId":1},{"price":64245.5,"quantity":0,"orderId":0},{"price":64229.8,"quantity":0,"orderId":0},{"price":64224.4,"quantity":0.24912647,"orderId":1},{"price":64205.1,"quantity":0.27029899,"orderId":2},{"price":64177.5,"quantity":0,"orderId":0},{"price":64176.7,"quantity":0,"orderId":0},{"price":64176.1,"quantity":0.01694225,"orderId":5},{"price":64160,"quantity":0.25056929,"orderId":13},{"price":64158.3,"quantity":0.00014683,"orderId":1}],"prevSeqId":31327886434,"currentSeqId":31327886758,"checksum":1439463821}
{"action":"update","channel":"books","instrumentId":"BTC-USDT","instAsks":[{"price":64331.8,"quantity":0.40730052,"orderId":5},{"price":64333.4,"quantity":0,"orderId":0},{"price":64337.1,"quantity":0.01106532,"orderId":1},{"price":64340.2,"quantity":0,"orderId":0},{"price":64344.1,"quantity":0.15361028,"orderId":2},{"price":64346.5,"quantity":0,"orderId":0},{"price":64348.8,"quantity":0.08549363,"orderId":1},{"price":64350.5,"quantity":0.09984026,"orderId":1},{"price":64353.3,"quantity":0,"orderId":0},{"price":64357.3,"quantity":0.12016244,"orderId":1},{"price":64362.6,"quantity":0,"orderId":0},{"price":64368.1,"quantity":0.15528239,"orderId":1},{"price":64370.4,"quantity":0.0296,"orderId":1},{"price":64376.6,"quantity":2.33852019,"orderId":3},{"price":64478.8,"quantity":0,"orderId":0},{"price":64479.3,"quantity":0,"orderId":0},{"price":64492.3,"quantity":0.46612,"orderId":1}],"instBids":[{"price":64331.7,"quantity":0.34793755,"orderId":5},{"price":64330.1,"quantity":0,"orderId":0},{"price":64330,"quantity":0.3182,"orderId":3},{"price":64326.1,"quantity":0.00024264,"orderId":1},{"price":64325.8,"quantity":0.15538449,"orderId":1},{"price":64325.2,"quantity":0.43198424,"orderId":2},{"price":64324.2,"quantity":0,"orderId":0},{"price":64324.1,"quantity":0.22301825,"orderId":2},{"price":64323.5,"quantity":0,"orderId":0},{"price":64323.4,"quantity":0.00833802,"orderId":1},{"price":64319.7,"quantity":0.0151,"orderId":1},{"price":64319.1,"quantity":0.0005,"orderId":1},{"price":64319,"quantity":0.0005,"orderId":1},{"price":64318.1,"quantity":0,"orderId":0},{"price":64318,"quantity":0.16629363,"orderId":2},{"price":64317.9,"quantity":0,"orderId":0},{"price":64317.8,"quantity":0,"orderId":0},{"price":64315.6,"quantity":0,"orderId":0},{"price":64314,"quantity":0.12390974,"orderId":3},{"price":64313.5,"quantity":0.09900901,"orderId":1},{"price":64312.1,"quantity":0.0296,"orderId":1},{"price":64309.5,"quantity":0,"orderId":0},{"price":64306.8,"quantity":0.11509259,"orderId":1},{"price":64302.8,"quantity":0.0189,"orderId":2},{"price":64302.7,"quantity":0,"orderId":0},{"price":64301.8,"quantity":2.48954107,"orderId":1},{"price":64299.8,"quantity":0,"orderId":0},{"price":64299.3,"quantity":0,"orderId":0},{"price":64291.8,"quantity":0.02332063,"orderId":1},{"price":64289.1,"quantity":0,"orderId":0},{"price":64283.5,"quantity":0.0025672,"orderId":1},{"price":64278.8,"quantity":0,"orderId":0},{"price":64276.5,"quantity":0.0068,"orderId":1},{"price":64274.8,"quantity":0,"orderId":0},{"price":64270.7,"quantity":0.00255834,"orderId":1},{"price":64262.8,"quantity":0,"orderId":0},{"price":64254.2,"quantity":0.45287469,"orderId":1},{"price":64246.8,"quantity":0.03099662,"orderId":1},{"price":64245.1,"quantity":0.0068,"orderId":1},{"price":64233.6,"quantity":0.00809839,"orderId":1},{"price":64233.5,"quantity":0,"orderId":0},{"price":64222,"quantity":0.00153073,"orderId":1},{"price":64214.4,"quantity":0,"orderId":0},{"price":64162.2,"quantity":0.0161613,"orderId":1},{"price":64159.6,"quantity":0,"orderId":0},{"price":64159.1,"quantity":0,"orderId":0},{"price":64158.8,"quantity":0,"orderId":0},{"price":64158.3,"quantity":0,"orderId":0}],"prevSeqId":31327886758,"currentSeqId":31327886876,"checksum":-1727733174}
{"action":"update","channel":"books","instrumentId":"BTC-USDT","instAsks":[{"price":64340.1,"quantity":0,"orderId":0},{"price":64341.3,"quantity":0.00775059,"orderId":1},{"price":64341.7,"quantity":0.05485732,"orderId":1},{"price":64343.8,"quantity":0,"orderId":0},{"price":64349.5,"quantity":0.00466206,"orderId":3},{"price":64369.4,"quantity":2.32492019,"orderId":1},{"price":64376.6,"quantity":0,"orderId":0},{"price":64412.5,"quantity":0,"orderId":0},{"price":64414.9,"quantity":0.25615194,"orderId":2},{"price":64419.7,"quantity":0,"orderId":0},{"price":64422.7,"quantity":0,"orderId":0},{"price":64422.9,"quantity":0.12772768,"orderId":2},{"price":64426,"quantity":0.01618344,"orderId":2},{"price":64432.7,"quantity":0,"orderId":0},{"price":64497.2,"quantity":0.00001001,"orderId":1},{"price":64511.2,"quantity":0.00004022,"orderId":1},{"price":64511.6,"quantity":0.00016309,"orderId":4},{"price":64511.8,"quantity":0.00001059,"orderId":1}],"instBids":[{"price":64319.7,"quantity":0.0152,"orderId":1},{"price":64310.9,"quantity":0.26466485,"orderId":4},{"price":64305.2,"quantity":0,"orderId":0},{"price":64276.5,"quantity":0,"orderId":0},{"price":64274.5,"quantity":0.7,"orderId":1},{"price":64273,"quantity":0,"orderId":0},{"price":64272.9,"quantity":0,"orderId":0},{"price":64245.1,"quantity":0,"orderId":0},{"price":64237.4,"quantity":0.04890158,"orderId":2},{"price":64225.5,"quantity":0.06610269,"orderId":2},{"price":64222.8,"quantity":0,"orderId":0},{"price":64205.8,"quantity":0.00778746,"orderId":1},{"price":64204.6,"quantity":0,"orderId":0},{"price":64175.7,"quantity":0.00646768,"orderId":1},{"price":64173.1,"quantity":0,"orderId":0},{"price":64166.8,"quantity":0.05878526,"orderId":2},{"price":64159.6,"quantity":1.5,"orderId":1},{"price":64159.1,"quantity":0.00001007,"orderId":1},{"price":64158.8,"quantity":0.00031097,"orderId":2},{"price":64158.3,"quantity":0.00014683,"orderId":1},{"price":64157.5,"quantity":0.00013042,"orderId":3}],"prevSeqId":31327886876,"currentSeqId":31327886932,"checksum":-876998026}
{"action":"update","channel":"books","instrumentId":"BTC-USDT","instAsks":[{"price":64334.6,"quantity":0.00463156,"orderId":1},{"price":64381.9,"quantity":0.0068,"orderId":1},{"price":64423.9,"quantity":0.018,"orderId":1},{"price":64434.7,"quantity":0.01616624,"orderId":1},{"price":64499.2,"quantity":0.01616624,"orderId":1},{"price":64510.4,"quantity":0,"orderId":0},{"price":64511,"quantity":0,"orderId":0},{"price":64511.2,"quantity":0,"orderId":0},{"price":64511.6,"quantity":0,"orderId":0},{"price":64511.8,"quantity":0,"orderId":0}],"instBids":[{"price":64331.7,"quantity":0.36793028,"orderId":6},{"price":64330,"quantity":0.0982,"orderId":2},{"price":64326.2,"quantity":0.00033367,"orderId":1},{"price":64326.1,"quantity":0.22,"orderId":1},{"price":64324.1,"quantity":0.00301825,"orderId":1},{"price":64321.6,"quantity":0.143265,"orderId":1},{"price":64319.7,"quantity":0.0153,"orderId":1},{"price":64319.5,"quantity":0.0005,"orderId":1},{"price":64319.4,"quantity":0.0005,"orderId":1},{"price":64319.1,"quantity":0,"orderId":0},{"price":64319,"quantity":0,"orderId":0},{"price":64316.5,"quantity":0,"orderId":0},{"price":64228.2,"quantity":0.00194885,"orderId":1},{"price":64228.1,"quantity":0.156341,"orderId":1},{"price":64221.5,"quantity":0.30565081,"orderId":3},{"price":64170.7,"quantity":0.01617701,"orderId":2},{"price":64158.3,"quantity":0,"orderId":0},{"price":64157.5,"quantity":0,"orderId":0}],"prevSeqId":31327886932,"currentSeqId":31327886966,"checksum":-1175164967}
{"action":"update","channel":"books","instrumentId":"BTC-USDT","instAsks":[{"price":64334.6,"quantity":0,"orderId":0},{"price":64411.6,"quantity":0,"orderId":0},{"price":64413.6,"quantity":0.00776234,"orderId":1},{"price":64418,"quantity":0.33876,"orderId":1},{"price":64420.1,"quantity":0.00776155,"orderId":1}],"instBids":[{"price":64250.1,"quantity":0.01617217,"orderId":1},{"price":64247.5,"quantity":0,"orderId":0},{"price":64226,"quantity":0,"orderId":0},{"price":64158.3,"quantity":0.00014683,"orderId":1}],"prevSeqId":31327886966,"currentSeqId":31327886974,"checksum":-1215304446}
{"action":"update","channel":"books","instrumentId":"BTC-USDT","instAsks":[{"price":64331.8,"quantity":0.29008212,"orderId":5},{"price":64350.5,"quantity":0,"orderId":0},{"price":64350.6,"quantity":0.0949647,"orderId":1},{"price":64357.3,"quantity":0,"orderId":0},{"price":64357.4,"quantity":0.12220806,"orderId":1},{"price":64458,"quantity":0,"orderId":0},{"price":64482.8,"quantity":0.24812848,"orderId":1}],"instBids":[{"price":64324.1,"quantity":0.01135627,"orderId":2},{"price":64323.4,"quantity":0,"orderId":0},{"price":64319.7,"quantity":0.0149,"orderId":1},{"price":64313.5,"quantity":0,"orderId":0},{"price":64313.4,"quantity":0.0942168,"orderId":1},{"price":64306.8,"quantity":0,"orderId":0},{"price":64306.6,"quantity":0.10986034,"orderId":1},{"price":64243.6,"quantity":0.01617184,"orderId":1},{"price":64241.7,"quantity":0,"orderId":0},{"price":64157.5,"quantity":0.00013042,"orderId":3}],"prevSeqId":31327886974,"currentSeqId":31327886992,"checksum":558249749}
{"action":"update","channel":"books","instrumentId":"BTC-USDT","instAsks":[{"price":64331.8,"quantity":0.38354762,"orderId":6},{"price":64344,"quantity":0.12159778,"orderId":2},{"price":64344.2,"quantity":0,"orderId":0},{"price":64414.9,"quantity":0.24838976,"orderId":1},{"price":64416.1,"quantity":0.00776203,"orderId":1},{"price":64461.9,"quantity":0.01294047,"orderId":1},{"price":64510.2,"quantity":0,"orderId":0}],"instBids":[{"price":64320,"quantity":0.0813,"orderId":2},{"price":64319.9,"quantity":0.0005,"orderId":1},{"price":64319.7,"quantity":0.015,"orderId":1},{"price":64319.5,"quantity":0,"orderId":0},{"price":64319.4,"quantity":0,"orderId":0},{"price":64157.3,"quantity":0.00001832,"orderId":1}],"prevSeqId":31327886992,"currentSeqId":31327887010,"checksum":-1322581346}
{"action":"update","channel":"books","instrumentId":"BTC-USDT","instAsks":[{"price":64334.7,"quantity":0.00476816,"orderId":1},{"price":64344,"quantity":0.12159716,"orderId":2},{"price":64510.1,"quantity":0,"orderId":0}],"instBids":[{"price":64331.7,"quantity":0.34793755,"orderId":5},{"price":64326,"quantity":0.3008,"orderId":2},{"price":64319.7,"quantity":0.0151,"orderId":1},{"price":64228.2,"quantity":0.00756896,"orderId":2}],"prevSeqId":31327887010,"currentSeqId":31327887025,"checksum":2022097257}
{"action":"update","channel":"books","instrumentId":"BTC-USDT","instAsks":[{"price":64331.8,"quantity":0.29008212,"orderId":5},{"price":64342.5,"quantity":0.01460931,"orderId":1},{"price":64343.8,"quantity":0.04,"orderId":1},{"price":64344,"quantity":0.00973533,"orderId":1},{"price":64344.7,"quantity":0.11186121,"orderId":1},{"price":64369.4,"quantity":0,"orderId":0},{"price":64369.8,"quantity":2.28260966,"orderId":1},{"price":64509.8,"quantity":0,"orderId":0},{"price":64510,"quantity":0,"orderId":0}],"instBids":[{"price":64319.7,"quantity":0,"orderId":0},{"price":64319.6,"quantity":0.0152,"orderId":1},{"price":64306.8,"quantity":0.01,"orderId":1},{"price":64304.1,"quantity":0.01555109,"orderId":1},{"price":64303,"quantity":0,"orderId":0},{"price":64290.6,"quantity":0,"orderId":0},{"price":64229.1,"quantity":0.00194884,"orderId":1},{"price":64228.2,"quantity":0.00562011,"orderId":1},{"price":64157.3,"quantity":0,"orderId":0}],"prevSeqId":31327887025,"currentSeqId":31327887065,"checksum":-53221731}
{"action":"update","channel":"books","instrumentId":"BTC-USDT","instAsks":[{"price":64331.8,"quantity":0.34929246,"orderId":6},{"price":64363.7,"quantity":0.24980464,"orderId":1},{"price":64369.8,"quantity":0,"orderId":0},{"price":64369.9,"quantity":2.36034666,"orderId":2},{"price":64395.1,"quantity":1.09366573,"orderId":1},{"price":64509.7,"quantity":0,"orderId":0}],"instBids":[{"price":64320.1,"quantity":0.0005,"orderId":1},{"price":64319.9,"quantity":0,"orderId":0},{"price":64274.8,"quantity":0.42000003,"orderId":1},{"price":64157.5,"quantity":0,"orderId":0}],"prevSeqId":31327887065,"currentSeqId":31327887107,"checksum":-458922693}
{"action":"update","channel":"books","instrumentId":"BTC-USDT","instAsks":[{"price":64331.8,"quantity":0.30828258,"orderId":6},{"price":64369.4,"quantity":2.28260966,"orderId":1},{"price":64369.9,"quantity":0.077737,"orderId":1},{"price":64509.6,"quantity":0,"orderId":0}],"instBids":[{"price":64331.7,"quantity":0.32293755,"orderId":4},{"price":64320.1,"quantity":0,"orderId":0},{"price":64319.9,"quantity":0.0005,"orderId":1},{"price":64319.6,"quantity":0.0153,"orderId":1},{"price":64305,"quantity":0.01555088,"orderId":1},{"price":64304.1,"quantity":0,"orderId":0},{"price":64290.3,"quantity":0.04833455,"orderId":2},{"price":64286.7,"quantity":0,"orderId":0},{"price":64225.5,"quantity":0.05831762,"orderId":1},{"price":64224.8,"quantity":0.03778819,"orderId":2},{"price":64157.5,"quantity":0.00013042,"orderId":3}],"prevSeqId":31327887107,"currentSeqId":31327887122,"checksum":709712114}
{"action":"update","channel":"books","instrumentId":"BTC-USDT","instAsks":[{"price":64331.8,"quantity":0.38094742,"orderId":7}],"instBids":[{"price":64325.2,"quantity":0.17198424,"orderId":1},{"price":64324,"quantity":0.46374734,"orderId":7},{"price":64320.1,"quantity":0.0005,"orderId":1},{"price":64319.9,"quantity":0,"orderId":0},{"price":64205.8,"quantity":0,"orderId":0},{"price":64204.6,"quantity":0.0077876,"orderId":1}],"prevSeqId":31327887122,"currentSeqId":31327887156,"checksum":-1564501308}
{"action":"update","channel":"books","instrumentId":"BTC-USDT","instAsks":[{"price":64419.7,"quantity":0.00776161,"orderId":1},{"price":64420.1,"quantity":0,"orderId":0}],"instBids":[{"price":64320.1,"quantity":0,"orderId":0},{"price":64319.9,"quantity":0.0005,"orderId":1},{"price":64319.6,"quantity":0.0154,"orderId":1}],"prevSeqId":31327887156,"currentSeqId":31327887165,"checksum":-1341581751}
{"action":"update","channel":"books","instrumentId":"BTC-USDT","instAsks":[{"price":64331.8,"quantity":0.60123625,"orderId":9},{"price":64338.2,"quantity":0.156,"orderId":1},{"price":64338.3,"quantity":0.26,"orderId":1},{"price":64338.8,"quantity":0.05968139,"orderId":1},{"price":64341.3,"quantity":0.11961547,"orderId":2},{"price":64341.6,"quantity":0.543898,"orderId":1},{"price":64344.7,"quantity":0,"orderId":0},{"price":64350.2,"quantity":0.12505371,"orderId":2},{"price":64350.6,"quantity":0,"orderId":0},{"price":64353.6,"quantity":0.08212495,"orderId":2},{"price":64356.9,"quantity":0.03469077,"orderId":1},{"price":64357,"quantity":0.12189295,"orderId":1},{"price":64357.3,"quantity":0.00528259,"orderId":1},{"price":64357.4,"quantity":0,"orderId":0},{"price":64369.4,"quantity":0,"orderId":0},{"price":64371.4,"quantity":2.28260966,"orderId":1},{"price":64393.4,"quantity":0.46612,"orderId":1},{"price":64414.9,"quantity":0,"orderId":0},{"price":64434.2,"quantity":0.00009215,"orderId":1},{"price":64482.8,"quantity":0,"orderId":0},{"price":64509.2,"quantity":0,"orderId":0},{"price":64509.4,"quantity":0,"orderId":0}],"instBids":[{"price":64331.7,"quantity":0.11465616,"orderId":1},{"price":64330,"quantity":0,"orderId":0},{"price":64328.6,"quantity":0,"orderId":0},{"price":64326.2,"quantity":0,"orderId":0},{"price":64326.1,"quantity":0,"orderId":0},{"price":64326,"quantity":0.0808,"orderId":1},{"price":64325.9,"quantity":0.0224,"orderId":2},{"price":64325.3,"quantity":0,"orderId":0},{"price":64324.1,"quantity":0.00301825,"orderId":1},{"price":64324,"quantity":0.18375461,"orderId":5},{"price":64322,"quantity":0.14500135,"orderId":4},{"price":64320.7,"quantity":0,"orderId":0},{"price":64320.1,"quantity":0.0005,"orderId":1},{"price":64319.9,"quantity":0,"orderId":0},{"price":64318.1,"quantity":0.00038208,"orderId":1},{"price":64313.4,"quantity":0,"orderId":0},{"price":64313,"quantity":0.12519597,"orderId":2},{"price":64311.1,"quantity":0.15541985,"orderId":1},{"price":64310.1,"quantity":0.15549,"orderId":1},{"price":64307.9,"quantity":0.00001501,"orderId":1},{"price":64306.6,"quantity":0,"orderId":0},{"price":64306.2,"quantity":0.23282079,"orderId":2},{"price":64301.8,"quantity":0,"orderId":0},{"price":64301.5,"quantity":0.000015,"orderId":1},{"price":64300.7,"quantity":0.0174,"orderId":1},{"price":64300.5,"quantity":0.31099,"orderId":1},{"price":64296.8,"quantity":2.48425563,"orderId":1},{"price":64259,"quantity":0,"orderId":0},{"price":64224.4,"quantity":0,"orderId":0},{"price":64205.1,"quantity":0.02109765,"orderId":1},{"price":64160,"quantity":0.00119308,"orderId":12},{"price":64157.3,"quantity":0.00001832,"orderId":1},{"price":64157.1,"quantity":0.00020869,"orderId":1},{"price":64156.8,"quantity":0.00122821,"orderId":1},{"price":64155.9,"quantity":0.000015,"orderId":1},{"price":64155.4,"quantity":0.00002122,"orderId":1},{"price":64155.2,"quantity":0.0077936,"orderId":1}],"prevSeqId":31327887165,"currentSeqId":31327887237,"checksum":-1246850445}
{"action":"update","channel":"books","instrumentId":"BTC-USDT","instAsks":[{"price":64331.8,"quantity":0.68023625,"orderId":10},{"price":64350.2,"quantity":0.03188352,"orderId":1},{"price":64357,"quantity":0,"orderId":0},{"price":64369.5,"quantity":2.3097926,"orderId":2},{"price":64371.4,"quantity":0,"orderId":0},{"price":64371.5,"quantity":0,"orderId":0},{"price":64393.4,"quantity":0,"orderId":0},{"price":64418.4,"quantity":0.24837624,"orderId":1},{"price":64437.6,"quantity":0.14898113,"orderId":1},{"price":64437.7,"quantity":0.24830186,"orderId":1},{"price":64473.7,"quantity":0,"orderId":0},{"price":64475.6,"quantity":0.01617217,"orderId":1},{"price":64482.8,"quantity":0.24812848,"orderId":1},{"price":64497.9,"quantity":0.00001933,"orderId":1},{"price":64509.2,"quantity":0.00006054,"orderId":3}],"instBids":[{"price":64329.6,"quantity":0.05968139,"orderId":1},{"price":64320.7,"quantity":0.000015,"orderId":1},{"price":64320.1,"quantity":0,"orderId":0},{"price":64320,"quantity":0.0808,"orderId":1},{"price":64319.9,"quantity":0.0005,"orderId":1},{"price":64319.8,"quantity":0.0005,"orderId":1},{"price":64319.7,"quantity":0.00833802,"orderId":1},{"price":64319.6,"quantity":0.0153,"orderId":1},{"price":64318.7,"quantity":0.26,"orderId":1},{"price":64318.3,"quantity":0,"orderId":0},{"price":64318.1,"quantity":0,"orderId":0},{"price":64317.4,"quantity":0.0174,"orderId":1},{"price":64313,"quantity":0.0316517,"orderId":1},{"price":64306.2,"quantity":0,"orderId":0},{"price":64305.1,"quantity":0.11186823,"orderId":1},{"price":64279.3,"quantity":0.70072713,"orderId":2},{"price":64274.8,"quantity":0,"orderId":0},{"price":64274.5,"quantity":0,"orderId":0},{"price":64254.3,"quantity":0.073081,"orderId":1},{"price":64227.9,"quantity":0.24911291,"orderId":1},{"price":64208.6,"quantity":0.24918778,"orderId":1},{"price":64163.5,"quantity":0.61128264,"orderId":2},{"price":64156.8,"quantity":0,"orderId":0},{"price":64155.9,"quantity":0,"orderId":0},{"price":64155.4,"quantity":0,"orderId":0},{"price":64155.2,"quantity":0,"orderId":0}],"prevSeqId":31327887237,"currentSeqId":31327887302,"checksum":1742154475}
{"action":"update","channel":"books","instrumentId":"BTC-USDT","instAsks":[{"price":64331.8,"quantity":0.60123625,"orderId":9},{"price":64350.4,"quantity":0.09116696,"orderId":1},{"price":64357.2,"quantity":0.13811635,"orderId":2},{"price":64437.6,"quantity":0,"orderId":0},{"price":64437.7,"quantity":0,"orderId":0},{"price":64482.8,"quantity":0,"orderId":0},{"price":64499.8,"quantity":0.06281475,"orderId":2},{"price":64509.4,"quantity":0.00528449,"orderId":1},{"price":64509.6,"quantity":0.0000314,"orderId":2}],"instBids":[{"price":64330,"quantity":0.0808,"orderId":1},{"price":64320.4,"quantity":0.00833802,"orderId":1},{"price":64319.7,"quantity":0,"orderId":0},{"price":64313.2,"quantity":0.09651873,"orderId":2},{"price":64311.1,"quantity":0.31090985,"orderId":2},{"price":64310.1,"quantity":0,"orderId":0},{"price":64306.4,"quantity":0.1127828,"orderId":1},{"price":64301.5,"quantity":0.311005,"orderId":2},{"price":64300.5,"quantity":0,"orderId":0}],"prevSeqId":31327887302,"currentSeqId":31327887335,"checksum":679248544}
{"action":"update","channel":"books","instrumentId":"BTC-USDT","instAsks":[{"price":64331.8,"quantity":0.43680742,"orderId":8},{"price":64350.4,"quantity":0,"orderId":0},{"price":64357.2,"quantity":0.02033272,"orderId":1},{"price":64509.7,"quantity":0.0000139,"orderId":1}],"instBids":[{"price":64313.2,"quantity":0.007774,"orderId":1},{"price":64306.4,"quantity":0,"orderId":0},{"price":64306.2,"quantity":0.11186747,"orderId":1},{"price":64306,"quantity":0.0015,"orderId":1},{"price":64305.1,"quantity":0,"orderId":0},{"price":64303.4,"quantity":1.22087953,"orderId":1},{"price":64302.8,"quantity":0.0174,"orderId":1},{"price":64261.7,"quantity":1.83450904,"orderId":2},{"price":64157.1,"quantity":0,"orderId":0}],"prevSeqId":31327887335,"currentSeqId":31327887349,"checksum":189264844}
{"action":"update","channel":"books","instrumentId":"BTC-USDT","instAsks":[{"price":64350.4,"quantity":0.09171721,"orderId":1},{"price":64357.2,"quantity":0.14313585,"orderId":2},{"price":64484.2,"quantity":0,"orderId":0},{"price":64486.1,"quantity":0.00646781,"orderId":1},{"price":64486.6,"quantity":0,"orderId":0},{"price":64489.8,"quantity":0.0161686,"orderId":1},{"price":64509.7,"quantity":0,"orderId":0}],"instBids":[{"price":64320.5,"quantity":0.0005,"orderId":1},{"price":64320.4,"quantity":0.00883802,"orderId":2},{"price":64319.9,"quantity":0,"orderId":0},{"price":64319.8,"quantity":0,"orderId":0},{"price":64319.6,"quantity":0.0154,"orderId":1},{"price":64313.2,"quantity":0.09814666,"orderId":2},{"price":64306.4,"quantity":0.11448595,"orderId":1}],"prevSeqId":31327887349,"currentSeqId":31327887364,"checksum":-669166089}
{"action":"update","channel":"books","instrumentId":"BTC-USDT","instAsks":[{"price":64338.2,"quantity":0,"orderId":0},{"price":64338.3,"quantity":0,"orderId":0},{"price":64341.3,"quantity":0.00775059,"orderId":1},{"price":64343.7,"quantity":0.11186429,"orderId":1},{"price":64350.4,"quantity":0,"orderId":0},{"price":64350.5,"quantity":0.08820309,"orderId":1},{"price":64357.2,"quantity":0.02033272,"orderId":1},{"price":64357.3,"quantity":0.12543697,"orderId":2},{"price":64509.7,"quantity":0.0000139,"orderId":1}],"instBids":[{"price":64331.7,"quantity":0.13205616,"orderId":2},{"price":64321.1,"quantity":0.00833802,"orderId":1},{"price":64320.4,"quantity":0.0005,"orderId":1},{"price":64313.3,"quantity":0.09744468,"orderId":1},{"price":64313.2,"quantity":0.007774,"orderId":1},{"price":64307.9,"quantity":0.1118793,"orderId":2},{"price":64306.5,"quantity":0.11901508,"orderId":1},{"price":64306.4,"quantity":0,"orderId":0},{"price":64306.2,"quantity":0,"orderId":0},{"price":64157.3,"quantity":0,"orderId":0}],"prevSeqId":31327887364,"currentSeqId":31327887386,"checksum":-1693065220}
{"action":"update","channel":"books","instrumentId":"BTC-USDT","instAsks":[{"price":64341.3,"quantity":0.11961529,"orderId":2},{"price":64343.7,"quantity":0,"orderId":0},{"price":64350.5,"quantity":0.09508598,"orderId":1},{"price":64350.7,"quantity":0.15690004,"orderId":1},{"price":64357.3,"quantity":0.13022436,"orderId":2},{"price":64369.3,"quantity":2.28260966,"orderId":1},{"price":64369.5,"quantity":0.02718294,"orderId":1},{"price":64437.7,"quantity":0.24830186,"orderId":1},{"price":64458.6,"quantity":0.40457238,"orderId":1},{"price":64482.8,"quantity":0.24812848,"orderId":1},{"price":64509.4,"quantity":0,"orderId":0},{"price":64509.6,"quantity":0,"orderId":0},{"price":64509.7,"quantity":0,"orderId":0}],"instBids":[{"price":64331.5,"quantity":0.01554634,"orderId":1},{"price":64319.6,"quantity":0.0155,"orderId":1},{"price":64313.3,"quantity":0.0972292,"orderId":1},{"price":64311.2,"quantity":0.62506212,"orderId":2},{"price":64311.1,"quantity":0.15541985,"orderId":1},{"price":64307.9,"quantity":0.11187957,"orderId":2},{"price":64306.5,"quantity":0.11880596,"orderId":1},{"price":64301.6,"quantity":0.31099,"orderId":1},{"price":64301.5,"quantity":0.000015,"orderId":1},{"price":64272.8,"quantity":0.2817433,"orderId":1},{"price":64158.8,"quantity":0,"orderId":0},{"price":64158.3,"quantity":0,"orderId":0},{"price":64157.5,"quantity":0,"orderId":0}],"prevSeqId":31327887386,"currentSeqId":31327887466,"checksum":-1460010366}
{"action":"update","channel":"books","instrumentId":"BTC-USDT","instAsks":[{"price":64341.3,"quantity":0.11961528,"orderId":2},{"price":64350.5,"quantity":0,"orderId":0},{"price":64350.6,"quantity":0.0990248,"orderId":1},{"price":64357.3,"quantity":0.00528259,"orderId":1},{"price":64357.4,"quantity":0.11554592,"orderId":1},{"price":64394.9,"quantity":0,"orderId":0},{"price":64396.2,"quantity":1.21152073,"orderId":2},{"price":64409.8,"quantity":0.10194037,"orderId":2},{"price":64416.1,"quantity":0,"orderId":0},{"price":64482.8,"quantity":0,"orderId":0},{"price":64509.4,"quantity":0.00528449,"orderId":1},{"price":64509.6,"quantity":0.0000314,"orderId":2}],"instBids":[{"price":64320.5,"quantity":0,"orderId":0},{"price":64320.3,"quantity":0.0005,"orderId":1},{"price":64313.4,"quantity":0.09831033,"orderId":1},{"price":64313.3,"quantity":0,"orderId":0},{"price":64307.9,"quantity":0.00001501,"orderId":1},{"price":64306.7,"quantity":0.11186488,"orderId":1},{"price":64306.6,"quantity":0.1248183,"orderId":1},{"price":64306.5,"quantity":0,"orderId":0},{"price":64224.8,"quantity":0.03000303,"orderId":1},{"price":64223.3,"quantity":0.06778538,"orderId":3},{"price":64159.1,"quantity":0,"orderId":0}],"prevSeqId":31327887466,"currentSeqId":31327887608,"checksum":-1452221853}
{"action":"update","channel":"books","instrumentId":"BTC-USDT","instAsks":[{"price":64341.2,"quantity":0.00018275,"orderId":1},{"price":64350.5,"quantity":0.09632413,"orderId":1},{"price":64350.6,"quantity":0,"orderId":0},{"price":64357.3,"quantity":0.12734742,"orderId":2},{"price":64357.4,"quantity":0,"orderId":0}],"instBids":[{"price":64331.7,"quantity":0.11465616,"orderId":1},{"price":64326.1,"quantity":0.18,"orderId":1},{"price":64320.4,"quantity":0,"orderId":0},{"price":64320.2,"quantity":0.0005,"orderId":1},{"price":64313.4,"quantity":0,"orderId":0},{"price":64313.3,"quantity":0.09431984,"orderId":1},{"price":64306.6,"quantity":0,"orderId":0},{"price":64306.5,"quantity":0.115193,"orderId":1},{"price":64228.2,"quantity":0,"orderId":0}],"prevSeqId":31327887608,"currentSeqId":31327887628,"checksum":1227410232}
{"action":"update","channel":"books","instrumentId":"BTC-USDT","instAsks":[{"price":64341.1,"quantity":0.00775059,"orderId":1},{"price":64341.2,"quantity":0,"orderId":0},{"price":64341.3,"quantity":0,"orderId":0},{"price":64342.4,"quantity":0.11186493,"orderId":1}],"instBids":[{"price":64320.4,"quantity":0.0005,"orderId":1},{"price":64320.2,"quantity":0,"orderId":0},{"price":64306.7,"quantity":0,"orderId":0},{"price":64306.6,"quantity":0.11186493,"orderId":1}],"prevSeqId":31327887628,"currentSeqId":31327887665,"checksum":1200708041}
{"action":"update","channel":"books","instrumentId":"BTC-USDT","instAsks":[{"price":64341.1,"quantity":0,"orderId":0},{"price":64341.3,"quantity":0.00775059,"orderId":1},{"price":64415,"quantity":0.03007519,"orderId":2}],"instBids":[{"price":64326.1,"quantity":0,"orderId":0},{"price":64318.1,"quantity":0.00471221,"orderId":1},{"price":64296.8,"quantity":0,"orderId":0},{"price":64293.9,"quantity":2.45370495,"orderId":1}],"prevSeqId":31327887665,"currentSeqId":31327887680,"checksum":-342561254}
{"action":"update","channel":"books","instrumentId":"BTC-USDT","instAsks":[{"price":64362.5,"quantity":0,"orderId":0},{"price":64377.7,"quantity":0.02328951,"orderId":1}],"instBids":[{"price":64320.5,"quantity":0.0005,"orderId":1},{"price":64320.3,"quantity":0,"orderId":0},{"price":64319.6,"quantity":0.0156,"orderId":1},{"price":64296.8,"quantity":2.45370495,"orderId":1},{"price":64293.9,"quantity":0,"orderId":0},{"price":64227.4,"quantity":0.00562018,"orderId":1},{"price":64159.6,"quantity":0,"orderId":0}],"prevSeqId":31327887680,"currentSeqId":31327887689,"checksum":-1626655433}
{"action":"update","channel":"books","instrumentId":"BTC-USDT","instAsks":[{"price":64363.7,"quantity":0.27309921,"orderId":2},{"price":64377.7,"quantity":0,"orderId":0},{"price":64509.7,"quantity":0.0000139,"orderId":1}],"instBids":[],"prevSeqId":31327887689,"currentSeqId":31327887719,"checksum":-1626655433}
{"action":"update","channel":"books","instrumentId":"BTC-USDT","instAsks":[{"price":64341.3,"quantity":0.11961572,"orderId":2},{"price":64342.4,"quantity":0,"orderId":0},{"price":64350.5,"quantity":0,"orderId":0},{"price":64350.6,"quantity":0.09885352,"orderId":1},{"price":64357.3,"quantity":0.00528259,"orderId":1},{"price":64357.4,"quantity":0.118299,"orderId":1},{"price":64389.5,"quantity":0,"orderId":0},{"price":64392.8,"quantity":0.01348064,"orderId":1},{"price":64407.7,"quantity":0.03876454,"orderId":2},{"price":64409.8,"quantity":0.09417758,"orderId":1},{"price":64453.9,"quantity":0,"orderId":0},{"price":64457.2,"quantity":0.01348064,"orderId":1}],"instBids":[{"price":64331.7,"quantity":0.13205616,"orderId":2},{"price":64322,"quantity":0.15333937,"orderId":5},{"price":64321.1,"quantity":0,"orderId":0},{"price":64320.5,"quantity":0,"orderId":0},{"price":64320.3,"quantity":0.0005,"orderId":1},{"price":64313.4,"quantity":0.0881573,"orderId":1},{"price":64313.3,"quantity":0,"orderId":0},{"price":64306.7,"quantity":0.11186513,"orderId":1},{"price":64306.6,"quantity":0.11368298,"orderId":1},{"price":64306.5,"quantity":0,"orderId":0},{"price":64249.7,"quantity":0.16982164,"orderId":2},{"price":64248.4,"quantity":0.07491349,"orderId":1},{"price":64185.4,"quantity":0.01656172,"orderId":2},{"price":64184.1,"quantity":0,"orderId":0},{"price":64159.6,"quantity":1.5,"orderId":1},{"price":64159.1,"quantity":0.00001007,"orderId":1}],"prevSeqId":31327887719,"currentSeqId":31327887755,"checksum":-1489131496}
{"action":"update","channel":"books","instrumentId":"BTC-USDT","instAsks":[{"price":64341.3,"quantity":0.00775059,"orderId":1},{"price":64342.4,"quantity":0.11186456,"orderId":1},{"price":64418.4,"quantity":0,"orderId":0},{"price":64437.7,"quantity":0,"orderId":0},{"price":64509.8,"quantity":0.00034037,"orderId":1}],"instBids":[{"price":64326.1,"quantity":0.18,"orderId":1},{"price":64307.9,"quantity":0.11187957,"orderId":2},{"price":64306.7,"quantity":0,"orderId":0},{"price":64251.3,"quantity":0.00308096,"orderId":1},{"price":64244.4,"quantity":0,"orderId":0},{"price":64227.9,"quantity":0,"orderId":0},{"price":64208.6,"quantity":0,"orderId":0},{"price":64163.5,"quantity":0.36192,"orderId":1},{"price":64158.8,"quantity":0.00031097,"orderId":2},{"price":64158.3,"quantity":0.00014683,"orderId":1}],"prevSeqId":31327887755,"currentSeqId":31327887778,"checksum":-1566950743}
{"action":"update","channel":"books","instrumentId":"BTC-USDT","instAsks":[{"price":64331.8,"quantity":0.48368718,"orderId":8},{"price":64342.4,"quantity":0,"orderId":0},{"price":64344.7,"quantity":0.1118615,"orderId":1},{"price":64369.3,"quantity":0,"orderId":0},{"price":64371.5,"quantity":2.25904713,"orderId":1}],"instBids":[{"price":64331.7,"quantity":0.26765616,"orderId":3},{"price":64323.8,"quantity":0.00833802,"orderId":1},{"price":64322,"quantity":0.14500135,"orderId":4},{"price":64320.5,"quantity":0.0005,"orderId":1},{"price":64320.3,"quantity":0,"orderId":0},{"price":64307.9,"quantity":0.11187944,"orderId":2},{"price":64158.3,"quantity":0,"orderId":0}],"prevSeqId":31327887778,"currentSeqId":31327887807,"checksum":795277992}
{"action":"update","channel":"books","instrumentId":"BTC-USDT","instAsks":[{"price":64343.7,"quantity":0.11186224,"orderId":1},{"price":64344.7,"quantity":0,"orderId":0},{"price":64369.8,"quantity":2.24707118,"orderId":1},{"price":64371.5,"quantity":0,"orderId":0},{"price":64438.3,"quantity":0.09380469,"orderId":1},{"price":64458.6,"quantity":0.84942845,"orderId":2},{"price":64509.8,"quantity":0,"orderId":0}],"instBids":[{"price":64323.8,"quantity":0,"orderId":0},{"price":64323,"quantity":0.00833802,"orderId":1},{"price":64307.9,"quantity":0.11187614,"orderId":2},{"price":64223.3,"quantity":0.06000004,"orderId":2},{"price":64222.8,"quantity":0.0077854,"orderId":1},{"price":64158.8,"quantity":0,"orderId":0}],"prevSeqId":31327887807,"currentSeqId":31327887834,"checksum":1894554685}
{"action":"update","channel":"books","instrumentId":"BTC-USDT","instAsks":[{"price":64331.8,"quantity":0.57604599,"orderId":9},{"price":64334.7,"quantity":0,"orderId":0},{"price":64343.7,"quantity":0,"orderId":0},{"price":64344.7,"quantity":0.11186175,"orderId":1},{"price":64360.8,"quantity":1.24,"orderId":1},{"price":64363.7,"quantity":0.02329457,"orderId":1},{"price":64369.8,"quantity":0,"orderId":0},{"price":64370.3,"quantity":2.53660824,"orderId":3},{"price":64418.4,"quantity":0.24837624,"orderId":1},{"price":64437.7,"quantity":0.24830186,"orderId":1},{"price":64482.8,"quantity":0.24812848,"orderId":1},{"price":64509.6,"quantity":0,"orderId":0},{"price":64509.7,"quantity":0,"orderId":0}],"instBids":[{"price":64320.6,"quantity":0.0005,"orderId":1},{"price":64320.4,"quantity":0,"orderId":0},{"price":64306,"quantity":0,"orderId":0},{"price":64298.3,"quantity":2.42728105,"orderId":1},{"price":64296.8,"quantity":0,"orderId":0},{"price":64253.1,"quantity":0.02126684,"orderId":2},{"price":64251.9,"quantity":0.04666185,"orderId":2},{"price":64244.1,"quantity":0.05174224,"orderId":1},{"price":64242.8,"quantity":0.02953706,"orderId":1},{"price":64227.9,"quantity":0.24911291,"orderId":1},{"price":64208.6,"quantity":0.24918778,"orderId":1},{"price":64188.8,"quantity":0.03387201,"orderId":2},{"price":64187.6,"quantity":0,"orderId":0},{"price":64163.5,"quantity":0.61128264,"orderId":2},{"price":64159.1,"quantity":0,"orderId":0}],"prevSeqId":31327887834,"currentSeqId":31327887865,"checksum":551513853}
