{"action":"update","channel":"books","instrumentId":"BTC-USDT","instAsks":[{"price":64437.7,"quantity":0,"orderId":0},{"price":64482.8,"quantity":0,"orderId":0},{"price":64509.6,"quantity":0.0000314,"orderId":2},{"price":64509.7,"quantity":0.0000139,"orderId":1}],"instBids":[{"price":64331.7,"quantity":0.13205616,"orderId":2},{"price":64306,"quantity":0.0015,"orderId":1},{"price":64298.3,"quantity":0,"orderId":0},{"price":64296.8,"quantity":2.42728105,"orderId":1},{"price":64225.8,"quantity":0.01616115,"orderId":1},{"price":64223.2,"quantity":0.03000303,"orderId":1},{"price":64159.9,"quantity":0,"orderId":0},{"price":64159.6,"quantity":0,"orderId":0}],"prevSeqId":31327887865,"currentSeqId":31327887874,"checksum":-1319481646}
{"action":"update","channel":"books","instrumentId":"BTC-USDT","instAsks":[],"instBids":[{"price":64240,"quantity":0.00646768,"orderId":1},{"price":64236.8,"quantity":0,"orderId":0},{"price":64236.6,"quantity":0.01616843,"orderId":1},{"price":64233.4,"quantity":0.01,"orderId":1},{"price":64231.1,"quantity":0.00001501,"orderId":1},{"price":64172.3,"quantity":0.01616843,"orderId":1},{"price":64169.1,"quantity":0,"orderId":0},{"price":64160,"quantity":0,"orderId":0}],"prevSeqId":31327887874,"currentSeqId":31327887884,"checksum":-1319481646}
{"action":"update","channel":"books","instrumentId":"BTC-USDT","instAsks":[{"price":64331.8,"quantity":0.36414258,"orderId":7},{"price":64343.7,"quantity":0.11186457,"orderId":1},{"price":64344.7,"quantity":0,"orderId":0},{"price":64370.3,"quantity":0.28953706,"orderId":2},{"price":64372.4,"quantity":2.24707118,"orderId":1},{"price":64418.4,"quantity":0,"orderId":0}],"instBids":[{"price":64329.6,"quantity":0,"orderId":0},{"price":64326.1,"quantity":0,"orderId":0},{"price":64324.1,"quantity":0.22301825,"orderId":2},{"price":64323,"quantity":0,"orderId":0},{"price":64322.1,"quantity":0.00833802,"orderId":1},{"price":64307.9,"quantity":0.11187958,"orderId":2},{"price":64233.1,"quantity":0.04616622,"orderId":2},{"price":64227.9,"quantity":0,"orderId":0},{"price":64208.6,"quantity":0,"orderId":0},{"price":64163.5,"quantity":0.36192,"orderId":1},{"price":64160,"quantity":0.00119308,"orderId":12},{"price":64159.9,"quantity":0.01564601,"orderId":2},{"price":64159.6,"quantity":1.5,"orderId":1},{"price":64159.1,"quantity":0.00001007,"orderId":1}],"prevSeqId":31327887884,"currentSeqId":31327887912,"checksum":1884300438}
{"action":"update","channel":"books","instrumentId":"BTC-USDT","instAsks":[{"price":64331.8,"quantity":0.60650321,"orderId":8},{"price":64350.5,"quantity":0.09007156,"orderId":1},{"price":64350.6,"quantity":0,"orderId":0},{"price":64357.3,"quantity":0.11442496,"orderId":2},{"price":64357.4,"quantity":0,"orderId":0},{"price":64370.3,"quantity":2.53660824,"orderId":3},{"price":64372.4,"quantity":0,"orderId":0},{"price":64429.6,"quantity":0.46957212,"orderId":1},{"price":64509.8,"quantity":0.00034037,"orderId":1},{"price":64510,"quantity":0.00101459,"orderId":2}],"instBids":[{"price":64331.7,"quantity":0.11465616,"orderId":1},{"price":64320.7,"quantity":0.000515,"orderId":2},{"price":64320.5,"quantity":0,"orderId":0},{"price":64319.6,"quantity":0.0157,"orderId":1},{"price":64313.4,"quantity":0,"orderId":0},{"price":64313.3,"quantity":0.09405804,"orderId":1},{"price":64306.6,"quantity":0,"orderId":0},{"price":64306.5,"quantity":0.11416169,"orderId":1},{"price":64222.2,"quantity":0.04616567,"orderId":2},{"price":64219.6,"quantity":0,"orderId":0},{"price":64184.5,"quantity":0.01617207,"orderId":1},{"price":64182.6,"quantity":0,"orderId":0},{"price":64158.8,"quantity":0.00031097,"orderId":2},{"price":64158.3,"quantity":0.00014683,"orderId":1}],"prevSeqId":31327887912,"currentSeqId":31327887936,"checksum":-1750925167}
{"action":"update","channel":"books","instrumentId":"BTC-USDT","instAsks":[],"instBids":[{"price":64329.4,"quantity":0.05968139,"orderId":1},{"price":64320.7,"quantity":0.000015,"orderId":1},{"price":64320.5,"quantity":0.0005,"orderId":1},{"price":64319.6,"quantity":0.0156,"orderId":1},{"price":64158.8,"quantity":0,"orderId":0},{"price":64158.3,"quantity":0,"orderId":0}],"prevSeqId":31327887936,"currentSeqId":31327887940,"checksum":-1784568742}
{"action":"update","channel":"books","instrumentId":"BTC-USDT","instAsks":[{"price":64353,"quantity":0,"orderId":0},{"price":64353.4,"quantity":0,"orderId":0},{"price":64395.1,"quantity":0.72691247,"orderId":1},{"price":64395.3,"quantity":0,"orderId":0},{"price":64510.1,"quantity":0.00008038,"orderId":2},{"price":64510.2,"quantity":0.00018585,"orderId":4},{"price":64510.4,"quantity":0.00010027,"orderId":4}],"instBids":[{"price":64320.7,"quantity":0.000515,"orderId":2},{"price":64320.5,"quantity":0,"orderId":0},{"price":64306,"quantity":0,"orderId":0},{"price":64303.4,"quantity":0,"orderId":0},{"price":64302.8,"quantity":0.0189,"orderId":2},{"price":64298.3,"quantity":2.42728105,"orderId":1},{"price":64296.8,"quantity":0,"orderId":0},{"price":64261.7,"quantity":0.001,"orderId":1},{"price":64158.8,"quantity":0.00031097,"orderId":2},{"price":64158.3,"quantity":0.00014683,"orderId":1},{"price":64157.5,"quantity":0.00013042,"orderId":3}],"prevSeqId":31327887940,"currentSeqId":31327887954,"checksum":-704512226}
{"action":"update","channel":"books","instrumentId":"BTC-USDT","instAsks":[{"price":64331.8,"quantity":0.38567111,"orderId":8},{"price":64335,"quantity":0.00473785,"orderId":1},{"price":64350.5,"quantity":0,"orderId":0},{"price":64350.6,"quantity":0.09899612,"orderId":1},{"price":64357.3,"quantity":0.00528259,"orderId":1},{"price":64357.4,"quantity":0.11735441,"orderId":1},{"price":64369.4,"quantity":2.24707118,"orderId":1},{"price":64370.3,"quantity":0.28953706,"orderId":2},{"price":64422.4,"quantity":0.15121608,"orderId":5},{"price":64510.1,"quantity":0,"orderId":0},{"price":64510.2,"quantity":0,"orderId":0},{"price":64510.4,"quantity":0,"orderId":0}],"instBids":[{"price":64331.7,"quantity":0.13205616,"orderId":2},{"price":64322.8,"quantity":0.00833802,"orderId":1},{"price":64322.1,"quantity":0,"orderId":0},{"price":64320.7,"quantity":0.000015,"orderId":1},{"price":64320.5,"quantity":0.0005,"orderId":1},{"price":64313.4,"quantity":0.09259057,"orderId":1},{"price":64313.3,"quantity":0,"orderId":0},{"price":64306.6,"quantity":0.11509139,"orderId":1},{"price":64306.5,"quantity":0,"orderId":0},{"price":64157.5,"quantity":0,"orderId":0}],"prevSeqId":31327887954,"currentSeqId":31327887978,"checksum":272635015}
{"action":"update","channel":"books","instrumentId":"BTC-USDT","instAsks":[{"price":64331.8,"quantity":0.32981111,"orderId":7},{"price":64343.7,"quantity":0,"orderId":0},{"price":64343.8,"quantity":0,"orderId":0},{"price":64346.5,"quantity":0.11185974,"orderId":1},{"price":64346.6,"quantity":0.28761701,"orderId":2},{"price":64355.6,"quantity":1.19186751,"orderId":2},{"price":64369.4,"quantity":0,"orderId":0},{"price":64373.6,"quantity":2.29063538,"orderId":1},{"price":64397.5,"quantity":1.96444368,"orderId":2},{"price":64407.7,"quantity":0.03100149,"orderId":1},{"price":64409.7,"quantity":0.0077628,"orderId":1}],"instBids":[{"price":64320.5,"quantity":0.0405,"orderId":2},{"price":64314,"quantity":0.08390974,"orderId":2},{"price":64311.4,"quantity":0.11185974,"orderId":1},{"price":64310.8,"quantity":0.01741554,"orderId":2},{"price":64307.9,"quantity":0.00001501,"orderId":1},{"price":64306,"quantity":0.0015,"orderId":1},{"price":64304.1,"quantity":1.22660334,"orderId":1},{"price":64302.8,"quantity":0.0174,"orderId":1},{"price":64298.3,"quantity":0,"orderId":0},{"price":64296.8,"quantity":2.39399894,"orderId":1},{"price":64263.8,"quantity":0,"orderId":0},{"price":64263.5,"quantity":0.35619159,"orderId":1},{"price":64262.4,"quantity":1.84992973,"orderId":1},{"price":64262.3,"quantity":0,"orderId":0},{"price":64205.1,"quantity":0.02888519,"orderId":2},{"price":64204.6,"quantity":0,"orderId":0},{"price":64158.8,"quantity":0,"orderId":0},{"price":64158.3,"quantity":0,"orderId":0}],"prevSeqId":31327887978,"currentSeqId":31327888015,"checksum":1002797353}
{"action":"update","channel":"books","instrumentId":"BTC-USDT","instAsks":[{"price":64331.8,"quantity":0,"orderId":0},{"price":64332,"quantity":0,"orderId":0},{"price":64332.8,"quantity":0.143261,"orderId":1},{"price":64334,"quantity":0,"orderId":0},{"price":64335,"quantity":0,"orderId":0},{"price":64335.2,"quantity":0,"orderId":0},{"price":64335.3,"quantity":0,"orderId":0},{"price":64335.7,"quantity":0,"orderId":0},{"price":64335.9,"quantity":0.0482871,"orderId":1},{"price":64336,"quantity":0.0808,"orderId":1},{"price":64337.1,"quantity":0,"orderId":0},{"price":64338,"quantity":0.0808,"orderId":1},{"price":64338.4,"quantity":0.00153117,"orderId":1},{"price":64338.8,"quantity":0,"orderId":0},{"price":64344.1,"quantity":0,"orderId":0},{"price":64344.8,"quantity":0.01,"orderId":1},{"price":64346.5,"quantity":0,"orderId":0},{"price":64346.6,"quantity":0.24761701,"orderId":1},{"price":64347.2,"quantity":0.11185637,"orderId":1},{"price":64347.3,"quantity":0.04,"orderId":1},{"price":64348.5,"quantity":0,"orderId":0},{"price":64350.6,"quantity":0.156341,"orderId":1},{"price":64353.2,"quantity":0.09325786,"orderId":1},{"price":64353.6,"quantity":0.02345539,"orderId":1},{"price":64353.7,"quantity":0,"orderId":0},{"price":64355,"quantity":0,"orderId":0},{"price":64355.6,"quantity":0.000015,"orderId":1},{"price":64356.9,"quantity":0,"orderId":0},{"price":64357.3,"quantity":0,"orderId":0},{"price":64357.4,"quantity":0.02332,"orderId":1},{"price":64358.8,"quantity":0,"orderId":0},{"price":64359.7,"quantity":0.74400009,"orderId":1},{"price":64360,"quantity":0.12297001,"orderId":1},{"price":64360.2,"quantity":0,"orderId":0},{"price":64364.4,"quantity":0.0233165,"orderId":1},{"price":64370.2,"quantity":0,"orderId":0},{"price":64370.3,"quantity":0.26,"orderId":1},{"price":64372.4,"quantity":0.15527207,"orderId":1},{"price":64373.6,"quantity":0,"orderId":0},{"price":64374,"quantity":0.02318903,"orderId":1},{"price":64378,"quantity":0,"orderId":0},{"price":64381.6,"quantity":0,"orderId":0},{"price":64381.7,"quantity":0,"orderId":0},{"price":64383.9,"quantity":2.29063538,"orderId":1},{"price":64384,"quantity":0.02953419,"orderId":1},{"price":64384.5,"quantity":0,"orderId":0},{"price":64385.8,"quantity":0,"orderId":0},{"price":64386.4,"quantity":0,"orderId":0},{"price":64386.5,"quantity":0.02953408,"orderId":1},{"price":64387.1,"quantity":0,"orderId":0},{"price":64387.2,"quantity":0.02953408,"orderId":1},{"price":64387.3,"quantity":0,"orderId":0},{"price":64387.6,"quantity":0.02954909,"orderId":2},{"price":64388,"quantity":0,"orderId":0},{"price":64388.7,"quantity":0,"orderId":0},{"price":64393.1,"quantity":0.00016206,"orderId":1},{"price":64393.6,"quantity":0,"orderId":0},{"price":64393.8,"quantity":0,"orderId":0},{"price":64394.8,"quantity":0.46609,"orderId":1},{"price":64413.8,"quantity":0.15600003,"orderId":1},{"price":64414,"quantity":0,"orderId":0},{"price":64414.3,"quantity":0,"orderId":0},{"price":64417.8,"quantity":1.17625,"orderId":1},{"price":64418.4,"quantity":0.24837624,"orderId":1},{"price":64420.6,"quantity":0,"orderId":0},{"price":64422.8,"quantity":0,"orderId":0},{"price":64423.5,"quantity":0.02193628,"orderId":1},{"price":64424.2,"quantity":0,"orderId":0},{"price":64436.6,"quantity":0.0310885,"orderId":1},{"price":64437.6,"quantity":0.14898113,"orderId":1},{"price":64437.7,"quantity":0.24830186,"orderId":1},{"price":64438.3,"quantity":0,"orderId":0},{"price":64441.2,"quantity":0.46531908,"orderId":1},{"price":64475.3,"quantity":0,"orderId":0},{"price":64482.8,"quantity":0.24812848,"orderId":1},{"price":64488.3,"quantity":0.00446463,"orderId":1},{"price":64510.1,"quantity":0.00008038,"orderId":2},{"price":64510.2,"quantity":0.00018585,"orderId":4},{"price":64510.4,"quantity":0.00010027,"orderId":4},{"price":64511,"quantity":0.00026944,"orderId":2},{"price":64511.2,"quantity":0.00004022,"orderId":1},{"price":64511.6,"quantity":0.00016309,"orderId":4},{"price":64511.8,"quantity":0.00001059,"orderId":1},{"price":64511.9,"quantity":0.00377421,"orderId":2},{"price":64512,"quantity":0.00002528,"orderId":1},{"price":64512.1,"quantity":0.00001024,"orderId":1},{"price":64513,"quantity":0.0000948,"orderId":2},{"price":64513.1,"quantity":4.20008512,"orderId":2},{"price":64513.5,"quantity":0.00813634,"orderId":1}],"instBids":[{"price":64332.4,"quantity":1.30777195,"orderId":14},{"price":64332.2,"quantity":0.079,"orderId":1},{"price":64332,"quantity":0.20910468,"orderId":2},{"price":64331.9,"quantity":0.0174,"orderId":1},{"price":64331.8,"quantity":0.00301806,"orderId":1},{"price":64331.7,"quantity":0.03739273,"orderId":2},{"price":64329.8,"quantity":0.15537475,"orderId":1},{"price":64329.4,"quantity":0,"orderId":0},{"price":64327.9,"quantity":0.05866956,"orderId":1},{"price":64327.3,"quantity":0.01192997,"orderId":1},{"price":64325.9,"quantity":0.2002429,"orderId":3},{"price":64325.8,"quantity":0,"orderId":0},{"price":64325.2,"quantity":0.26,"orderId":1},{"price":64324.1,"quantity":0,"orderId":0},{"price":64324,"quantity":0.10475461,"orderId":4},{"price":64322.8,"quantity":0,"orderId":0},{"price":64320.7,"quantity":0.015715,"orderId":2},{"price":64320.6,"quantity":0,"orderId":0},{"price":64320.5,"quantity":0.04,"orderId":1},{"price":64320.4,"quantity":0.0005,"orderId":1},{"price":64320.3,"quantity":0.0005,"orderId":1},{"price":64319.7,"quantity":0.02,"orderId":1},{"price":64319.6,"quantity":0,"orderId":0},{"price":64317.3,"quantity":0.001,"orderId":1},{"price":64316,"quantity":0.18135799,"orderId":3},{"price":64314.5,"quantity":0.0077729,"orderId":1},{"price":64314,"quantity":0.0808,"orderId":1},{"price":64313.4,"quantity":0,"orderId":0},{"price":64313.2,"quantity":0,"orderId":0},{"price":64312.8,"quantity":0.15549,"orderId":1},{"price":64312.6,"quantity":0.11185637,"orderId":1},{"price":64311.5,"quantity":0.02,"orderId":1},{"price":64311.4,"quantity":0,"orderId":0},{"price":64311.2,"quantity":0.46957212,"orderId":1},{"price":64310,"quantity":0,"orderId":0},{"price":64309.4,"quantity":0.15542394,"orderId":1},{"price":64309.2,"quantity":0.11143843,"orderId":1},{"price":64308,"quantity":0.01705983,"orderId":2},{"price":64306.6,"quantity":0,"orderId":0},{"price":64305,"quantity":0,"orderId":0},{"price":64303.2,"quantity":0.31099,"orderId":1},{"price":64302.5,"quantity":0,"orderId":0},{"price":64301.6,"quantity":0,"orderId":0},{"price":64300.7,"quantity":0,"orderId":0},{"price":64300.1,"quantity":0,"orderId":0},{"price":64299.3,"quantity":2.39399894,"orderId":1},{"price":64298.2,"quantity":0.0548003,"orderId":2},{"price":64297.1,"quantity":0.0068,"orderId":1},{"price":64296.8,"quantity":0,"orderId":0},{"price":64294.1,"quantity":0.5621665,"orderId":1},{"price":64291.2,"quantity":0.30590653,"orderId":1},{"price":64285.6,"quantity":0.00163709,"orderId":1},{"price":64285.3,"quantity":1.21107726,"orderId":2},{"price":64285.2,"quantity":0,"orderId":0},{"price":64284.5,"quantity":0.0068,"orderId":1},{"price":64283.5,"quantity":0,"orderId":0},{"price":64278.9,"quantity":0.0349787,"orderId":1},{"price":64262.7,"quantity":0,"orderId":0},{"price":64261.9,"quantity":0,"orderId":0},{"price":64253.1,"quantity":0.02806684,"orderId":3},{"price":64251.6,"quantity":0.01991737,"orderId":1},{"price":64248.6,"quantity":0.05829702,"orderId":1},{"price":64244.2,"quantity":0.15600007,"orderId":1},{"price":64243.9,"quantity":0.000015,"orderId":1},{"price":64232.3,"quantity":0.46683188,"orderId":1},{"price":64227.9,"quantity":0.24911291,"orderId":1},{"price":64227.4,"quantity":0,"orderId":0},{"price":64226.6,"quantity":0.27239345,"orderId":2},{"price":64225.5,"quantity":0,"orderId":0},{"price":64222.8,"quantity":0.00931623,"orderId":2},{"price":64222,"quantity":0,"orderId":0},{"price":64208.6,"quantity":0.24918778,"orderId":1},{"price":64205.3,"quantity":0,"orderId":0},{"price":64163.5,"quantity":0.61128264,"orderId":2},{"price":64161.1,"quantity":0,"orderId":0},{"price":64160.5,"quantity":0,"orderId":0},{"price":64160,"quantity":0,"orderId":0},{"price":64159.9,"quantity":0,"orderId":0},{"price":64159.6,"quantity":0,"orderId":0},{"price":64159.1,"quantity":0,"orderId":0}],"prevSeqId":31327888015,"currentSeqId":31327888456,"checksum":1901564209}
{"action":"update","channel":"books","instrumentId":"BTC-USDT","instAsks":[{"price":64332.5,"quantity":0.00503105,"orderId":2},{"price":64334,"quantity":0.0808,"orderId":1},{"price":64335.2,"quantity":0.005,"orderId":1},{"price":64338.1,"quantity":0.02254037,"orderId":1},{"price":64340.2,"quantity":0.01106532,"orderId":1},{"price":64341.3,"quantity":0,"orderId":0},{"price":64342.4,"quantity":0.00774949,"orderId":1},{"price":64344,"quantity":0.00898533,"orderId":1},{"price":64344.8,"quantity":0.04580887,"orderId":2},{"price":64344.9,"quantity":0.05968139,"orderId":1},{"price":64345.5,"quantity":0.26,"orderId":1},{"price":64347.2,"quantity":0.11185647,"orderId":1},{"price":64351.5,"quantity":0.09041485,"orderId":1},{"price":64353.2,"quantity":0,"orderId":0},{"price":64358.3,"quantity":0.26818211,"orderId":2},{"price":64360,"quantity":0,"orderId":0},{"price":64372.2,"quantity":1.22834044,"orderId":1},{"price":64381.9,"quantity":0,"orderId":0},{"price":64383.9,"quantity":0,"orderId":0},{"price":64401.2,"quantity":0,"orderId":0},{"price":64401.3,"quantity":0.01806146,"orderId":1},{"price":64418.9,"quantity":0,"orderId":0},{"price":64424.9,"quantity":0.05173983,"orderId":1},{"price":64512.1,"quantity":0,"orderId":0},{"price":64513,"quantity":0,"orderId":0},{"price":64513.1,"quantity":0,"orderId":0},{"price":64513.5,"quantity":0,"orderId":0}],"instBids":[{"price":64332.4,"quantity":0.82777195,"orderId":12},{"price":64321.5,"quantity":0.0005,"orderId":1},{"price":64321.4,"quantity":0.0005,"orderId":1},{"price":64320.4,"quantity":0,"orderId":0},{"price":64320.3,"quantity":0,"orderId":0},{"price":64316.2,"quantity":0.0077729,"orderId":1},{"price":64316,"quantity":0.08156467,"orderId":2},{"price":64314.5,"quantity":0,"orderId":0},{"price":64314.2,"quantity":0.09369078,"orderId":1},{"price":64312.6,"quantity":0.11185647,"orderId":1},{"price":64309.2,"quantity":0,"orderId":0},{"price":64307.5,"quantity":0.11871685,"orderId":1},{"price":64301.7,"quantity":2.4700685,"orderId":3},{"price":64299.3,"quantity":0,"orderId":0},{"price":64285.3,"quantity":1.20851,"orderId":1},{"price":64284.5,"quantity":0.0136,"orderId":2},{"price":64283.5,"quantity":0.00256727,"orderId":1},{"price":64181.4,"quantity":0.05626201,"orderId":2},{"price":64177.9,"quantity":0.00018698,"orderId":1},{"price":64161.2,"quantity":0,"orderId":0}],"prevSeqId":31327888456,"currentSeqId":31327888518,"checksum":1451385170}
{"action":"update","channel":"books","instrumentId":"BTC-USDT","instAsks":[{"price":64344.8,"quantity":0.16152394,"orderId":3},{"price":64346.5,"quantity":0.11185796,"orderId":1},{"price":64347.2,"quantity":0,"orderId":0},{"price":64374.7,"quantity":2.29063538,"orderId":1},{"price":64387,"quantity":0.0136,"orderId":2},{"price":64390.5,"quantity":0.58124611,"orderId":1},{"price":64409.7,"quantity":0,"orderId":0},{"price":64411.6,"quantity":0.0068,"orderId":1},{"price":64417.6,"quantity":0.00776185,"orderId":1},{"price":64511.6,"quantity":0,"orderId":0},{"price":64511.8,"quantity":0,"orderId":0},{"price":64511.9,"quantity":0,"orderId":0},{"price":64512,"quantity":0,"orderId":0}],"instBids":[{"price":64322.8,"quantity":0.0005,"orderId":1},{"price":64322.7,"quantity":0.0005,"orderId":1},{"price":64321.5,"quantity":0,"orderId":0},{"price":64321.4,"quantity":0,"orderId":0},{"price":64312.6,"quantity":0,"orderId":0},{"price":64311.6,"quantity":0.11185796,"orderId":1},{"price":64253.1,"quantity":0.03486684,"orderId":4}],"prevSeqId":31327888518,"currentSeqId":31327888543,"checksum":-1840783470}
{"action":"update","channel":"books","instrumentId":"BTC-USDT","instAsks":[{"price":64346.5,"quantity":0.11185766,"orderId":1},{"price":64349.3,"quantity":0.02433202,"orderId":1},{"price":64372.1,"quantity":2.29063538,"orderId":1},{"price":64374.7,"quantity":0,"orderId":0},{"price":64419.7,"quantity":0,"orderId":0},{"price":64421.5,"quantity":0.00779097,"orderId":2}],"instBids":[{"price":64322.9,"quantity":0.0005,"orderId":1},{"price":64322.7,"quantity":0,"orderId":0},{"price":64322.5,"quantity":0.0156,"orderId":1},{"price":64320.7,"quantity":0.000015,"orderId":1},{"price":64311.6,"quantity":0.11185766,"orderId":1},{"price":64226.6,"quantity":0.2780137,"orderId":3},{"price":64212.6,"quantity":0.07776473,"orderId":2},{"price":64205.9,"quantity":0.00778745,"orderId":1},{"price":64205.1,"quantity":0.02109765,"orderId":1},{"price":64191.7,"quantity":0,"orderId":0},{"price":64161.4,"quantity":0,"orderId":0}],"prevSeqId":31327888543,"currentSeqId":31327888579,"checksum":2134759003}
{"action":"update","channel":"books","instrumentId":"BTC-USDT","instAsks":[{"price":64413.6,"quantity":0,"orderId":0},{"price":64419.2,"quantity":0.03876146,"orderId":2},{"price":64511.6,"quantity":0.00016309,"orderId":4}],"instBids":[{"price":64312.5,"quantity":0.05936993,"orderId":1},{"price":64297.1,"quantity":0,"orderId":0},{"price":64291.4,"quantity":0.02,"orderId":1},{"price":64284.5,"quantity":0,"orderId":0},{"price":64274.1,"quantity":0,"orderId":0},{"price":64253.1,"quantity":0.02126684,"orderId":2},{"price":64227.6,"quantity":0.00778482,"orderId":1},{"price":64222.8,"quantity":0.00153083,"orderId":1},{"price":64161.4,"quantity":0.46957212,"orderId":1}],"prevSeqId":31327888579,"currentSeqId":31327888594,"checksum":2134759003}
{"action":"update","channel":"books","instrumentId":"BTC-USDT","instAsks":[{"price":64342.5,"quantity":0.0742907,"orderId":2},{"price":64344.9,"quantity":0,"orderId":0},{"price":64346.5,"quantity":0,"orderId":0},{"price":64348.7,"quantity":0.11185697,"orderId":1},{"price":64364.6,"quantity":0,"orderId":0},{"price":64379.8,"quantity":0.02328875,"orderId":1},{"price":64388.5,"quantity":0.46609,"orderId":1}],"instBids":[{"price":64323,"quantity":0.0005,"orderId":1},{"price":64322.8,"quantity":0,"orderId":0},{"price":64312.2,"quantity":0.11185697,"orderId":1},{"price":64311.6,"quantity":0,"orderId":0}],"prevSeqId":31327888594,"currentSeqId":31327888605,"checksum":1166962264}
{"action":"update","channel":"books","instrumentId":"BTC-USDT","instAsks":[{"price":64337.7,"quantity":0.00468734,"orderId":1},{"price":64339.5,"quantity":0.01106532,"orderId":1},{"price":64340.2,"quantity":0,"orderId":0},{"price":64371.6,"quantity":2.34930494,"orderId":2},{"price":64372.1,"quantity":0,"orderId":0}],"instBids":[{"price":64323,"quantity":0,"orderId":0},{"price":64322.8,"quantity":0.0005,"orderId":1},{"price":64322.5,"quantity":0,"orderId":0},{"price":64322.4,"quantity":0.0157,"orderId":1},{"price":64310.7,"quantity":0,"orderId":0},{"price":64161.2,"quantity":0.00001014,"orderId":1}],"prevSeqId":31327888605,"currentSeqId":31327888618,"checksum":1401826245}
{"action":"update","channel":"books","instrumentId":"BTC-USDT","instAsks":[{"price":64347.2,"quantity":0.1118572,"orderId":1},{"price":64348.7,"quantity":0,"orderId":0},{"price":64358.5,"quantity":0,"orderId":0},{"price":64368.2,"quantity":0.000209,"orderId":1},{"price":64371.6,"quantity":0.05866956,"orderId":1},{"price":64372.1,"quantity":2.30591783,"orderId":1},{"price":64374.8,"quantity":0.00001501,"orderId":1},{"price":64391.2,"quantity":0.00209,"orderId":1},{"price":64511.2,"quantity":0,"orderId":0},{"price":64511.6,"quantity":0,"orderId":0}],"instBids":[{"price":64332.4,"quantity":0.57487922,"orderId":9},{"price":64331.7,"quantity":0.0174,"orderId":1},{"price":64323,"quantity":0.0005,"orderId":1},{"price":64322.8,"quantity":0,"orderId":0},{"price":64312.2,"quantity":0.1118572,"orderId":1}],"prevSeqId":31327888618,"currentSeqId":31327888644,"checksum":1334488925}
{"action":"update","channel":"books","instrumentId":"BTC-USDT","instAsks":[{"price":64332.5,"quantity":0.47113384,"orderId":7},{"price":64339.5,"quantity":0,"orderId":0},{"price":64344.7,"quantity":0.11186196,"orderId":1},{"price":64347.2,"quantity":0,"orderId":0},{"price":64351.3,"quantity":0.0921909,"orderId":1},{"price":64351.5,"quantity":0,"orderId":0},{"price":64353.8,"quantity":0.05866956,"orderId":1},{"price":64358.1,"quantity":0.12169212,"orderId":1},{"price":64358.3,"quantity":0.19103177,"orderId":2},{"price":64370.3,"quantity":2.56591783,"orderId":2},{"price":64372.1,"quantity":0,"orderId":0}],"instBids":[{"price":64332.4,"quantity":0.39769332,"orderId":6},{"price":64332.2,"quantity":0,"orderId":0},{"price":64332,"quantity":0.0808,"orderId":1},{"price":64327.9,"quantity":0,"orderId":0},{"price":64327.3,"quantity":0,"orderId":0},{"price":64325.2,"quantity":0,"orderId":0},{"price":64314.2,"quantity":0,"orderId":0},{"price":64314.1,"quantity":0.09548256,"orderId":1},{"price":64312.2,"quantity":0,"orderId":0},{"price":64309.5,"quantity":0.11186181,"orderId":1},{"price":64307.5,"quantity":0,"orderId":0},{"price":64307.3,"quantity":0.11339593,"orderId":1},{"price":64306,"quantity":0,"orderId":0},{"price":64301.7,"quantity":0.07606956,"orderId":2},{"price":64297.2,"quantity":2.36735991,"orderId":1},{"price":64297.1,"quantity":0.0068,"orderId":1},{"price":64284.5,"quantity":0.0068,"orderId":1},{"price":64253.1,"quantity":0.02806684,"orderId":3},{"price":64229.7,"quantity":0.00194884,"orderId":1},{"price":64229.1,"quantity":0,"orderId":0},{"price":64161.1,"quantity":0.0296,"orderId":1},{"price":64160,"quantity":0.00119308,"orderId":12}],"prevSeqId":31327888644,"currentSeqId":31327888712,"checksum":-1454650306}
{"action":"update","channel":"books","instrumentId":"BTC-USDT","instAsks":[{"price":64482.8,"quantity":0,"orderId":0},{"price":64511.2,"quantity":0.00004022,"orderId":1}],"instBids":[{"price":64332.4,"quantity":0.35923332,"orderId":6},{"price":64322.1,"quantity":0.00024801,"orderId":1},{"price":64309.5,"quantity":0,"orderId":0},{"price":64308.1,"quantity":0.11186198,"orderId":1},{"price":64298.3,"quantity":2.36735991,"orderId":1},{"price":64297.2,"quantity":0,"orderId":0},{"price":64297.1,"quantity":0,"orderId":0},{"price":64284.6,"quantity":0.00256718,"orderId":1},{"price":64284.5,"quantity":0,"orderId":0},{"price":64283.5,"quantity":0,"orderId":0},{"price":64253.1,"quantity":0.02126684,"orderId":2},{"price":64160.5,"quantity":0.26,"orderId":1}],"prevSeqId":31327888712,"currentSeqId":31327888731,"checksum":-1052292817}
{"action":"update","channel":"books","instrumentId":"BTC-USDT","instAsks":[{"price":64369.8,"quantity":2.30591783,"orderId":1},{"price":64370.3,"quantity":0.26,"orderId":1},{"price":64372.2,"quantity":0,"orderId":0},{"price":64390.4,"quantity":0.34874769,"orderId":1},{"price":64437.6,"quantity":0.09380463,"orderId":1},{"price":64437.7,"quantity":0,"orderId":0}],"instBids":[{"price":64323.1,"quantity":0.0005,"orderId":1},{"price":64322.9,"quantity":0,"orderId":0},{"price":64322.1,"quantity":0,"orderId":0},{"price":64311.5,"quantity":0,"orderId":0},{"price":64301.8,"quantity":2.36735991,"orderId":1},{"price":64298.3,"quantity":0,"orderId":0},{"price":64284.6,"quantity":0,"orderId":0},{"price":64283.5,"quantity":0.03776905,"orderId":2},{"price":64263.5,"quantity":0.910183,"orderId":2},{"price":64226.6,"quantity":0.005632,"orderId":2},{"price":64159.9,"quantity":0.01564601,"orderId":2},{"price":64159.6,"quantity":1.5,"orderId":1}],"prevSeqId":31327888731,"currentSeqId":31327888751,"checksum":-168102678}
{"action":"update","channel":"books","instrumentId":"BTC-USDT","instAsks":[{"price":64343.1,"quantity":0.15534287,"orderId":1},{"price":64369.8,"quantity":0,"orderId":0},{"price":64370.3,"quantity":2.56591783,"orderId":2}],"instBids":[{"price":64326.1,"quantity":0.22,"orderId":1},{"price":64318.8,"quantity":0.156341,"orderId":1},{"price":64301.8,"quantity":0,"orderId":0},{"price":64299.3,"quantity":2.36735991,"orderId":1},{"price":64159.9,"quantity":0,"orderId":0},{"price":64159.6,"quantity":0,"orderId":0}],"prevSeqId":31327888751,"currentSeqId":31327888859,"checksum":1265950135}
{"action":"update","channel":"books","instrumentId":"BTC-USDT","instAsks":[{"price":64337.7,"quantity":0,"orderId":0},{"price":64342.4,"quantity":0.11961388,"orderId":2},{"price":64344.7,"quantity":0,"orderId":0},{"price":64356.2,"quantity":1.25114903,"orderId":1},{"price":64357.1,"quantity":0,"orderId":0},{"price":64454.6,"quantity":0,"orderId":0},{"price":64455,"quantity":0.01631645,"orderId":2},{"price":64511.6,"quantity":0.00016309,"orderId":4},{"price":64511.8,"quantity":0.00001059,"orderId":1},{"price":64511.9,"quantity":0.00377421,"orderId":2}],"instBids":[{"price":64308.1,"quantity":0,"orderId":0},{"price":64307.4,"quantity":0.11186439,"orderId":1},{"price":64301.7,"quantity":2.44342947,"orderId":3},{"price":64299.3,"quantity":0,"orderId":0},{"price":64233.6,"quantity":0,"orderId":0},{"price":64159.9,"quantity":0.01564601,"orderId":2},{"price":64159.6,"quantity":1.5,"orderId":1}],"prevSeqId":31327888859,"currentSeqId":31327888878,"checksum":322315061}
{"action":"update","channel":"books","instrumentId":"BTC-USDT","instAsks":[{"price":64342.4,"quantity":0.00774949,"orderId":1},{"price":64344.7,"quantity":0.11186322,"orderId":1},{"price":64511.9,"quantity":0,"orderId":0}],"instBids":[{"price":64308.1,"quantity":0.11186322,"orderId":1},{"price":64307.4,"quantity":0,"orderId":0},{"price":64237.1,"quantity":0.25824967,"orderId":3}],"prevSeqId":31327888878,"currentSeqId":31327888890,"checksum":-1996321916}
{"action":"update","channel":"books","instrumentId":"BTC-USDT","instAsks":[{"price":64441.6,"quantity":0.24828719,"orderId":1},{"price":64486.6,"quantity":0.24811382,"orderId":1},{"price":64511.6,"quantity":0,"orderId":0},{"price":64511.8,"quantity":0,"orderId":0}],"instBids":[],"prevSeqId":31327888890,"currentSeqId":31327888892,"checksum":-1996321916}
{"action":"update","channel":"books","instrumentId":"BTC-USDT","instAsks":[{"price":64344.7,"quantity":0.11186346,"orderId":1},{"price":64411.1,"quantity":0.01617217,"orderId":1},{"price":64412,"quantity":0,"orderId":0},{"price":64435.3,"quantity":0.01616609,"orderId":1},{"price":64436.8,"quantity":0,"orderId":0}],"instBids":[{"price":64332.4,"quantity":0.34183332,"orderId":5},{"price":64307.4,"quantity":0.11018507,"orderId":1},{"price":64307.3,"quantity":0,"orderId":0},{"price":64228.1,"quantity":0.276341,"orderId":2},{"price":64160.8,"quantity":0.01616609,"orderId":1},{"price":64159.6,"quantity":0,"orderId":0}],"prevSeqId":31327888892,"currentSeqId":31327888906,"checksum":1711784463}
{"action":"update","channel":"books","instrumentId":"BTC-USDT","instAsks":[{"price":64332.5,"quantity":0.52699384,"orderId":8},{"price":64412.9,"quantity":0,"orderId":0},{"price":64413.5,"quantity":0.01617156,"orderId":1},{"price":64418.4,"quantity":0,"orderId":0},{"price":64441.6,"quantity":0,"orderId":0},{"price":64477.4,"quantity":0,"orderId":0},{"price":64478,"quantity":0.01617156,"orderId":1},{"price":64486.6,"quantity":0,"orderId":0},{"price":64511.6,"quantity":0.00016309,"orderId":4},{"price":64511.8,"quantity":0.00001059,"orderId":1},{"price":64511.9,"quantity":0.00377421,"orderId":2}],"instBids":[{"price":64332,"quantity":0,"orderId":0},{"price":64331.9,"quantity":0,"orderId":0},{"price":64331.7,"quantity":0,"orderId":0},{"price":64323.1,"quantity":0,"orderId":0},{"price":64323,"quantity":0,"orderId":0},{"price":64322.6,"quantity":0.0005,"orderId":1},{"price":64322.5,"quantity":0.0005,"orderId":1},{"price":64308.1,"quantity":0.11186264,"orderId":1},{"price":64227.9,"quantity":0,"orderId":0},{"price":64220.6,"quantity":0,"orderId":0},{"price":64208.6,"quantity":0,"orderId":0},{"price":64180.3,"quantity":0.01617156,"orderId":1},{"price":64176.1,"quantity":0.00077054,"orderId":4},{"price":64163.5,"quantity":0.36192,"orderId":1},{"price":64159.6,"quantity":1.5,"orderId":1},{"price":64159.1,"quantity":0.00001007,"orderId":1},{"price":64158.8,"quantity":0.00031097,"orderId":2},{"price":64158.3,"quantity":0.00014683,"orderId":1},{"price":64157.5,"quantity":0.00013042,"orderId":3}],"prevSeqId":31327888906,"currentSeqId":31327888948,"checksum":-368703252}
{"action":"update","channel":"books","instrumentId":"BTC-USDT","instAsks":[{"price":64332.5,"quantity":0.43249959,"orderId":7},{"price":64343,"quantity":0.1118637,"orderId":1},{"price":64344.7,"quantity":0,"orderId":0}],"instBids":[{"price":64332.4,"quantity":0.20324332,"orderId":3},{"price":64226.6,"quantity":0.00001175,"orderId":1},{"price":64163.8,"quantity":0.01616118,"orderId":1},{"price":64162.2,"quantity":0,"orderId":0}],"prevSeqId":31327888948,"currentSeqId":31327888963,"checksum":-1835156991}
{"action":"update","channel":"books","instrumentId":"BTC-USDT","instAsks":[{"price":64422.7,"quantity":0.0064677,"orderId":1},{"price":64422.9,"quantity":0.12126,"orderId":1},{"price":64426,"quantity":0.00001501,"orderId":1},{"price":64426.4,"quantity":0.01616833,"orderId":1},{"price":64434.7,"quantity":0,"orderId":0},{"price":64499.2,"quantity":0,"orderId":0}],"instBids":[{"price":64332,"quantity":0.0808,"orderId":1},{"price":64326,"quantity":0.3008,"orderId":2},{"price":64283.6,"quantity":0.00256722,"orderId":1},{"price":64283.5,"quantity":0.03520183,"orderId":1},{"price":64178,"quantity":0.0064677,"orderId":1},{"price":64175.7,"quantity":0,"orderId":0},{"price":64170.7,"quantity":0.00001077,"orderId":1},{"price":64158.3,"quantity":0,"orderId":0},{"price":64157.5,"quantity":0,"orderId":0}],"prevSeqId":31327888963,"currentSeqId":31327888978,"checksum":-1430484475}
{"action":"update","channel":"books","instrumentId":"BTC-USDT","instAsks":[{"price":64332.5,"quantity":0.38793579,"orderId":6},{"price":64332.8,"quantity":0,"orderId":0},{"price":64335.3,"quantity":0.08595544,"orderId":1},{"price":64335.4,"quantity":0.143259,"orderId":1},{"price":64335.9,"quantity":0,"orderId":0},{"price":64343,"quantity":0,"orderId":0},{"price":64344.7,"quantity":0.11186328,"orderId":1},{"price":64437,"quantity":0.01616567,"orderId":1},{"price":64501.5,"quantity":0.01616567,"orderId":1},{"price":64511.8,"quantity":0,"orderId":0},{"price":64511.9,"quantity":0,"orderId":0}],"instBids":[{"price":64325.9,"quantity":0.3435019,"orderId":4},{"price":64321.6,"quantity":0,"orderId":0},{"price":64308.1,"quantity":0.11186328,"orderId":1},{"price":64231.6,"quantity":0.28019715,"orderId":2},{"price":64212.3,"quantity":0.24917306,"orderId":1},{"price":64170.4,"quantity":0.01618533,"orderId":2},{"price":64167.3,"quantity":0.36487791,"orderId":2}],"prevSeqId":31327888978,"currentSeqId":31327889007,"checksum":97741389}
{"action":"update","channel":"books","instrumentId":"BTC-USDT","instAsks":[{"price":64332.5,"quantity":0.41404414,"orderId":7},{"price":64344.7,"quantity":0.11186318,"orderId":1},{"price":64356.1,"quantity":0.75068948,"orderId":1},{"price":64376.6,"quantity":0.72700207,"orderId":1},{"price":64511.2,"quantity":0,"orderId":0},{"price":64511.6,"quantity":0,"orderId":0}],"instBids":[{"price":64332.4,"quantity":0.22064332,"orderId":4},{"price":64322.9,"quantity":0.0005,"orderId":1},{"price":64322.8,"quantity":0.0005,"orderId":1},{"price":64322.6,"quantity":0,"orderId":0},{"price":64322.5,"quantity":0,"orderId":0},{"price":64251.1,"quantity":0.01617189,"orderId":1},{"price":64250.1,"quantity":0,"orderId":0},{"price":64228.2,"quantity":0.00562011,"orderId":1},{"price":64158.8,"quantity":0,"orderId":0}],"prevSeqId":31327889007,"currentSeqId":31327889029,"checksum":634550615}
{"action":"update","channel":"books","instrumentId":"BTC-USDT","instAsks":[{"price":64332.5,"quantity":0.45812866,"orderId":8},{"price":64343,"quantity":0.11186366,"orderId":1},{"price":64344.7,"quantity":0,"orderId":0},{"price":64461.9,"quantity":0,"orderId":0},{"price":64462.3,"quantity":0.01294039,"orderId":1}],"instBids":[{"price":64308.1,"quantity":0,"orderId":0},{"price":64307.9,"quantity":0.11187867,"orderId":2},{"price":64244.6,"quantity":0.01617156,"orderId":1},{"price":64243.6,"quantity":0,"orderId":0},{"price":64158.8,"quantity":0.00031097,"orderId":2}],"prevSeqId":31327889029,"currentSeqId":31327889044,"checksum":-863185323}
{"action":"update","channel":"books","instrumentId":"BTC-USDT","instAsks":[],"instBids":[{"price":64323.1,"quantity":0.0005,"orderId":1},{"price":64323,"quantity":0.0005,"orderId":1},{"price":64322.9,"quantity":0,"orderId":0},{"price":64322.8,"quantity":0,"orderId":0}],"prevSeqId":31327889044,"currentSeqId":31327889051,"checksum":-1220040520}
{"action":"update","channel":"books","instrumentId":"BTC-USDT","instAsks":[{"price":64343,"quantity":0,"orderId":0},{"price":64344.7,"quantity":0.1118627,"orderId":1}],"instBids":[{"price":64332.4,"quantity":0.20324332,"orderId":3},{"price":64323.1,"quantity":0,"orderId":0},{"price":64323,"quantity":0,"orderId":0},{"price":64322.8,"quantity":0.0005,"orderId":1},{"price":64322.7,"quantity":0.0005,"orderId":1},{"price":64308.1,"quantity":0.1118627,"orderId":1},{"price":64307.9,"quantity":0.00001501,"orderId":1},{"price":64158.8,"quantity":0,"orderId":0}],"prevSeqId":31327889051,"currentSeqId":31327889060,"checksum":-171997098}
{"action":"update","channel":"books","instrumentId":"BTC-USDT","instAsks":[{"price":64332.5,"quantity":1.14630484,"orderId":13},{"price":64335.8,"quantity":0.05866956,"orderId":1},{"price":64337.2,"quantity":0.01106532,"orderId":1},{"price":64337.9,"quantity":0.15600002,"orderId":1},{"price":64338.2,"quantity":0.05968139,"orderId":1},{"price":64338.7,"quantity":0.11187102,"orderId":1},{"price":64338.8,"quantity":0.15535326,"orderId":1},{"price":64339,"quantity":0.26,"orderId":1},{"price":64342.3,"quantity":0.05866956,"orderId":1},{"price":64342.5,"quantity":0.01460931,"orderId":1},{"price":64343.1,"quantity":0,"orderId":0},{"price":64344.7,"quantity":0.156341,"orderId":1},{"price":64346.2,"quantity":0.03469077,"orderId":1},{"price":64351.3,"quantity":0,"orderId":0},{"price":64354.5,"quantity":0.03133881,"orderId":1},{"price":64357.5,"quantity":0.00528259,"orderId":1},{"price":64358.1,"quantity":0,"orderId":0},{"price":64358.3,"quantity":0.31164719,"orderId":2},{"price":64371.7,"quantity":0,"orderId":0},{"price":64372.4,"quantity":0,"orderId":0},{"price":64388.2,"quantity":0.07050338,"orderId":2},{"price":64393.4,"quantity":0.4661,"orderId":1},{"price":64412.6,"quantity":0.06643202,"orderId":2},{"price":64413.9,"quantity":0.03876211,"orderId":2},{"price":64417.6,"quantity":0,"orderId":0},{"price":64419.2,"quantity":0.0309998,"orderId":1},{"price":64422.3,"quantity":0.24836157,"orderId":1},{"price":64424.9,"quantity":0.08273939,"orderId":2},{"price":64441.6,"quantity":0.24828719,"orderId":1},{"price":64486.6,"quantity":0.24811382,"orderId":1},{"price":64509.4,"quantity":0,"orderId":0},{"price":64509.6,"quantity":0,"orderId":0},{"price":64509.7,"quantity":0,"orderId":0},{"price":64509.8,"quantity":0,"orderId":0},{"price":64510,"quantity":0,"orderId":0},{"price":64510.1,"quantity":0,"orderId":0},{"price":64510.2,"quantity":0,"orderId":0},{"price":64510.4,"quantity":0,"orderId":0},{"price":64511,"quantity":0,"orderId":0}],"instBids":[{"price":64332.4,"quantity":0.11856193,"orderId":1},{"price":64332,"quantity":0,"orderId":0},{"price":64330,"quantity":0,"orderId":0},{"price":64329.8,"quantity":0,"orderId":0},{"price":64328,"quantity":0,"orderId":0},{"price":64326.1,"quantity":0,"orderId":0},{"price":64326,"quantity":0.15538381,"orderId":1},{"price":64325.9,"quantity":0.1778429,"orderId":1},{"price":64324.1,"quantity":0.00310753,"orderId":1},{"price":64324,"quantity":0.08235461,"orderId":2},{"price":64323.9,"quantity":0,"orderId":0},{"price":64322.8,"quantity":0,"orderId":0},{"price":64322.7,"quantity":0,"orderId":0},{"price":64322.6,"quantity":0.0005,"orderId":1},{"price":64322.5,"quantity":0.0005,"orderId":1},{"price":64322,"quantity":0.0810492,"orderId":2},{"price":64318.8,"quantity":0,"orderId":0},{"price":64318.7,"quantity":0,"orderId":0},{"price":64317.7,"quantity":0.00528259,"orderId":1},{"price":64316.8,"quantity":0,"orderId":0},{"price":64314.1,"quantity":0,"orderId":0},{"price":64312.8,"quantity":0,"orderId":0},{"price":64311.8,"quantity":0.15549,"orderId":1},{"price":64311.3,"quantity":0,"orderId":0},{"price":64311.1,"quantity":0,"orderId":0},{"price":64308.1,"quantity":0,"orderId":0},{"price":64307.4,"quantity":0,"orderId":0},{"price":64304.5,"quantity":0.11186742,"orderId":1},{"price":64304.1,"quantity":0,"orderId":0},{"price":64303.2,"quantity":0,"orderId":0},{"price":64302.2,"quantity":0.31099,"orderId":1},{"price":64301.7,"quantity":0.07606956,"orderId":2},{"price":64298.2,"quantity":0.0233183,"orderId":1},{"price":64295.1,"quantity":0.15547362,"orderId":2},{"price":64294.1,"quantity":0,"orderId":0},{"price":64283.5,"quantity":0,"orderId":0},{"price":64263.8,"quantity":0.156,"orderId":1},{"price":64263.5,"quantity":0,"orderId":0},{"price":64262.4,"quantity":0,"orderId":0},{"price":64236.7,"quantity":0.43737139,"orderId":1},{"price":64227.6,"quantity":0,"orderId":0},{"price":64223.3,"quantity":0.06778538,"orderId":3},{"price":64217.1,"quantity":0.03520185,"orderId":1},{"price":64212.6,"quantity":0.06997809,"orderId":1},{"price":64206.9,"quantity":0.11485732,"orderId":2},{"price":64205.9,"quantity":0,"orderId":0},{"price":64199.2,"quantity":0.00786212,"orderId":2},{"price":64158.8,"quantity":0.00031097,"orderId":2},{"price":64158.3,"quantity":0.00014683,"orderId":1},{"price":64157.5,"quantity":0.00013042,"orderId":3},{"price":64157.3,"quantity":0.00001832,"orderId":1},{"price":64157.1,"quantity":0.00020869,"orderId":1},{"price":64156.8,"quantity":0.00122821,"orderId":1},{"price":64156.2,"quantity":0.03039456,"orderId":1},{"price":64155.9,"quantity":0.000015,"orderId":1},{"price":64155.4,"quantity":0.00002122,"orderId":1},{"price":64154.8,"quantity":0.01021209,"orderId":1},{"price":64154.5,"quantity":0.00086876,"orderId":5},{"price":64154.1,"quantity":0.00001345,"orderId":1},{"price":64154,"quantity":0.26861939,"orderId":2},{"price":64153.8,"quantity":0.03858932,"orderId":6},{"price":64153.7,"quantity":0.00055031,"orderId":1}],"prevSeqId":31327889060,"currentSeqId":31327889194,"checksum":1462588143}
{"action":"update","channel":"books","instrumentId":"BTC-USDT","instAsks":[{"price":64332.5,"quantity":0.88630484,"orderId":12},{"price":64335.1,"quantity":0.05968139,"orderId":1},{"price":64338.2,"quantity":0,"orderId":0},{"price":64338.7,"quantity":0.1118718,"orderId":1},{"price":64341.9,"quantity":0.06287949,"orderId":2},{"price":64342.4,"quantity":0,"orderId":0},{"price":64351.1,"quantity":0.09310328,"orderId":1},{"price":64357.8,"quantity":0.11654636,"orderId":1},{"price":64367.8,"quantity":2.32980059,"orderId":1},{"price":64370.3,"quantity":0.26,"orderId":1},{"price":64392.8,"quantity":0,"orderId":0},{"price":64394.7,"quantity":0.01789172,"orderId":2},{"price":64457.2,"quantity":0,"orderId":0}],"instBids":[{"price":64328,"quantity":0.0808,"orderId":1},{"price":64324.1,"quantity":0.00017763,"orderId":1},{"price":64323.8,"quantity":0.143259,"orderId":1},{"price":64322.6,"quantity":0,"orderId":0},{"price":64322.5,"quantity":0,"orderId":0},{"price":64322.4,"quantity":0,"orderId":0},{"price":64321.8,"quantity":0.0005,"orderId":1},{"price":64321.7,"quantity":0.0161,"orderId":2},{"price":64319.8,"quantity":0.01192997,"orderId":1},{"price":64319.4,"quantity":0.26,"orderId":1},{"price":64318.1,"quantity":0,"orderId":0},{"price":64317.7,"quantity":0,"orderId":0},{"price":64313.9,"quantity":0.11434969,"orderId":2},{"price":64312.9,"quantity":0.00528259,"orderId":1},{"price":64312.2,"quantity":0.156341,"orderId":1},{"price":64311.2,"quantity":0,"orderId":0},{"price":64311,"quantity":0.46957212,"orderId":1},{"price":64307.1,"quantity":0.11699566,"orderId":1},{"price":64304.5,"quantity":0.1118718,"orderId":1},{"price":64301.1,"quantity":0,"orderId":0},{"price":64286.1,"quantity":2.33318835,"orderId":1},{"price":64283.7,"quantity":0.009324,"orderId":1},{"price":64280.1,"quantity":0.55884034,"orderId":1},{"price":64279.3,"quantity":0.7,"orderId":1},{"price":64249.7,"quantity":0.156341,"orderId":1},{"price":64185.4,"quantity":0.00308108,"orderId":1},{"price":64154.8,"quantity":0,"orderId":0},{"price":64154.5,"quantity":0,"orderId":0},{"price":64154.1,"quantity":0,"orderId":0},{"price":64154,"quantity":0,"orderId":0},{"price":64153.8,"quantity":0,"orderId":0},{"price":64153.7,"quantity":0,"orderId":0}],"prevSeqId":31327889194,"currentSeqId":31327889279,"checksum":508820834}
{"action":"update","channel":"books","instrumentId":"BTC-USDT","instAsks":[{"price":64338.7,"quantity":0,"orderId":0},{"price":64341.3,"quantity":0.11186946,"orderId":1}],"instBids":[{"price":64319.9,"quantity":0.01192997,"orderId":1},{"price":64319.8,"quantity":0,"orderId":0},{"price":64319.7,"quantity":0,"orderId":0},{"price":64313,"quantity":0.0549557,"orderId":2},{"price":64309.7,"quantity":0,"orderId":0},{"price":64290.4,"quantity":2.33318835,"orderId":1},{"price":64286.1,"quantity":0,"orderId":0},{"price":64154.8,"quantity":0.01021209,"orderId":1},{"price":64154.5,"quantity":0.00086876,"orderId":5}],"prevSeqId":31327889279,"currentSeqId":31327889303,"checksum":-544889082}
{"action":"update","channel":"books","instrumentId":"BTC-USDT","instAsks":[{"price":64338.7,"quantity":0.11187046,"orderId":1},{"price":64341.3,"quantity":0,"orderId":0}],"instBids":[{"price":64325.9,"quantity":0.23752429,"orderId":2},{"price":64321.7,"quantity":0.0159,"orderId":2},{"price":64301.4,"quantity":1.2070344,"orderId":1},{"price":64295.2,"quantity":2.33318835,"orderId":1},{"price":64290.4,"quantity":0,"orderId":0},{"price":64259.6,"quantity":1.86435612,"orderId":1},{"price":64154.8,"quantity":0,"orderId":0},{"price":64154.5,"quantity":0,"orderId":0}],"prevSeqId":31327889303,"currentSeqId":31327889315,"checksum":-659408129}
{"action":"update","channel":"books","instrumentId":"BTC-USDT","instAsks":[{"price":64335.1,"quantity":0,"orderId":0},{"price":64335.3,"quantity":0.04848004,"orderId":1},{"price":64335.4,"quantity":0,"orderId":0},{"price":64338.7,"quantity":0,"orderId":0},{"price":64341.3,"quantity":0.11187042,"orderId":1},{"price":64351.1,"quantity":0,"orderId":0},{"price":64351.3,"quantity":0.08894273,"orderId":1},{"price":64357.8,"quantity":0,"orderId":0},{"price":64358.1,"quantity":0.11953416,"orderId":1},{"price":64395.6,"quantity":0.01348005,"orderId":1},{"price":64413.9,"quantity":0.04652441,"orderId":3},{"price":64421.5,"quantity":0.00002959,"orderId":1},{"price":64460,"quantity":0.02598095,"orderId":2},{"price":64509.4,"quantity":0.00528449,"orderId":1}],"instBids":[{"price":64332.4,"quantity":0.25806193,"orderId":2},{"price":64332,"quantity":0.0808,"orderId":1},{"price":64330,"quantity":0.0808,"orderId":1},{"price":64321.7,"quantity":0.02782997,"orderId":3},{"price":64319.9,"quantity":0,"orderId":0},{"price":64314.1,"quantity":0.0872079,"orderId":1},{"price":64313.9,"quantity":0.0174,"orderId":1},{"price":64307.4,"quantity":0.11774349,"orderId":1},{"price":64307.1,"quantity":0,"orderId":0},{"price":64306.2,"quantity":0.11186751,"orderId":1},{"price":64304.5,"quantity":0,"orderId":0},{"price":64303.5,"quantity":0.0015,"orderId":1},{"price":64283.8,"quantity":0.00256746,"orderId":1},{"price":64283.6,"quantity":0,"orderId":0},{"price":64250,"quantity":0.01427359,"orderId":2},{"price":64206.9,"quantity":0.10707,"orderId":1},{"price":64199.7,"quantity":0.0077882,"orderId":1},{"price":64199.2,"quantity":0.00007386,"orderId":1},{"price":64188.6,"quantity":0.00778954,"orderId":1},{"price":64185.7,"quantity":0.01370223,"orderId":2},{"price":64157.1,"quantity":0,"orderId":0},{"price":64156.8,"quantity":0,"orderId":0},{"price":64156.2,"quantity":0,"orderId":0},{"price":64155.9,"quantity":0,"orderId":0},{"price":64155.4,"quantity":0,"orderId":0}],"prevSeqId":31327889315,"currentSeqId":31327889355,"checksum":172127597}
{"action":"update","channel":"books","instrumentId":"BTC-USDT","instAsks":[{"price":64332.7,"quantity":0.143259,"orderId":1},{"price":64335.8,"quantity":0,"orderId":0},{"price":64337.9,"quantity":0.09321202,"orderId":1},{"price":64339,"quantity":0,"orderId":0},{"price":64341.3,"quantity":0,"orderId":0},{"price":64342.3,"quantity":0,"orderId":0},{"price":64344.7,"quantity":0.11186495,"orderId":1},{"price":64354.5,"quantity":0,"orderId":0},{"price":64367.8,"quantity":0,"orderId":0},{"price":64370.3,"quantity":2.63158927,"orderId":2},{"price":64407.6,"quantity":0.06600348,"orderId":2},{"price":64413.9,"quantity":0.0387621,"orderId":2},{"price":64509.6,"quantity":0.0000314,"orderId":2},{"price":64509.7,"quantity":0.0000139,"orderId":1},{"price":64509.8,"quantity":0.00034037,"orderId":1},{"price":64510,"quantity":0.00101459,"orderId":2},{"price":64510.1,"quantity":0.00008038,"orderId":2}],"instBids":[{"price":64323.9,"quantity":0.01192997,"orderId":1},{"price":64321.7,"quantity":0.0159,"orderId":2},{"price":64308.5,"quantity":0.01555004,"orderId":1},{"price":64308,"quantity":0.00150967,"orderId":1},{"price":64307.9,"quantity":0.11187996,"orderId":2},{"price":64306.2,"quantity":0,"orderId":0},{"price":64296.8,"quantity":2.27271174,"orderId":1},{"price":64295.2,"quantity":0,"orderId":0},{"price":64283.5,"quantity":0.03520179,"orderId":1},{"price":64280.2,"quantity":0.7,"orderId":1},{"price":64279.3,"quantity":0,"orderId":0},{"price":64223.3,"quantity":0.06000004,"orderId":2},{"price":64218.7,"quantity":0.00778589,"orderId":1},{"price":64158.3,"quantity":0,"orderId":0},{"price":64157.5,"quantity":0,"orderId":0},{"price":64157.3,"quantity":0,"orderId":0}],"prevSeqId":31327889355,"currentSeqId":31327889400,"checksum":1714545675}
{"action":"update","channel":"books","instrumentId":"BTC-USDT","instAsks":[{"price":64337.9,"quantity":0.15289341,"orderId":2},{"price":64341.9,"quantity":0.05513,"orderId":1},{"price":64342.4,"quantity":0.00774949,"orderId":1},{"price":64370.3,"quantity":0.26,"orderId":1},{"price":64371.6,"quantity":2.43025883,"orderId":2},{"price":64372.4,"quantity":1.42295363,"orderId":1},{"price":64410.7,"quantity":0.16472517,"orderId":3},{"price":64412.6,"quantity":0.05866956,"orderId":1},{"price":64458.6,"quantity":0.40457238,"orderId":1},{"price":64475.6,"quantity":0,"orderId":0},{"price":64477.9,"quantity":0.02296891,"orderId":2},{"price":64499.8,"quantity":0.04664866,"orderId":1},{"price":64502.1,"quantity":0.01616551,"orderId":1},{"price":64510,"quantity":0,"orderId":0},{"price":64510.1,"quantity":0,"orderId":0}],"instBids":[{"price":64332.2,"quantity":0.01554634,"orderId":1},{"price":64331.5,"quantity":0,"orderId":0},{"price":64328.8,"quantity":0.05968139,"orderId":1},{"price":64325.9,"quantity":0.1778429,"orderId":1},{"price":64158.8,"quantity":0,"orderId":0}],"prevSeqId":31327889400,"currentSeqId":31327889421,"checksum":-731814195}
{"action":"update","channel":"books","instrumentId":"BTC-USDT","instAsks":[{"price":64332.5,"quantity":0.80730484,"orderId":11},{"price":64341.9,"quantity":0.06287949,"orderId":2},{"price":64342.4,"quantity":0,"orderId":0},{"price":64344.7,"quantity":0.11186535,"orderId":1},{"price":64372.4,"quantity":0,"orderId":0},{"price":64458.6,"quantity":0.84942853,"orderId":2},{"price":64510,"quantity":0.00101459,"orderId":2},{"price":64510.1,"quantity":0.00008038,"orderId":2}],"instBids":[{"price":64326.1,"quantity":0.22,"orderId":1},{"price":64324.7,"quantity":0.01192997,"orderId":1},{"price":64323.9,"quantity":0,"orderId":0},{"price":64317,"quantity":0.00472697,"orderId":1},{"price":64308.4,"quantity":0.02,"orderId":1},{"price":64307.9,"quantity":0.00001501,"orderId":1},{"price":64307.5,"quantity":0.11186546,"orderId":1},{"price":64189.2,"quantity":0.00778947,"orderId":1},{"price":64188.6,"quantity":0,"orderId":0},{"price":64160,"quantity":0,"orderId":0},{"price":64159.9,"quantity":0,"orderId":0},{"price":64159.6,"quantity":0,"orderId":0},{"price":64159.1,"quantity":0,"orderId":0}],"prevSeqId":31327889421,"currentSeqId":31327889443,"checksum":1416361916}
{"action":"update","channel":"books","instrumentId":"BTC-USDT","instAsks":[{"price":64341.9,"quantity":0.05513,"orderId":1},{"price":64342.4,"quantity":0.00774949,"orderId":1},{"price":64510.1,"quantity":0,"orderId":0}],"instBids":[{"price":64323,"quantity":0.0005,"orderId":1},{"price":64322.9,"quantity":0.0005,"orderId":1},{"price":64322.2,"quantity":0.0153,"orderId":1},{"price":64321.8,"quantity":0,"orderId":0},{"price":64321.7,"quantity":0,"orderId":0},{"price":64160.5,"quantity":0,"orderId":0}],"prevSeqId":31327889443,"currentSeqId":31327889454,"checksum":1924513005}
{"action":"update","channel":"books","instrumentId":"BTC-USDT","instAsks":[{"price":64341.9,"quantity":0.06287949,"orderId":2},{"price":64342.4,"quantity":0,"orderId":0},{"price":64363.7,"quantity":0,"orderId":0},{"price":64379.3,"quantity":0.02328893,"orderId":1},{"price":64486.1,"quantity":0,"orderId":0},{"price":64489,"quantity":0.01929268,"orderId":3},{"price":64489.8,"quantity":0,"orderId":0},{"price":64492.1,"quantity":0.01616802,"orderId":1},{"price":64510.1,"quantity":0.00008038,"orderId":2},{"price":64510.2,"quantity":0.00018585,"orderId":4}],"instBids":[{"price":64326.1,"quantity":0,"orderId":0},{"price":64298.3,"quantity":2.27271174,"orderId":1},{"price":64296.8,"quantity":0,"orderId":0},{"price":64160,"quantity":0.00119308,"orderId":12}],"prevSeqId":31327889454,"currentSeqId":31327889468,"checksum":-2144316417}
{"action":"update","channel":"books","instrumentId":"BTC-USDT","instAsks":[{"price":64341.9,"quantity":0.05513,"orderId":1},{"price":64342.4,"quantity":0.00774949,"orderId":1},{"price":64365.3,"quantity":0.023294,"orderId":1},{"price":64379.3,"quantity":0,"orderId":0},{"price":64422.3,"quantity":0,"orderId":0},{"price":64441.6,"quantity":0,"orderId":0},{"price":64486.6,"quantity":0,"orderId":0},{"price":64510.4,"quantity":0.00010027,"orderId":4},{"price":64511,"quantity":0.00026944,"orderId":2}],"instBids":[{"price":64324.7,"quantity":0,"orderId":0},{"price":64324,"quantity":0.09428458,"orderId":3},{"price":64323.2,"quantity":0.0005,"orderId":1},{"price":64323.1,"quantity":0.0005,"orderId":1},{"price":64323,"quantity":0,"orderId":0},{"price":64322.9,"quantity":0,"orderId":0},{"price":64231.6,"quantity":0.03109895,"orderId":1},{"price":64212.3,"quantity":0,"orderId":0},{"price":64167.3,"quantity":0.11553,"orderId":1},{"price":64160.5,"quantity":0.26,"orderId":1},{"price":64159.9,"quantity":0.01564601,"orderId":2}],"prevSeqId":31327889468,"currentSeqId":31327889485,"checksum":-1418182562}
{"action":"update","channel":"books","instrumentId":"BTC-USDT","instAsks":[{"price":64332.5,"quantity":0.88630484,"orderId":12},{"price":64341.9,"quantity":0.06287949,"orderId":2},{"price":64342.4,"quantity":0,"orderId":0},{"price":64511.2,"quantity":0.00004022,"orderId":1}],"instBids":[{"price":64332,"quantity":0,"orderId":0},{"price":64323.3,"quantity":0.0005,"orderId":1},{"price":64323.1,"quantity":0,"orderId":0},{"price":64307.9,"quantity":0.11187992,"orderId":2},{"price":64307.5,"quantity":0,"orderId":0},{"price":64298.3,"quantity":0,"orderId":0},{"price":64296,"quantity":2.27272279,"orderId":2},{"price":64228.2,"quantity":0,"orderId":0},{"price":64159.6,"quantity":1.5,"orderId":1},{"price":64159.1,"quantity":0.00001007,"orderId":1},{"price":64158.8,"quantity":0.00031097,"orderId":2},{"price":64158.3,"quantity":0.00014683,"orderId":1}],"prevSeqId":31327889485,"currentSeqId":31327889499,"checksum":-260701354}
{"action":"update","channel":"books","instrumentId":"BTC-USDT","instAsks":[{"price":64341.9,"quantity":0.05513,"orderId":1},{"price":64342.4,"quantity":0.00774949,"orderId":1},{"price":64396.2,"quantity":1.19858,"orderId":1},{"price":64511.2,"quantity":0,"orderId":0}],"instBids":[{"price":64332,"quantity":0.0808,"orderId":1},{"price":64323.3,"quantity":0,"orderId":0},{"price":64323.1,"quantity":0.0005,"orderId":1},{"price":64298.3,"quantity":2.27271174,"orderId":1},{"price":64296,"quantity":0.00001105,"orderId":1},{"price":64158.8,"quantity":0,"orderId":0},{"price":64158.3,"quantity":0,"orderId":0}],"prevSeqId":31327889499,"currentSeqId":31327889511,"checksum":-1446101263}
{"action":"update","channel":"books","instrumentId":"BTC-USDT","instAsks":[{"price":64341.9,"quantity":0.06287949,"orderId":2},{"price":64342.4,"quantity":0,"orderId":0},{"price":64346.2,"quantity":0,"orderId":0},{"price":64354.4,"quantity":0.03469077,"orderId":1},{"price":64397.8,"quantity":0.01294041,"orderId":1},{"price":64407.6,"quantity":0.05824042,"orderId":1},{"price":64409.7,"quantity":0.0077628,"orderId":1},{"price":64413.9,"quantity":0.0309998,"orderId":1},{"price":64414.1,"quantity":0.26776227,"orderId":2},{"price":64511,"quantity":0,"orderId":0}],"instBids":[{"price":64323.3,"quantity":0.0005,"orderId":1},{"price":64323.1,"quantity":0,"orderId":0},{"price":64298.3,"quantity":0,"orderId":0},{"price":64296.8,"quantity":2.27271174,"orderId":1},{"price":64231.6,"quantity":0.28019715,"orderId":2},{"price":64212.3,"quantity":0.24917306,"orderId":1},{"price":64200.9,"quantity":0.00778805,"orderId":1},{"price":64199.7,"quantity":0,"orderId":0},{"price":64167.3,"quantity":0.36487791,"orderId":2},{"price":64159.1,"quantity":0,"orderId":0}],"prevSeqId":31327889511,"currentSeqId":31327889536,"checksum":-821599840}
{"action":"update","channel":"books","instrumentId":"BTC-USDT","instAsks":[{"price":64341.9,"quantity":0.05513,"orderId":1},{"price":64342.4,"quantity":0.00774949,"orderId":1},{"price":64510.4,"quantity":0,"orderId":0}],"instBids":[{"price":64319.7,"quantity":0.05866956,"orderId":1},{"price":64159.6,"quantity":0,"orderId":0}],"prevSeqId":31327889536,"currentSeqId":31327889545,"checksum":-980867415}
{"action":"update","channel":"books","instrumentId":"BTC-USDT","instAsks":[{"price":64341.9,"quantity":0.06287949,"orderId":2},{"price":64342.4,"quantity":0,"orderId":0},{"price":64510.4,"quantity":0.00010027,"orderId":4}],"instBids":[{"price":64326.1,"quantity":0.22,"orderId":1},{"price":64220.4,"quantity":0.00562079,"orderId":1},{"price":64160,"quantity":0,"orderId":0},{"price":64159.9,"quantity":0,"orderId":0}],"prevSeqId":31327889545,"currentSeqId":31327889554,"checksum":-243263240}
{"action":"update","channel":"books","instrumentId":"BTC-USDT","instAsks":[{"price":64332.5,"quantity":0.80730484,"orderId":11},{"price":64341.9,"quantity":0.05513,"orderId":1},{"price":64342.4,"quantity":0.00774949,"orderId":1},{"price":64371.5,"quantity":1.4581553,"orderId":1},{"price":64458.6,"quantity":0.40457238,"orderId":1},{"price":64510.2,"quantity":0,"orderId":0},{"price":64510.4,"quantity":0,"orderId":0}],"instBids":[{"price":64260.1,"quantity":0.75418313,"orderId":1},{"price":64236.7,"quantity":0,"orderId":0},{"price":64231.6,"quantity":0.03109895,"orderId":1},{"price":64212.3,"quantity":0,"orderId":0},{"price":64167.3,"quantity":0.11553,"orderId":1},{"price":64160,"quantity":0.00119308,"orderId":12}],"prevSeqId":31327889554,"currentSeqId":31327889570,"checksum":1401188261}
{"action":"update","channel":"books","instrumentId":"BTC-USDT","instAsks":[{"price":64341.9,"quantity":0.06287949,"orderId":2},{"price":64342.4,"quantity":0,"orderId":0},{"price":64371.4,"quantity":2.37158927,"orderId":1},{"price":64371.5,"quantity":0,"orderId":0},{"price":64371.6,"quantity":0.05866956,"orderId":1},{"price":64422.3,"quantity":0.24836157,"orderId":1},{"price":64441.6,"quantity":0.24828719,"orderId":1},{"price":64486.6,"quantity":0.24811382,"orderId":1},{"price":64510,"quantity":0,"orderId":0},{"price":64510.1,"quantity":0,"orderId":0}],"instBids":[{"price":64332.4,"quantity":0.27546193,"orderId":3},{"price":64231.6,"quantity":0.28019715,"orderId":2},{"price":64212.3,"quantity":0.24917306,"orderId":1},{"price":64167.3,"quantity":0.36487791,"orderId":2},{"price":64160,"quantity":0,"orderId":0}],"prevSeqId":31327889570,"currentSeqId":31327889583,"checksum":2096897426}
{"action":"update","channel":"books","instrumentId":"BTC-USDT","instAsks":[{"price":64332.5,"quantity":0.88630484,"orderId":12},{"price":64339,"quantity":0.26,"orderId":1},{"price":64341.9,"quantity":0.05513,"orderId":1},{"price":64342.4,"quantity":0.11961556,"orderId":2},{"price":64344.7,"quantity":0,"orderId":0},{"price":64351.3,"quantity":0,"orderId":0},{"price":64358.1,"quantity":0,"orderId":0},{"price":64510,"quantity":0.00101459,"orderId":2}],"instBids":[{"price":64332.4,"quantity":0.11856193,"orderId":1},{"price":64332,"quantity":0,"orderId":0},{"price":64326.1,"quantity":0,"orderId":0},{"price":64324,"quantity":0.08235461,"orderId":2},{"price":64322.7,"quantity":0.01192997,"orderId":1},{"price":64314.1,"quantity":0,"orderId":0},{"price":64307.9,"quantity":0.00001501,"orderId":1},{"price":64307.5,"quantity":0.11186555,"orderId":1},{"price":64307.4,"quantity":0,"orderId":0},{"price":64160,"quantity":0.00119308,"orderId":12},{"price":64159.9,"quantity":0.01564601,"orderId":2}],"prevSeqId":31327889583,"currentSeqId":31327889702,"checksum":-1293418994}
{"action":"update","channel":"books","instrumentId":"BTC-USDT","instAsks":[{"price":64337.9,"quantity":0.2040299,"orderId":3},{"price":64341.9,"quantity":0.06287949,"orderId":2},{"price":64342.4,"quantity":0.11186645,"orderId":1},{"price":64351.1,"quantity":0.08861101,"orderId":1},{"price":64357.9,"quantity":0.11461387,"orderId":1},{"price":64370.3,"quantity":2.66391037,"orderId":2},{"price":64371.4,"quantity":0,"orderId":0},{"price":64510,"quantity":0,"orderId":0}],"instBids":[{"price":64330,"quantity":0,"orderId":0},{"price":64324.1,"quantity":0.22017763,"orderId":2},{"price":64323.3,"quantity":0,"orderId":0},{"price":64323.2,"quantity":0,"orderId":0},{"price":64322.8,"quantity":0.0005,"orderId":1},{"price":64322.7,"quantity":0.0005,"orderId":1},{"price":64322.2,"quantity":0.0152,"orderId":1},{"price":64321.1,"quantity":0.01192997,"orderId":1},{"price":64313.9,"quantity":0.1094428,"orderId":2},{"price":64307.5,"quantity":0,"orderId":0},{"price":64307.2,"quantity":0.12273678,"orderId":1},{"price":64306.2,"quantity":0.11186673,"orderId":1},{"price":64296.8,"quantity":0,"orderId":0},{"price":64296,"quantity":2.22808165,"orderId":2},{"price":64159.6,"quantity":1.5,"orderId":1}],"prevSeqId":31327889702,"currentSeqId":31327889756,"checksum":1142666146}
{"action":"update","channel":"books","instrumentId":"BTC-USDT","instAsks":[{"price":64342.4,"quantity":0,"orderId":0},{"price":64344.7,"quantity":0.11186602,"orderId":1},{"price":64346.6,"quantity":0,"orderId":0},{"price":64346.7,"quantity":0,"orderId":0},{"price":64348.7,"quantity":0.05129621,"orderId":1},{"price":64351.1,"quantity":0,"orderId":0},{"price":64351.2,"quantity":0.09737185,"orderId":1},{"price":64353.7,"quantity":0.24761704,"orderId":1},{"price":64354.9,"quantity":0.412695,"orderId":1},{"price":64509.8,"quantity":0,"orderId":0}],"instBids":[{"price":64330,"quantity":0.0808,"orderId":1},{"price":64322.8,"quantity":0,"orderId":0},{"price":64322.6,"quantity":0.0005,"orderId":1},{"price":64321.9,"quantity":0.01192997,"orderId":1},{"price":64321.1,"quantity":0,"orderId":0},{"price":64314,"quantity":0.17607686,"orderId":2},{"price":64313.9,"quantity":0.0174,"orderId":1},{"price":64307.3,"quantity":0.11186602,"orderId":1},{"price":64306.2,"quantity":0,"orderId":0},{"price":64300.6,"quantity":0.40284,"orderId":1},{"price":64291.2,"quantity":0,"orderId":0},{"price":64291.1,"quantity":0,"orderId":0},{"price":64286.1,"quantity":0.97589287,"orderId":1},{"price":64283.5,"quantity":0,"orderId":0},{"price":64260.1,"quantity":0,"orderId":0},{"price":64159.1,"quantity":0.00001007,"orderId":1}],"prevSeqId":31327889756,"currentSeqId":31327889792,"checksum":1349930456}
{"action":"update","channel":"books","instrumentId":"BTC-USDT","instAsks":[{"price":64342.4,"quantity":0.11186689,"orderId":1},{"price":64344.7,"quantity":0,"orderId":0},{"price":64404.9,"quantity":0.16410438,"orderId":2},{"price":64407.8,"quantity":0.00776304,"orderId":1},{"price":64409.7,"quantity":0,"orderId":0},{"price":64410.7,"quantity":0.15696248,"orderId":2},{"price":64441.6,"quantity":0,"orderId":0},{"price":64486.6,"quantity":0,"orderId":0},{"price":64509.8,"quantity":0.00034037,"orderId":1},{"price":64510,"quantity":0.00101459,"orderId":2}],"instBids":[{"price":64322.3,"quantity":0.01192997,"orderId":1},{"price":64321.9,"quantity":0,"orderId":0},{"price":64307.3,"quantity":0,"orderId":0},{"price":64306.2,"quantity":0.11186689,"orderId":1},{"price":64218.9,"quantity":0.00778587,"orderId":1},{"price":64218.7,"quantity":0,"orderId":0},{"price":64195.8,"quantity":0.00778867,"orderId":1},{"price":64189.2,"quantity":0,"orderId":0}],"prevSeqId":31327889792,"currentSeqId":31327889812,"checksum":-964408433}
{"action":"update","channel":"books","instrumentId":"BTC-USDT","instAsks":[{"price":64342.4,"quantity":0,"orderId":0},{"price":64344.7,"quantity":0.11186655,"orderId":1},{"price":64370.3,"quantity":0.26,"orderId":1},{"price":64372.4,"quantity":2.40391037,"orderId":1},{"price":64510,"quantity":0,"orderId":0}],"instBids":[{"price":64326.1,"quantity":0.1,"orderId":1},{"price":64322.8,"quantity":0.0005,"orderId":1},{"price":64322.6,"quantity":0,"orderId":0},{"price":64307.3,"quantity":0.11186655,"orderId":1},{"price":64306.2,"quantity":0,"orderId":0},{"price":64253.1,"quantity":0.00832637,"orderId":1},{"price":64247,"quantity":0.05174305,"orderId":1},{"price":64244.1,"quantity":0,"orderId":0},{"price":64188.8,"quantity":0.02093154,"orderId":1},{"price":64159.1,"quantity":0,"orderId":0}],"prevSeqId":31327889812,"currentSeqId":31327889825,"checksum":1841356972}
{"action":"update","channel":"books","instrumentId":"BTC-USDT","instAsks":[{"price":64332.5,"quantity":0.73086242,"orderId":10},{"price":64337.9,"quantity":0.15289341,"orderId":2},{"price":64339,"quantity":0,"orderId":0},{"price":64344.7,"quantity":0.11186602,"orderId":1},{"price":64370.8,"quantity":2.46276814,"orderId":1},{"price":64372.4,"quantity":0,"orderId":0},{"price":64441.6,"quantity":0.24828719,"orderId":1},{"price":64486.6,"quantity":0.24811382,"orderId":1},{"price":64509.8,"quantity":0,"orderId":0}],"instBids":[{"price":64323.1,"quantity":0.01192997,"orderId":1},{"price":64322.8,"quantity":0,"orderId":0},{"price":64322.6,"quantity":0.0005,"orderId":1},{"price":64322.3,"quantity":0,"orderId":0},{"price":64307.9,"quantity":0.11188064,"orderId":2},{"price":64307.3,"quantity":0,"orderId":0},{"price":64255.4,"quantity":0.01294055,"orderId":1},{"price":64228.7,"quantity":0.01616138,"orderId":1},{"price":64225.8,"quantity":0,"orderId":0},{"price":64191.1,"quantity":0.01294055,"orderId":1},{"price":64159.6,"quantity":0,"orderId":0}],"prevSeqId":31327889825,"currentSeqId":31327889856,"checksum":-2145720436}
{"action":"update","channel":"books","instrumentId":"BTC-USDT","instAsks":[{"price":64341.9,"quantity":0.05513,"orderId":1},{"price":64342.4,"quantity":0.00774949,"orderId":1},{"price":64370.3,"quantity":2.72276814,"orderId":2},{"price":64370.8,"quantity":0,"orderId":0},{"price":64486.6,"quantity":0,"orderId":0},{"price":64509.8,"quantity":0.00034037,"orderId":1}],"instBids":[{"price":64322.8,"quantity":0.0005,"orderId":1},{"price":64322.6,"quantity":0,"orderId":0},{"price":64307.9,"quantity":0.00001501,"orderId":1},{"price":64307.3,"quantity":0.11186571,"orderId":1},{"price":64296.8,"quantity":2.19424698,"orderId":1},{"price":64296,"quantity":0.00001105,"orderId":1},{"price":64242.3,"quantity":0.00646771,"orderId":1},{"price":64240,"quantity":0,"orderId":0},{"price":64238.9,"quantity":0.0161685,"orderId":1},{"price":64236.6,"quantity":0,"orderId":0},{"price":64233.1,"quantity":0.03000018,"orderId":1},{"price":64174.6,"quantity":0.0161685,"orderId":1},{"price":64172.3,"quantity":0,"orderId":0},{"price":64160,"quantity":0,"orderId":0},{"price":64159.9,"quantity":0,"orderId":0}],"prevSeqId":31327889856,"currentSeqId":31327889878,"checksum":-1339218625}
{"action":"update","channel":"books","instrumentId":"BTC-USDT","instAsks":[{"price":64341.9,"quantity":0.06287949,"orderId":2},{"price":64342.4,"quantity":0,"orderId":0},{"price":64370.3,"quantity":0.26,"orderId":1},{"price":64371.5,"quantity":2.46276814,"orderId":1},{"price":64414.1,"quantity":0.26,"orderId":1},{"price":64416.5,"quantity":0.16410298,"orderId":2}],"instBids":[{"price":64308.5,"quantity":0,"orderId":0},{"price":64307.9,"quantity":0.11188063,"orderId":2},{"price":64307.3,"quantity":0,"orderId":0},{"price":64236.6,"quantity":0.01616617,"orderId":1},{"price":64218.9,"quantity":0,"orderId":0},{"price":64217.4,"quantity":0.00778605,"orderId":1},{"price":64160,"quantity":0.00119308,"orderId":12}],"prevSeqId":31327889878,"currentSeqId":31327889896,"checksum":2099304178}
{"action":"update","channel":"books","instrumentId":"BTC-USDT","instAsks":[{"price":64341.9,"quantity":0.05513,"orderId":1},{"price":64342.4,"quantity":0.00774949,"orderId":1},{"price":64371.4,"quantity":1.47766094,"orderId":1},{"price":64404.9,"quantity":0.156341,"orderId":1},{"price":64405.1,"quantity":0.00776336,"orderId":1},{"price":64407.8,"quantity":0,"orderId":0},{"price":64410.7,"quantity":0.16472517,"orderId":3},{"price":64422.3,"quantity":0,"orderId":0},{"price":64441.6,"quantity":0,"orderId":0}],"instBids":[{"price":64326.1,"quantity":0.22,"orderId":2},{"price":64322.9,"quantity":0.0005,"orderId":1},{"price":64322.7,"quantity":0,"orderId":0},{"price":64260.1,"quantity":0.11939854,"orderId":1},{"price":64231.6,"quantity":0.03109895,"orderId":1},{"price":64223.8,"quantity":0.01616584,"orderId":1},{"price":64222.2,"quantity":0.02999953,"orderId":1},{"price":64212.3,"quantity":0,"orderId":0},{"price":64205.2,"quantity":0.00778753,"orderId":1},{"price":64200.9,"quantity":0,"orderId":0},{"price":64186.8,"quantity":0.01623259,"orderId":2},{"price":64184.5,"quantity":0,"orderId":0},{"price":64167.3,"quantity":0.11553,"orderId":1}],"prevSeqId":31327889896,"currentSeqId":31327889924,"checksum":-706078667}
{"action":"update","channel":"books","instrumentId":"BTC-USDT","instAsks":[{"price":64341.9,"quantity":0.06287949,"orderId":2},{"price":64342.4,"quantity":0,"orderId":0},{"price":64369.4,"quantity":2.46276814,"orderId":1},{"price":64371.4,"quantity":0,"orderId":0},{"price":64371.5,"quantity":0,"orderId":0},{"price":64422.3,"quantity":0.24836157,"orderId":1},{"price":64441.6,"quantity":0.24828719,"orderId":1},{"price":64458.6,"quantity":0.84942852,"orderId":2},{"price":64486.6,"quantity":0.24811382,"orderId":1},{"price":64509.8,"quantity":0,"orderId":0}],"instBids":[{"price":64231.6,"quantity":0.28019715,"orderId":2},{"price":64212.3,"quantity":0.24917306,"orderId":1},{"price":64167.3,"quantity":0.36487791,"orderId":2},{"price":64160,"quantity":0,"orderId":0}],"prevSeqId":31327889924,"currentSeqId":31327889938,"checksum":-488258182}
{"action":"update","channel":"books","instrumentId":"BTC-USDT","instAsks":[{"price":64332.5,"quantity":0.76075816,"orderId":11},{"price":64341.9,"quantity":0.05513,"orderId":1},{"price":64342.4,"quantity":0.00774949,"orderId":1},{"price":64509.7,"quantity":0,"orderId":0}],"instBids":[{"price":64296.8,"quantity":0,"orderId":0},{"price":64296.5,"quantity":2.45424698,"orderId":2},{"price":64160,"quantity":0.00119308,"orderId":12}],"prevSeqId":31327889938,"currentSeqId":31327889945,"checksum":-1175467119}
{"action":"update","channel":"books","instrumentId":"BTC-USDT","instAsks":[{"price":64341.9,"quantity":0.06287949,"orderId":2},{"price":64342.4,"quantity":0.1118665,"orderId":1},{"price":64344.7,"quantity":0,"orderId":0},{"price":64369.4,"quantity":0,"orderId":0},{"price":64373.6,"quantity":2.46276814,"orderId":1},{"price":64509.7,"quantity":0.0000139,"orderId":1}],"instBids":[{"price":64326,"quantity":0.31538381,"orderId":2},{"price":64322.9,"quantity":0,"orderId":0},{"price":64322.7,"quantity":0.0005,"orderId":1},{"price":64307.9,"quantity":0.00001501,"orderId":1},{"price":64307.3,"quantity":0.1118657,"orderId":1},{"price":64296.8,"quantity":2.19424698,"orderId":1},{"price":64296.5,"quantity":0.26,"orderId":1},{"price":64160.5,"quantity":0,"orderId":0},{"price":64160,"quantity":0,"orderId":0}],"prevSeqId":31327889945,"currentSeqId":31327889969,"checksum":-397821893}
{"action":"update","channel":"books","instrumentId":"BTC-USDT","instAsks":[{"price":64341.9,"quantity":0.05513,"orderId":1},{"price":64342.4,"quantity":0.00774949,"orderId":1},{"price":64344.7,"quantity":0.11186626,"orderId":1},{"price":64371.5,"quantity":2.46276814,"orderId":1},{"price":64373.6,"quantity":0,"orderId":0},{"price":64509.7,"quantity":0,"orderId":0}],"instBids":[{"price":64296.8,"quantity":0,"orderId":0},{"price":64296,"quantity":2.19425803,"orderId":2},{"price":64219.2,"quantity":0.00778584,"orderId":1},{"price":64217.4,"quantity":0,"orderId":0},{"price":64160.5,"quantity":0.26,"orderId":1}],"prevSeqId":31327889969,"currentSeqId":31327889985,"checksum":1850083650}
{"action":"update","channel":"books","instrumentId":"BTC-USDT","instAsks":[{"price":64332.5,"quantity":0.24682624,"orderId":5},{"price":64332.7,"quantity":0,"orderId":0},{"price":64337.2,"quantity":0,"orderId":0},{"price":64337.9,"quantity":0.09321202,"orderId":1},{"price":64341.4,"quantity":0.033078,"orderId":1},{"price":64341.6,"quantity":0,"orderId":0},{"price":64341.9,"quantity":0.06287949,"orderId":2},{"price":64342.4,"quantity":0,"orderId":0},{"price":64344.7,"quantity":0.11186471,"orderId":1},{"price":64351.2,"quantity":0,"orderId":0},{"price":64351.3,"quantity":0.0982638,"orderId":1},{"price":64357.9,"quantity":0,"orderId":0},{"price":64358.1,"quantity":0.11778548,"orderId":1},{"price":64371.5,"quantity":0,"orderId":0},{"price":64373.7,"quantity":2.4695653,"orderId":2},{"price":64405.1,"quantity":0,"orderId":0},{"price":64407.5,"quantity":0.00776307,"orderId":1},{"price":64509.7,"quantity":0.0000139,"orderId":1},{"price":64509.8,"quantity":0.00034037,"orderId":1},{"price":64510,"quantity":0.00101459,"orderId":2},{"price":64510.1,"quantity":0.00008038,"orderId":2},{"price":64510.2,"quantity":0.00018585,"orderId":4}],"instBids":[{"price":64332.4,"quantity":0.45225193,"orderId":5},{"price":64332,"quantity":0.0808,"orderId":1},{"price":64323.1,"quantity":0,"orderId":0},{"price":64322.8,"quantity":0,"orderId":0},{"price":64322.7,"quantity":0,"orderId":0},{"price":64322.3,"quantity":0.0005,"orderId":1},{"price":64322.2,"quantity":0.0158,"orderId":2},{"price":64320.3,"quantity":0.02,"orderId":1},{"price":64314.1,"quantity":0.09750189,"orderId":1},{"price":64314,"quantity":0.0808,"orderId":1},{"price":64308.4,"quantity":0,"orderId":0},{"price":64307.9,"quantity":0.11188012,"orderId":2},{"price":64307.4,"quantity":0.10892702,"orderId":1},{"price":64307.3,"quantity":0,"orderId":0},{"price":64307.2,"quantity":0,"orderId":0},{"price":64296.6,"quantity":2.19424698,"orderId":1},{"price":64296,"quantity":0.00001105,"orderId":1}],"prevSeqId":31327889985,"currentSeqId":31327890052,"checksum":202924405}
{"action":"update","channel":"books","instrumentId":"BTC-USDT","instAsks":[{"price":64332.5,"quantity":0.52582237,"orderId":7},{"price":64333.2,"quantity":0.140447,"orderId":1},{"price":64340.3,"quantity":0.03580887,"orderId":1},{"price":64340.4,"quantity":0.05968139,"orderId":1},{"price":64341.4,"quantity":0,"orderId":0},{"price":64341.9,"quantity":0.05513,"orderId":1},{"price":64342.4,"quantity":0.00774949,"orderId":1},{"price":64344.6,"quantity":0.14761017,"orderId":2},{"price":64344.7,"quantity":0,"orderId":0},{"price":64344.8,"quantity":0.01,"orderId":1},{"price":64345.4,"quantity":0.1118601,"orderId":1},{"price":64347.5,"quantity":0.32631723,"orderId":1},{"price":64347.6,"quantity":0.543862,"orderId":1},{"price":64348.7,"quantity":0,"orderId":0},{"price":64373.7,"quantity":0.00679716,"orderId":1},{"price":64376.5,"quantity":2.46276814,"orderId":1},{"price":64376.6,"quantity":0,"orderId":0},{"price":64423.1,"quantity":0.05174128,"orderId":1},{"price":64424.9,"quantity":0.03099956,"orderId":1},{"price":64509.6,"quantity":0,"orderId":0},{"price":64509.7,"quantity":0,"orderId":0},{"price":64509.8,"quantity":0,"orderId":0},{"price":64510,"quantity":0,"orderId":0},{"price":64510.1,"quantity":0,"orderId":0},{"price":64510.2,"quantity":0,"orderId":0}],"instBids":[{"price":64327.2,"quantity":0.05866956,"orderId":1},{"price":64325.9,"quantity":0.4378429,"orderId":2},{"price":64324,"quantity":0.0808,"orderId":1},{"price":64309.5,"quantity":0.11186039,"orderId":1},{"price":64308.5,"quantity":0.01555004,"orderId":1},{"price":64307.9,"quantity":0.00001501,"orderId":1},{"price":64296.7,"quantity":2.34970165,"orderId":2},{"price":64296.6,"quantity":0,"orderId":0},{"price":64256.1,"quantity":0.48394571,"orderId":4},{"price":64251.6,"quantity":0,"orderId":0},{"price":64181.4,"quantity":0.05626346,"orderId":2},{"price":64160.5,"quantity":0,"orderId":0}],"prevSeqId":31327890052,"currentSeqId":31327890104,"checksum":-1615363718}
{"action":"update","channel":"books","instrumentId":"BTC-USDT","instAsks":[{"price":64332.5,"quantity":0.44099284,"orderId":7},{"price":64333.1,"quantity":0.08426826,"orderId":1},{"price":64335.3,"quantity":0,"orderId":0},{"price":64344.5,"quantity":0.1118625,"orderId":1},{"price":64345.4,"quantity":0,"orderId":0},{"price":64373.7,"quantity":2.4695653,"orderId":2},{"price":64376.5,"quantity":0,"orderId":0},{"price":64441.6,"quantity":0,"orderId":0},{"price":64486.6,"quantity":0,"orderId":0},{"price":64509.6,"quantity":0.0000314,"orderId":2},{"price":64509.7,"quantity":0.0000139,"orderId":1},{"price":64509.8,"quantity":0.00034037,"orderId":1}],"instBids":[{"price":64325.9,"quantity":0.1778429,"orderId":1},{"price":64322.7,"quantity":0.0005,"orderId":1},{"price":64322.6,"quantity":0.0005,"orderId":1},{"price":64322.3,"quantity":0,"orderId":0},{"price":64322.2,"quantity":0.0153,"orderId":1},{"price":64312.9,"quantity":0.16077259,"orderId":2},{"price":64311.8,"quantity":0,"orderId":0},{"price":64309.5,"quantity":0.11186214,"orderId":1},{"price":64303.3,"quantity":0.31099,"orderId":1},{"price":64302.2,"quantity":0,"orderId":0}],"prevSeqId":31327890104,"currentSeqId":31327890141,"checksum":-1707475245}
{"action":"update","channel":"books","instrumentId":"BTC-USDT","instAsks":[{"price":64332.5,"quantity":0.56796518,"orderId":8},{"price":64372.4,"quantity":2.46276814,"orderId":1},{"price":64373.7,"quantity":0.00679716,"orderId":1},{"price":64407.5,"quantity":0,"orderId":0},{"price":64412.9,"quantity":0.00776242,"orderId":1},{"price":64416.5,"quantity":0.156341,"orderId":1},{"price":64416.8,"quantity":0.00776196,"orderId":1},{"price":64509.7,"quantity":0,"orderId":0},{"price":64509.8,"quantity":0,"orderId":0}],"instBids":[{"price":64322.7,"quantity":0,"orderId":0},{"price":64322.6,"quantity":0,"orderId":0},{"price":64322.4,"quantity":0.0005,"orderId":1},{"price":64322.3,"quantity":0.0005,"orderId":1},{"price":64309.5,"quantity":0,"orderId":0},{"price":64308.6,"quantity":0.11186263,"orderId":1},{"price":64296.7,"quantity":0.15545467,"orderId":1},{"price":64296.1,"quantity":2.17055856,"orderId":1},{"price":64224.6,"quantity":0.00778518,"orderId":1},{"price":64219.2,"quantity":0,"orderId":0},{"price":64196.7,"quantity":0.00778857,"orderId":1},{"price":64195.8,"quantity":0,"orderId":0},{"price":64160.8,"quantity":0,"orderId":0}],"prevSeqId":31327890141,"currentSeqId":31327890169,"checksum":-1853815915}
{"action":"update","channel":"books","instrumentId":"BTC-USDT","instAsks":[{"price":64332.5,"quantity":0.57935108,"orderId":9},{"price":64410.7,"quantity":0.15696248,"orderId":2},{"price":64418.6,"quantity":0.03176042,"orderId":2}],"instBids":[{"price":64308.6,"quantity":0.1118626,"orderId":1},{"price":64296.8,"quantity":2.17055856,"orderId":1},{"price":64296.1,"quantity":0,"orderId":0},{"price":64207.6,"quantity":0.00778724,"orderId":1},{"price":64205.2,"quantity":0,"orderId":0}],"prevSeqId":31327890169,"currentSeqId":31327890180,"checksum":128698312}
{"action":"update","channel":"books","instrumentId":"BTC-USDT","instAsks":[{"price":64333.1,"quantity":0,"orderId":0},{"price":64335.9,"quantity":0.04848008,"orderId":1}],"instBids":[{"price":64322.8,"quantity":0.0005,"orderId":1},{"price":64322.7,"quantity":0.0005,"orderId":1},{"price":64322.4,"quantity":0,"orderId":0},{"price":64322.3,"quantity":0,"orderId":0}],"prevSeqId":31327890180,"currentSeqId":31327890192,"checksum":243459708}
{"action":"update","channel":"books","instrumentId":"BTC-USDT","instAsks":[{"price":64332.5,"quantity":0.26835035,"orderId":4},{"price":64333.1,"quantity":0.1131415,"orderId":1},{"price":64335.9,"quantity":0,"orderId":0},{"price":64337.9,"quantity":0.09321198,"orderId":1},{"price":64350.9,"quantity":0,"orderId":0},{"price":64351,"quantity":0.07772148,"orderId":1},{"price":64372.4,"quantity":2.50092656,"orderId":1},{"price":64441.6,"quantity":0.24828719,"orderId":1},{"price":64486.6,"quantity":0.24811382,"orderId":1},{"price":64509.4,"quantity":0,"orderId":0},{"price":64509.6,"quantity":0,"orderId":0}],"instBids":[{"price":64324.1,"quantity":0.00017763,"orderId":1},{"price":64324,"quantity":0.09259429,"orderId":2},{"price":64323.6,"quantity":0.00457696,"orderId":1},{"price":64323.1,"quantity":0.0005,"orderId":1},{"price":64323,"quantity":0.0005,"orderId":1},{"price":64322.8,"quantity":0,"orderId":0},{"price":64322.7,"quantity":0,"orderId":0},{"price":64322.2,"quantity":0,"orderId":0},{"price":64322.1,"quantity":0.0155,"orderId":1},{"price":64290.4,"quantity":0.0777628,"orderId":1},{"price":64286.1,"quantity":0,"orderId":0},{"price":64260.1,"quantity":1.01752857,"orderId":2},{"price":64161.1,"quantity":0,"orderId":0}],"prevSeqId":31327890192,"currentSeqId":31327890229,"checksum":1628054478}
{"action":"update","channel":"books","instrumentId":"BTC-USDT","instAsks":[{"price":64332.5,"quantity":1.11427059,"orderId":10},{"price":64333.1,"quantity":0,"orderId":0},{"price":64335.9,"quantity":0.04848008,"orderId":1},{"price":64337.1,"quantity":0.01106532,"orderId":1},{"price":64337.9,"quantity":0.20402998,"orderId":3},{"price":64339,"quantity":0.26,"orderId":1},{"price":64340.3,"quantity":0,"orderId":0},{"price":64340.4,"quantity":0,"orderId":0},{"price":64341.5,"quantity":0.11186983,"orderId":1},{"price":64344.5,"quantity":0,"orderId":0},{"price":64351.1,"quantity":0.0953222,"orderId":1},{"price":64351.3,"quantity":0,"orderId":0},{"price":64357.9,"quantity":0.12453822,"orderId":1},{"price":64358.1,"quantity":0,"orderId":0},{"price":64369.4,"quantity":2.50092656,"orderId":1},{"price":64372.4,"quantity":0,"orderId":0}],"instBids":[{"price":64332.4,"quantity":0.11856193,"orderId":1},{"price":64332,"quantity":0,"orderId":0},{"price":64330,"quantity":0,"orderId":0},{"price":64327.2,"quantity":0,"orderId":0},{"price":64326.1,"quantity":0,"orderId":0},{"price":64326,"quantity":0.15538381,"orderId":1},{"price":64323.1,"quantity":0,"orderId":0},{"price":64322.9,"quantity":0.0005,"orderId":1},{"price":64321.1,"quantity":0.01192997,"orderId":1},{"price":64319.4,"quantity":0,"orderId":0},{"price":64314.1,"quantity":0,"orderId":0},{"price":64313.9,"quantity":0.10919591,"orderId":2},{"price":64308.6,"quantity":0,"orderId":0},{"price":64307.4,"quantity":0,"orderId":0},{"price":64307.2,"quantity":0.11660896,"orderId":1},{"price":64304.5,"quantity":0.11186876,"orderId":1},{"price":64303.5,"quantity":0,"orderId":0},{"price":64301.4,"quantity":0,"orderId":0},{"price":64297,"quantity":0.0015,"orderId":1},{"price":64260.1,"quantity":0,"orderId":0},{"price":64259.6,"quantity":0,"orderId":0},{"price":64236.7,"quantity":0.70071698,"orderId":1},{"price":64161.1,"quantity":0.0296,"orderId":1},{"price":64160.8,"quantity":0.01616609,"orderId":1},{"price":64160.5,"quantity":0.26,"orderId":1},{"price":64160,"quantity":0.00119308,"orderId":12},{"price":64159.9,"quantity":0.01564601,"orderId":2},{"price":64159.6,"quantity":1.5,"orderId":1},{"price":64159.1,"quantity":0.00001007,"orderId":1}],"prevSeqId":31327890229,"currentSeqId":31327890309,"checksum":-1073885324}
{"action":"update","channel":"books","instrumentId":"BTC-USDT","instAsks":[{"price":64336.5,"quantity":0.00463197,"orderId":1},{"price":64341.5,"quantity":0,"orderId":0},{"price":64341.6,"quantity":0.11186945,"orderId":1},{"price":64341.9,"quantity":0.06287949,"orderId":2},{"price":64342.4,"quantity":0,"orderId":0},{"price":64369.4,"quantity":0,"orderId":0},{"price":64369.5,"quantity":2.5281095,"orderId":2},{"price":64509.4,"quantity":0.00528449,"orderId":1}],"instBids":[{"price":64323.6,"quantity":0,"orderId":0},{"price":64321.9,"quantity":0.01192997,"orderId":1},{"price":64321.1,"quantity":0,"orderId":0},{"price":64319.4,"quantity":0.26,"orderId":1},{"price":64306.2,"quantity":0.11186845,"orderId":1},{"price":64304.5,"quantity":0,"orderId":0},{"price":64297.1,"quantity":2.17055856,"orderId":1},{"price":64297,"quantity":0,"orderId":0},{"price":64296.8,"quantity":0,"orderId":0},{"price":64158.8,"quantity":0.00031097,"orderId":2}],"prevSeqId":31327890309,"currentSeqId":31327890340,"checksum":1171451035}
